[2023-11-27 14:23:24,802] {taskinstance.py:1159} INFO - Dependencies all met for <TaskInstance: final_project_data_covid_etl.create_dim_province manual__2023-11-27T14:23:20.785587+00:00 [queued]>
[2023-11-27 14:23:24,812] {taskinstance.py:1159} INFO - Dependencies all met for <TaskInstance: final_project_data_covid_etl.create_dim_province manual__2023-11-27T14:23:20.785587+00:00 [queued]>
[2023-11-27 14:23:24,812] {taskinstance.py:1356} INFO - 
--------------------------------------------------------------------------------
[2023-11-27 14:23:24,812] {taskinstance.py:1357} INFO - Starting attempt 1 of 3
[2023-11-27 14:23:24,812] {taskinstance.py:1358} INFO - 
--------------------------------------------------------------------------------
[2023-11-27 14:23:24,827] {taskinstance.py:1377} INFO - Executing <Task(PythonOperator): create_dim_province> on 2023-11-27 14:23:20.785587+00:00
[2023-11-27 14:23:24,834] {standard_task_runner.py:52} INFO - Started process 885 to run task
[2023-11-27 14:23:24,837] {standard_task_runner.py:79} INFO - Running: ['***', 'tasks', 'run', 'final_project_data_covid_etl', 'create_dim_province', 'manual__2023-11-27T14:23:20.785587+00:00', '--job-id', '458', '--raw', '--subdir', 'DAGS_FOLDER/get_data.py', '--cfg-path', '/tmp/tmpks7l2hmh', '--error-file', '/tmp/tmp05wjlc_w']
[2023-11-27 14:23:24,837] {standard_task_runner.py:80} INFO - Job 458: Subtask create_dim_province
[2023-11-27 14:23:24,885] {task_command.py:369} INFO - Running <TaskInstance: final_project_data_covid_etl.create_dim_province manual__2023-11-27T14:23:20.785587+00:00 [running]> on host 9bd194bc0dbc
[2023-11-27 14:23:24,966] {taskinstance.py:1571} INFO - Exporting the following env vars:
AIRFLOW_CTX_DAG_OWNER=ricky
AIRFLOW_CTX_DAG_ID=final_project_data_covid_etl
AIRFLOW_CTX_TASK_ID=create_dim_province
AIRFLOW_CTX_EXECUTION_DATE=2023-11-27T14:23:20.785587+00:00
AIRFLOW_CTX_TRY_NUMBER=1
AIRFLOW_CTX_DAG_RUN_ID=manual__2023-11-27T14:23:20.785587+00:00
[2023-11-27 14:23:24,995] {logging_mixin.py:115} INFO - province_id province_name
         32    Jawa Barat
[2023-11-27 14:23:25,029] {taskinstance.py:1889} ERROR - Task failed with exception
Traceback (most recent call last):
  File "/home/airflow/.local/lib/python3.7/site-packages/sqlalchemy/engine/base.py", line 1706, in _execute_context
    cursor, statement, parameters, context
  File "/home/airflow/.local/lib/python3.7/site-packages/sqlalchemy/engine/default.py", line 716, in do_execute
    cursor.execute(statement, parameters)
psycopg2.errors.UndefinedTable: table "dim_province" does not exist


The above exception was the direct cause of the following exception:

Traceback (most recent call last):
  File "/home/airflow/.local/lib/python3.7/site-packages/airflow/operators/python.py", line 171, in execute
    return_value = self.execute_callable()
  File "/home/airflow/.local/lib/python3.7/site-packages/airflow/operators/python.py", line 189, in execute_callable
    return self.python_callable(*self.op_args, **self.op_kwargs)
  File "/opt/airflow/dags/get_data.py", line 47, in create_dim_province
    df.to_sql('dim_province', engine_postgres, index=False, if_exists='replace')
  File "/home/airflow/.local/lib/python3.7/site-packages/pandas/core/generic.py", line 2882, in to_sql
    method=method,
  File "/home/airflow/.local/lib/python3.7/site-packages/pandas/io/sql.py", line 728, in to_sql
    **engine_kwargs,
  File "/home/airflow/.local/lib/python3.7/site-packages/pandas/io/sql.py", line 1758, in to_sql
    dtype=dtype,
  File "/home/airflow/.local/lib/python3.7/site-packages/pandas/io/sql.py", line 1650, in prep_table
    table.create()
  File "/home/airflow/.local/lib/python3.7/site-packages/pandas/io/sql.py", line 860, in create
    self.pd_sql.drop_table(self.name, self.schema)
  File "/home/airflow/.local/lib/python3.7/site-packages/pandas/io/sql.py", line 1810, in drop_table
    self.get_table(table_name, schema).drop()
  File "/home/airflow/.local/lib/python3.7/site-packages/sqlalchemy/sql/schema.py", line 960, in drop
    bind._run_ddl_visitor(ddl.SchemaDropper, self, checkfirst=checkfirst)
  File "/home/airflow/.local/lib/python3.7/site-packages/sqlalchemy/engine/base.py", line 3008, in _run_ddl_visitor
    conn._run_ddl_visitor(visitorcallable, element, **kwargs)
  File "/home/airflow/.local/lib/python3.7/site-packages/sqlalchemy/engine/base.py", line 2016, in _run_ddl_visitor
    visitorcallable(self.dialect, self, **kwargs).traverse_single(element)
  File "/home/airflow/.local/lib/python3.7/site-packages/sqlalchemy/sql/visitors.py", line 483, in traverse_single
    return meth(obj, **kw)
  File "/home/airflow/.local/lib/python3.7/site-packages/sqlalchemy/sql/ddl.py", line 1097, in visit_table
    self.connection.execute(DropTable(table))
  File "/home/airflow/.local/lib/python3.7/site-packages/sqlalchemy/engine/base.py", line 1200, in execute
    return meth(self, multiparams, params, _EMPTY_EXECUTION_OPTS)
  File "/home/airflow/.local/lib/python3.7/site-packages/sqlalchemy/sql/ddl.py", line 78, in _execute_on_connection
    self, multiparams, params, execution_options
  File "/home/airflow/.local/lib/python3.7/site-packages/sqlalchemy/engine/base.py", line 1296, in _execute_ddl
    compiled,
  File "/home/airflow/.local/lib/python3.7/site-packages/sqlalchemy/engine/base.py", line 1749, in _execute_context
    e, statement, parameters, cursor, context
  File "/home/airflow/.local/lib/python3.7/site-packages/sqlalchemy/engine/base.py", line 1930, in _handle_dbapi_exception
    sqlalchemy_exception, with_traceback=exc_info[2], from_=e
  File "/home/airflow/.local/lib/python3.7/site-packages/sqlalchemy/util/compat.py", line 211, in raise_
    raise exception
  File "/home/airflow/.local/lib/python3.7/site-packages/sqlalchemy/engine/base.py", line 1706, in _execute_context
    cursor, statement, parameters, context
  File "/home/airflow/.local/lib/python3.7/site-packages/sqlalchemy/engine/default.py", line 716, in do_execute
    cursor.execute(statement, parameters)
sqlalchemy.exc.ProgrammingError: (psycopg2.errors.UndefinedTable) table "dim_province" does not exist

[SQL: 
DROP TABLE dim_province]
(Background on this error at: http://sqlalche.me/e/14/f405)
[2023-11-27 14:23:25,039] {taskinstance.py:1400} INFO - Marking task as UP_FOR_RETRY. dag_id=final_project_data_covid_etl, task_id=create_dim_province, execution_date=20231127T142320, start_date=20231127T142324, end_date=20231127T142325
[2023-11-27 14:23:25,053] {standard_task_runner.py:97} ERROR - Failed to execute job 458 for task create_dim_province ((psycopg2.errors.UndefinedTable) table "dim_province" does not exist

[SQL: 
DROP TABLE dim_province]
(Background on this error at: http://sqlalche.me/e/14/f405); 885)
[2023-11-27 14:23:25,091] {local_task_job.py:156} INFO - Task exited with return code 1
[2023-11-27 14:23:25,135] {local_task_job.py:273} INFO - 0 downstream tasks scheduled from follow-on schedule check
