[2023-11-26 18:20:26,078] {taskinstance.py:1159} INFO - Dependencies all met for <TaskInstance: data_covid_etl.ingest_staging_db manual__2023-11-26T18:15:21.599200+00:00 [queued]>
[2023-11-26 18:20:26,102] {taskinstance.py:1159} INFO - Dependencies all met for <TaskInstance: data_covid_etl.ingest_staging_db manual__2023-11-26T18:15:21.599200+00:00 [queued]>
[2023-11-26 18:20:26,102] {taskinstance.py:1356} INFO - 
--------------------------------------------------------------------------------
[2023-11-26 18:20:26,102] {taskinstance.py:1357} INFO - Starting attempt 2 of 3
[2023-11-26 18:20:26,102] {taskinstance.py:1358} INFO - 
--------------------------------------------------------------------------------
[2023-11-26 18:20:26,129] {taskinstance.py:1377} INFO - Executing <Task(PythonOperator): ingest_staging_db> on 2023-11-26 18:15:21.599200+00:00
[2023-11-26 18:20:26,136] {standard_task_runner.py:52} INFO - Started process 1805 to run task
[2023-11-26 18:20:26,140] {standard_task_runner.py:79} INFO - Running: ['***', 'tasks', 'run', 'data_covid_etl', 'ingest_staging_db', 'manual__2023-11-26T18:15:21.599200+00:00', '--job-id', '277', '--raw', '--subdir', 'DAGS_FOLDER/get_data.py', '--cfg-path', '/tmp/tmpwv7zn5rb', '--error-file', '/tmp/tmpvbp6k8uf']
[2023-11-26 18:20:26,140] {standard_task_runner.py:80} INFO - Job 277: Subtask ingest_staging_db
[2023-11-26 18:20:26,222] {task_command.py:369} INFO - Running <TaskInstance: data_covid_etl.ingest_staging_db manual__2023-11-26T18:15:21.599200+00:00 [running]> on host 79a606f4be36
[2023-11-26 18:20:26,324] {taskinstance.py:1571} INFO - Exporting the following env vars:
AIRFLOW_CTX_DAG_OWNER=oce
AIRFLOW_CTX_DAG_ID=data_covid_etl
AIRFLOW_CTX_TASK_ID=ingest_staging_db
AIRFLOW_CTX_EXECUTION_DATE=2023-11-26T18:15:21.599200+00:00
AIRFLOW_CTX_TRY_NUMBER=2
AIRFLOW_CTX_DAG_RUN_ID=manual__2023-11-26T18:15:21.599200+00:00
[2023-11-26 18:20:26,898] {taskinstance.py:1889} ERROR - Task failed with exception
Traceback (most recent call last):
  File "/home/airflow/.local/lib/python3.7/site-packages/sqlalchemy/engine/base.py", line 1706, in _execute_context
    cursor, statement, parameters, context
  File "/home/airflow/.local/lib/python3.7/site-packages/sqlalchemy/engine/default.py", line 716, in do_execute
    cursor.execute(statement, parameters)
  File "/home/airflow/.local/lib/python3.7/site-packages/MySQLdb/cursors.py", line 206, in execute
    res = self._query(query)
  File "/home/airflow/.local/lib/python3.7/site-packages/MySQLdb/cursors.py", line 319, in _query
    db.query(q)
  File "/home/airflow/.local/lib/python3.7/site-packages/MySQLdb/connections.py", line 254, in query
    _mysql.connection.query(self, query)
MySQLdb._exceptions.OperationalError: (1050, "Table 'covid_jabar' already exists")

The above exception was the direct cause of the following exception:

Traceback (most recent call last):
  File "/home/airflow/.local/lib/python3.7/site-packages/airflow/operators/python.py", line 171, in execute
    return_value = self.execute_callable()
  File "/home/airflow/.local/lib/python3.7/site-packages/airflow/operators/python.py", line 189, in execute_callable
    return self.python_callable(*self.op_args, **self.op_kwargs)
  File "/opt/airflow/dags/get_data.py", line 35, in ingest_data_staging
    df.to_sql("covid_jabar", staging_db_constring, if_exists="replace", index=False)
  File "/home/airflow/.local/lib/python3.7/site-packages/pandas/core/generic.py", line 2882, in to_sql
    method=method,
  File "/home/airflow/.local/lib/python3.7/site-packages/pandas/io/sql.py", line 728, in to_sql
    **engine_kwargs,
  File "/home/airflow/.local/lib/python3.7/site-packages/pandas/io/sql.py", line 1758, in to_sql
    dtype=dtype,
  File "/home/airflow/.local/lib/python3.7/site-packages/pandas/io/sql.py", line 1650, in prep_table
    table.create()
  File "/home/airflow/.local/lib/python3.7/site-packages/pandas/io/sql.py", line 861, in create
    self._execute_create()
  File "/home/airflow/.local/lib/python3.7/site-packages/pandas/io/sql.py", line 853, in _execute_create
    self.table.create()
  File "/home/airflow/.local/lib/python3.7/site-packages/sqlalchemy/sql/schema.py", line 943, in create
    bind._run_ddl_visitor(ddl.SchemaGenerator, self, checkfirst=checkfirst)
  File "/home/airflow/.local/lib/python3.7/site-packages/sqlalchemy/engine/base.py", line 3008, in _run_ddl_visitor
    conn._run_ddl_visitor(visitorcallable, element, **kwargs)
  File "/home/airflow/.local/lib/python3.7/site-packages/sqlalchemy/engine/base.py", line 2016, in _run_ddl_visitor
    visitorcallable(self.dialect, self, **kwargs).traverse_single(element)
  File "/home/airflow/.local/lib/python3.7/site-packages/sqlalchemy/sql/visitors.py", line 483, in traverse_single
    return meth(obj, **kw)
  File "/home/airflow/.local/lib/python3.7/site-packages/sqlalchemy/sql/ddl.py", line 895, in visit_table
    include_foreign_key_constraints,  # noqa
  File "/home/airflow/.local/lib/python3.7/site-packages/sqlalchemy/engine/base.py", line 1200, in execute
    return meth(self, multiparams, params, _EMPTY_EXECUTION_OPTS)
  File "/home/airflow/.local/lib/python3.7/site-packages/sqlalchemy/sql/ddl.py", line 78, in _execute_on_connection
    self, multiparams, params, execution_options
  File "/home/airflow/.local/lib/python3.7/site-packages/sqlalchemy/engine/base.py", line 1296, in _execute_ddl
    compiled,
  File "/home/airflow/.local/lib/python3.7/site-packages/sqlalchemy/engine/base.py", line 1749, in _execute_context
    e, statement, parameters, cursor, context
  File "/home/airflow/.local/lib/python3.7/site-packages/sqlalchemy/engine/base.py", line 1930, in _handle_dbapi_exception
    sqlalchemy_exception, with_traceback=exc_info[2], from_=e
  File "/home/airflow/.local/lib/python3.7/site-packages/sqlalchemy/util/compat.py", line 211, in raise_
    raise exception
  File "/home/airflow/.local/lib/python3.7/site-packages/sqlalchemy/engine/base.py", line 1706, in _execute_context
    cursor, statement, parameters, context
  File "/home/airflow/.local/lib/python3.7/site-packages/sqlalchemy/engine/default.py", line 716, in do_execute
    cursor.execute(statement, parameters)
  File "/home/airflow/.local/lib/python3.7/site-packages/MySQLdb/cursors.py", line 206, in execute
    res = self._query(query)
  File "/home/airflow/.local/lib/python3.7/site-packages/MySQLdb/cursors.py", line 319, in _query
    db.query(q)
  File "/home/airflow/.local/lib/python3.7/site-packages/MySQLdb/connections.py", line 254, in query
    _mysql.connection.query(self, query)
sqlalchemy.exc.OperationalError: (MySQLdb._exceptions.OperationalError) (1050, "Table 'covid_jabar' already exists")
[SQL: 
CREATE TABLE covid_jabar (
	`CLOSECONTACT` BIGINT, 
	`CONFIRMATION` BIGINT, 
	`PROBABLE` BIGINT, 
	`SUSPECT` BIGINT, 
	closecontact_dikarantina BIGINT, 
	closecontact_discarded BIGINT, 
	closecontact_meninggal BIGINT, 
	confirmation_meninggal BIGINT, 
	confirmation_sembuh BIGINT, 
	kode_kab TEXT, 
	kode_prov TEXT, 
	nama_kab TEXT, 
	nama_prov TEXT, 
	probable_diisolasi BIGINT, 
	probable_discarded BIGINT, 
	probable_meninggal BIGINT, 
	suspect_diisolasi BIGINT, 
	suspect_discarded BIGINT, 
	suspect_meninggal BIGINT, 
	tanggal TEXT
)

]
(Background on this error at: http://sqlalche.me/e/14/e3q8)
[2023-11-26 18:20:26,920] {taskinstance.py:1400} INFO - Marking task as UP_FOR_RETRY. dag_id=data_covid_etl, task_id=ingest_staging_db, execution_date=20231126T181521, start_date=20231126T182026, end_date=20231126T182026
[2023-11-26 18:20:26,941] {standard_task_runner.py:97} ERROR - Failed to execute job 277 for task ingest_staging_db ((MySQLdb._exceptions.OperationalError) (1050, "Table 'covid_jabar' already exists")
[SQL: 
CREATE TABLE covid_jabar (
	`CLOSECONTACT` BIGINT, 
	`CONFIRMATION` BIGINT, 
	`PROBABLE` BIGINT, 
	`SUSPECT` BIGINT, 
	closecontact_dikarantina BIGINT, 
	closecontact_discarded BIGINT, 
	closecontact_meninggal BIGINT, 
	confirmation_meninggal BIGINT, 
	confirmation_sembuh BIGINT, 
	kode_kab TEXT, 
	kode_prov TEXT, 
	nama_kab TEXT, 
	nama_prov TEXT, 
	probable_diisolasi BIGINT, 
	probable_discarded BIGINT, 
	probable_meninggal BIGINT, 
	suspect_diisolasi BIGINT, 
	suspect_discarded BIGINT, 
	suspect_meninggal BIGINT, 
	tanggal TEXT
)

]
(Background on this error at: http://sqlalche.me/e/14/e3q8); 1805)
[2023-11-26 18:20:26,958] {local_task_job.py:156} INFO - Task exited with return code 1
[2023-11-26 18:20:26,999] {local_task_job.py:273} INFO - 0 downstream tasks scheduled from follow-on schedule check
