[2023-11-26 14:26:17,573] {taskinstance.py:1159} INFO - Dependencies all met for <TaskInstance: data_covid_etl.ingest_staging_db scheduled__2023-11-21T00:00:00+00:00 [queued]>
[2023-11-26 14:26:17,597] {taskinstance.py:1159} INFO - Dependencies all met for <TaskInstance: data_covid_etl.ingest_staging_db scheduled__2023-11-21T00:00:00+00:00 [queued]>
[2023-11-26 14:26:17,597] {taskinstance.py:1356} INFO - 
--------------------------------------------------------------------------------
[2023-11-26 14:26:17,600] {taskinstance.py:1357} INFO - Starting attempt 1 of 6
[2023-11-26 14:26:17,600] {taskinstance.py:1358} INFO - 
--------------------------------------------------------------------------------
[2023-11-26 14:26:17,629] {taskinstance.py:1377} INFO - Executing <Task(PythonOperator): ingest_staging_db> on 2023-11-21 00:00:00+00:00
[2023-11-26 14:26:17,635] {standard_task_runner.py:52} INFO - Started process 680 to run task
[2023-11-26 14:26:17,645] {standard_task_runner.py:79} INFO - Running: ['***', 'tasks', 'run', 'data_covid_etl', 'ingest_staging_db', 'scheduled__2023-11-21T00:00:00+00:00', '--job-id', '19', '--raw', '--subdir', 'DAGS_FOLDER/get_data.py', '--cfg-path', '/tmp/tmpjygt1zi2', '--error-file', '/tmp/tmpd95gwr9t']
[2023-11-26 14:26:17,645] {standard_task_runner.py:80} INFO - Job 19: Subtask ingest_staging_db
[2023-11-26 14:26:17,770] {task_command.py:369} INFO - Running <TaskInstance: data_covid_etl.ingest_staging_db scheduled__2023-11-21T00:00:00+00:00 [running]> on host f384f2afcc4f
[2023-11-26 14:26:17,884] {taskinstance.py:1571} INFO - Exporting the following env vars:
AIRFLOW_CTX_DAG_OWNER=oce
AIRFLOW_CTX_DAG_ID=data_covid_etl
AIRFLOW_CTX_TASK_ID=ingest_staging_db
AIRFLOW_CTX_EXECUTION_DATE=2023-11-21T00:00:00+00:00
AIRFLOW_CTX_TRY_NUMBER=1
AIRFLOW_CTX_DAG_RUN_ID=scheduled__2023-11-21T00:00:00+00:00
[2023-11-26 14:26:19,274] {python.py:173} INFO - Done. Returned value was: None
[2023-11-26 14:26:19,285] {taskinstance.py:1400} INFO - Marking task as SUCCESS. dag_id=data_covid_etl, task_id=ingest_staging_db, execution_date=20231121T000000, start_date=20231126T142617, end_date=20231126T142619
[2023-11-26 14:26:19,309] {local_task_job.py:156} INFO - Task exited with return code 0
[2023-11-26 14:26:19,348] {local_task_job.py:273} INFO - 0 downstream tasks scheduled from follow-on schedule check
[2023-11-26 15:39:37,810] {taskinstance.py:1159} INFO - Dependencies all met for <TaskInstance: data_covid_etl.ingest_staging_db scheduled__2023-11-21T00:00:00+00:00 [queued]>
[2023-11-26 15:39:37,844] {taskinstance.py:1159} INFO - Dependencies all met for <TaskInstance: data_covid_etl.ingest_staging_db scheduled__2023-11-21T00:00:00+00:00 [queued]>
[2023-11-26 15:39:37,844] {taskinstance.py:1356} INFO - 
--------------------------------------------------------------------------------
[2023-11-26 15:39:37,844] {taskinstance.py:1357} INFO - Starting attempt 1 of 6
[2023-11-26 15:39:37,844] {taskinstance.py:1358} INFO - 
--------------------------------------------------------------------------------
[2023-11-26 15:39:37,866] {taskinstance.py:1377} INFO - Executing <Task(PythonOperator): ingest_staging_db> on 2023-11-21 00:00:00+00:00
[2023-11-26 15:39:37,871] {standard_task_runner.py:52} INFO - Started process 2546 to run task
[2023-11-26 15:39:37,880] {standard_task_runner.py:79} INFO - Running: ['***', 'tasks', 'run', 'data_covid_etl', 'ingest_staging_db', 'scheduled__2023-11-21T00:00:00+00:00', '--job-id', '56', '--raw', '--subdir', 'DAGS_FOLDER/get_data.py', '--cfg-path', '/tmp/tmpgn2u3y6t', '--error-file', '/tmp/tmp7nc1jfvu']
[2023-11-26 15:39:37,882] {standard_task_runner.py:80} INFO - Job 56: Subtask ingest_staging_db
[2023-11-26 15:39:37,994] {task_command.py:369} INFO - Running <TaskInstance: data_covid_etl.ingest_staging_db scheduled__2023-11-21T00:00:00+00:00 [running]> on host f384f2afcc4f
[2023-11-26 15:39:38,087] {taskinstance.py:1571} INFO - Exporting the following env vars:
AIRFLOW_CTX_DAG_OWNER=oce
AIRFLOW_CTX_DAG_ID=data_covid_etl
AIRFLOW_CTX_TASK_ID=ingest_staging_db
AIRFLOW_CTX_EXECUTION_DATE=2023-11-21T00:00:00+00:00
AIRFLOW_CTX_TRY_NUMBER=1
AIRFLOW_CTX_DAG_RUN_ID=scheduled__2023-11-21T00:00:00+00:00
[2023-11-26 15:39:57,858] {python.py:173} INFO - Done. Returned value was: None
[2023-11-26 15:39:57,870] {taskinstance.py:1400} INFO - Marking task as SUCCESS. dag_id=data_covid_etl, task_id=ingest_staging_db, execution_date=20231121T000000, start_date=20231126T153937, end_date=20231126T153957
[2023-11-26 15:39:57,900] {local_task_job.py:156} INFO - Task exited with return code 0
[2023-11-26 15:39:57,932] {local_task_job.py:273} INFO - 0 downstream tasks scheduled from follow-on schedule check
[2023-11-26 17:57:11,992] {taskinstance.py:1159} INFO - Dependencies all met for <TaskInstance: data_covid_etl.ingest_staging_db scheduled__2023-11-21T00:00:00+00:00 [queued]>
[2023-11-26 17:57:12,027] {taskinstance.py:1159} INFO - Dependencies all met for <TaskInstance: data_covid_etl.ingest_staging_db scheduled__2023-11-21T00:00:00+00:00 [queued]>
[2023-11-26 17:57:12,028] {taskinstance.py:1356} INFO - 
--------------------------------------------------------------------------------
[2023-11-26 17:57:12,028] {taskinstance.py:1357} INFO - Starting attempt 1 of 6
[2023-11-26 17:57:12,028] {taskinstance.py:1358} INFO - 
--------------------------------------------------------------------------------
[2023-11-26 17:57:12,082] {taskinstance.py:1377} INFO - Executing <Task(PythonOperator): ingest_staging_db> on 2023-11-21 00:00:00+00:00
[2023-11-26 17:57:12,101] {standard_task_runner.py:52} INFO - Started process 696 to run task
[2023-11-26 17:57:12,119] {standard_task_runner.py:79} INFO - Running: ['***', 'tasks', 'run', 'data_covid_etl', 'ingest_staging_db', 'scheduled__2023-11-21T00:00:00+00:00', '--job-id', '107', '--raw', '--subdir', 'DAGS_FOLDER/get_data.py', '--cfg-path', '/tmp/tmpga39a53y', '--error-file', '/tmp/tmp946wjxmc']
[2023-11-26 17:57:12,119] {standard_task_runner.py:80} INFO - Job 107: Subtask ingest_staging_db
[2023-11-26 17:57:12,316] {task_command.py:369} INFO - Running <TaskInstance: data_covid_etl.ingest_staging_db scheduled__2023-11-21T00:00:00+00:00 [running]> on host 79a606f4be36
[2023-11-26 17:57:12,540] {taskinstance.py:1571} INFO - Exporting the following env vars:
AIRFLOW_CTX_DAG_OWNER=oce
AIRFLOW_CTX_DAG_ID=data_covid_etl
AIRFLOW_CTX_TASK_ID=ingest_staging_db
AIRFLOW_CTX_EXECUTION_DATE=2023-11-21T00:00:00+00:00
AIRFLOW_CTX_TRY_NUMBER=1
AIRFLOW_CTX_DAG_RUN_ID=scheduled__2023-11-21T00:00:00+00:00
[2023-11-26 17:57:12,926] {taskinstance.py:1889} ERROR - Task failed with exception
Traceback (most recent call last):
  File "/home/airflow/.local/lib/python3.7/site-packages/sqlalchemy/engine/base.py", line 1706, in _execute_context
    cursor, statement, parameters, context
  File "/home/airflow/.local/lib/python3.7/site-packages/sqlalchemy/engine/default.py", line 716, in do_execute
    cursor.execute(statement, parameters)
  File "/home/airflow/.local/lib/python3.7/site-packages/MySQLdb/cursors.py", line 206, in execute
    res = self._query(query)
  File "/home/airflow/.local/lib/python3.7/site-packages/MySQLdb/cursors.py", line 319, in _query
    db.query(q)
  File "/home/airflow/.local/lib/python3.7/site-packages/MySQLdb/connections.py", line 254, in query
    _mysql.connection.query(self, query)
MySQLdb._exceptions.OperationalError: (1050, "Table 'covid_jabar' already exists")

The above exception was the direct cause of the following exception:

Traceback (most recent call last):
  File "/home/airflow/.local/lib/python3.7/site-packages/airflow/operators/python.py", line 171, in execute
    return_value = self.execute_callable()
  File "/home/airflow/.local/lib/python3.7/site-packages/airflow/operators/python.py", line 189, in execute_callable
    return self.python_callable(*self.op_args, **self.op_kwargs)
  File "/opt/airflow/dags/get_data.py", line 34, in ingest_data_staging
    df.to_sql("covid_jabar", staging_db_constring, if_exists="replace", index=False)
  File "/home/airflow/.local/lib/python3.7/site-packages/pandas/core/generic.py", line 2882, in to_sql
    method=method,
  File "/home/airflow/.local/lib/python3.7/site-packages/pandas/io/sql.py", line 728, in to_sql
    **engine_kwargs,
  File "/home/airflow/.local/lib/python3.7/site-packages/pandas/io/sql.py", line 1758, in to_sql
    dtype=dtype,
  File "/home/airflow/.local/lib/python3.7/site-packages/pandas/io/sql.py", line 1650, in prep_table
    table.create()
  File "/home/airflow/.local/lib/python3.7/site-packages/pandas/io/sql.py", line 867, in create
    self._execute_create()
  File "/home/airflow/.local/lib/python3.7/site-packages/pandas/io/sql.py", line 853, in _execute_create
    self.table.create()
  File "/home/airflow/.local/lib/python3.7/site-packages/sqlalchemy/sql/schema.py", line 943, in create
    bind._run_ddl_visitor(ddl.SchemaGenerator, self, checkfirst=checkfirst)
  File "/home/airflow/.local/lib/python3.7/site-packages/sqlalchemy/engine/base.py", line 3008, in _run_ddl_visitor
    conn._run_ddl_visitor(visitorcallable, element, **kwargs)
  File "/home/airflow/.local/lib/python3.7/site-packages/sqlalchemy/engine/base.py", line 2016, in _run_ddl_visitor
    visitorcallable(self.dialect, self, **kwargs).traverse_single(element)
  File "/home/airflow/.local/lib/python3.7/site-packages/sqlalchemy/sql/visitors.py", line 483, in traverse_single
    return meth(obj, **kw)
  File "/home/airflow/.local/lib/python3.7/site-packages/sqlalchemy/sql/ddl.py", line 895, in visit_table
    include_foreign_key_constraints,  # noqa
  File "/home/airflow/.local/lib/python3.7/site-packages/sqlalchemy/engine/base.py", line 1200, in execute
    return meth(self, multiparams, params, _EMPTY_EXECUTION_OPTS)
  File "/home/airflow/.local/lib/python3.7/site-packages/sqlalchemy/sql/ddl.py", line 78, in _execute_on_connection
    self, multiparams, params, execution_options
  File "/home/airflow/.local/lib/python3.7/site-packages/sqlalchemy/engine/base.py", line 1296, in _execute_ddl
    compiled,
  File "/home/airflow/.local/lib/python3.7/site-packages/sqlalchemy/engine/base.py", line 1749, in _execute_context
    e, statement, parameters, cursor, context
  File "/home/airflow/.local/lib/python3.7/site-packages/sqlalchemy/engine/base.py", line 1930, in _handle_dbapi_exception
    sqlalchemy_exception, with_traceback=exc_info[2], from_=e
  File "/home/airflow/.local/lib/python3.7/site-packages/sqlalchemy/util/compat.py", line 211, in raise_
    raise exception
  File "/home/airflow/.local/lib/python3.7/site-packages/sqlalchemy/engine/base.py", line 1706, in _execute_context
    cursor, statement, parameters, context
  File "/home/airflow/.local/lib/python3.7/site-packages/sqlalchemy/engine/default.py", line 716, in do_execute
    cursor.execute(statement, parameters)
  File "/home/airflow/.local/lib/python3.7/site-packages/MySQLdb/cursors.py", line 206, in execute
    res = self._query(query)
  File "/home/airflow/.local/lib/python3.7/site-packages/MySQLdb/cursors.py", line 319, in _query
    db.query(q)
  File "/home/airflow/.local/lib/python3.7/site-packages/MySQLdb/connections.py", line 254, in query
    _mysql.connection.query(self, query)
sqlalchemy.exc.OperationalError: (MySQLdb._exceptions.OperationalError) (1050, "Table 'covid_jabar' already exists")
[SQL: 
CREATE TABLE covid_jabar (
	`CLOSECONTACT` BIGINT, 
	`CONFIRMATION` BIGINT, 
	`PROBABLE` BIGINT, 
	`SUSPECT` BIGINT, 
	closecontact_dikarantina BIGINT, 
	closecontact_discarded BIGINT, 
	closecontact_meninggal BIGINT, 
	confirmation_meninggal BIGINT, 
	confirmation_sembuh BIGINT, 
	kode_kab TEXT, 
	kode_prov TEXT, 
	nama_kab TEXT, 
	nama_prov TEXT, 
	probable_diisolasi BIGINT, 
	probable_discarded BIGINT, 
	probable_meninggal BIGINT, 
	suspect_diisolasi BIGINT, 
	suspect_discarded BIGINT, 
	suspect_meninggal BIGINT, 
	tanggal TEXT
)

]
(Background on this error at: http://sqlalche.me/e/14/e3q8)
[2023-11-26 17:57:12,943] {taskinstance.py:1400} INFO - Marking task as UP_FOR_RETRY. dag_id=data_covid_etl, task_id=ingest_staging_db, execution_date=20231121T000000, start_date=20231126T175711, end_date=20231126T175712
[2023-11-26 17:57:12,970] {standard_task_runner.py:97} ERROR - Failed to execute job 107 for task ingest_staging_db ((MySQLdb._exceptions.OperationalError) (1050, "Table 'covid_jabar' already exists")
[SQL: 
CREATE TABLE covid_jabar (
	`CLOSECONTACT` BIGINT, 
	`CONFIRMATION` BIGINT, 
	`PROBABLE` BIGINT, 
	`SUSPECT` BIGINT, 
	closecontact_dikarantina BIGINT, 
	closecontact_discarded BIGINT, 
	closecontact_meninggal BIGINT, 
	confirmation_meninggal BIGINT, 
	confirmation_sembuh BIGINT, 
	kode_kab TEXT, 
	kode_prov TEXT, 
	nama_kab TEXT, 
	nama_prov TEXT, 
	probable_diisolasi BIGINT, 
	probable_discarded BIGINT, 
	probable_meninggal BIGINT, 
	suspect_diisolasi BIGINT, 
	suspect_discarded BIGINT, 
	suspect_meninggal BIGINT, 
	tanggal TEXT
)

]
(Background on this error at: http://sqlalche.me/e/14/e3q8); 696)
[2023-11-26 17:57:13,019] {local_task_job.py:156} INFO - Task exited with return code 1
[2023-11-26 17:57:13,106] {local_task_job.py:273} INFO - 0 downstream tasks scheduled from follow-on schedule check
[2023-11-26 18:00:54,424] {taskinstance.py:1159} INFO - Dependencies all met for <TaskInstance: data_covid_etl.ingest_staging_db scheduled__2023-11-21T00:00:00+00:00 [queued]>
[2023-11-26 18:00:54,444] {taskinstance.py:1159} INFO - Dependencies all met for <TaskInstance: data_covid_etl.ingest_staging_db scheduled__2023-11-21T00:00:00+00:00 [queued]>
[2023-11-26 18:00:54,445] {taskinstance.py:1356} INFO - 
--------------------------------------------------------------------------------
[2023-11-26 18:00:54,445] {taskinstance.py:1357} INFO - Starting attempt 1 of 6
[2023-11-26 18:00:54,445] {taskinstance.py:1358} INFO - 
--------------------------------------------------------------------------------
[2023-11-26 18:00:54,464] {taskinstance.py:1377} INFO - Executing <Task(PythonOperator): ingest_staging_db> on 2023-11-21 00:00:00+00:00
[2023-11-26 18:00:54,469] {standard_task_runner.py:52} INFO - Started process 917 to run task
[2023-11-26 18:00:54,473] {standard_task_runner.py:79} INFO - Running: ['***', 'tasks', 'run', 'data_covid_etl', 'ingest_staging_db', 'scheduled__2023-11-21T00:00:00+00:00', '--job-id', '154', '--raw', '--subdir', 'DAGS_FOLDER/get_data.py', '--cfg-path', '/tmp/tmpjb6yv1fw', '--error-file', '/tmp/tmplljrpsbc']
[2023-11-26 18:00:54,475] {standard_task_runner.py:80} INFO - Job 154: Subtask ingest_staging_db
[2023-11-26 18:00:54,572] {task_command.py:369} INFO - Running <TaskInstance: data_covid_etl.ingest_staging_db scheduled__2023-11-21T00:00:00+00:00 [running]> on host 79a606f4be36
[2023-11-26 18:00:54,684] {taskinstance.py:1571} INFO - Exporting the following env vars:
AIRFLOW_CTX_DAG_OWNER=oce
AIRFLOW_CTX_DAG_ID=data_covid_etl
AIRFLOW_CTX_TASK_ID=ingest_staging_db
AIRFLOW_CTX_EXECUTION_DATE=2023-11-21T00:00:00+00:00
AIRFLOW_CTX_TRY_NUMBER=1
AIRFLOW_CTX_DAG_RUN_ID=scheduled__2023-11-21T00:00:00+00:00
[2023-11-26 18:00:55,228] {python.py:173} INFO - Done. Returned value was: None
[2023-11-26 18:00:55,239] {taskinstance.py:1400} INFO - Marking task as SUCCESS. dag_id=data_covid_etl, task_id=ingest_staging_db, execution_date=20231121T000000, start_date=20231126T180054, end_date=20231126T180055
[2023-11-26 18:00:55,288] {local_task_job.py:156} INFO - Task exited with return code 0
[2023-11-26 18:00:55,422] {local_task_job.py:273} INFO - 0 downstream tasks scheduled from follow-on schedule check
[2023-11-26 18:02:40,598] {taskinstance.py:1159} INFO - Dependencies all met for <TaskInstance: data_covid_etl.ingest_staging_db scheduled__2023-11-21T00:00:00+00:00 [queued]>
[2023-11-26 18:02:40,607] {taskinstance.py:1159} INFO - Dependencies all met for <TaskInstance: data_covid_etl.ingest_staging_db scheduled__2023-11-21T00:00:00+00:00 [queued]>
[2023-11-26 18:02:40,607] {taskinstance.py:1356} INFO - 
--------------------------------------------------------------------------------
[2023-11-26 18:02:40,607] {taskinstance.py:1357} INFO - Starting attempt 1 of 4
[2023-11-26 18:02:40,607] {taskinstance.py:1358} INFO - 
--------------------------------------------------------------------------------
[2023-11-26 18:02:40,620] {taskinstance.py:1377} INFO - Executing <Task(PythonOperator): ingest_staging_db> on 2023-11-21 00:00:00+00:00
[2023-11-26 18:02:40,629] {standard_task_runner.py:52} INFO - Started process 1008 to run task
[2023-11-26 18:02:40,635] {standard_task_runner.py:79} INFO - Running: ['***', 'tasks', 'run', 'data_covid_etl', 'ingest_staging_db', 'scheduled__2023-11-21T00:00:00+00:00', '--job-id', '171', '--raw', '--subdir', 'DAGS_FOLDER/get_data.py', '--cfg-path', '/tmp/tmpd5b9_gwo', '--error-file', '/tmp/tmp4xtupl5n']
[2023-11-26 18:02:40,636] {standard_task_runner.py:80} INFO - Job 171: Subtask ingest_staging_db
[2023-11-26 18:02:40,707] {task_command.py:369} INFO - Running <TaskInstance: data_covid_etl.ingest_staging_db scheduled__2023-11-21T00:00:00+00:00 [running]> on host 79a606f4be36
[2023-11-26 18:02:40,789] {taskinstance.py:1571} INFO - Exporting the following env vars:
AIRFLOW_CTX_DAG_OWNER=oce
AIRFLOW_CTX_DAG_ID=data_covid_etl
AIRFLOW_CTX_TASK_ID=ingest_staging_db
AIRFLOW_CTX_EXECUTION_DATE=2023-11-21T00:00:00+00:00
AIRFLOW_CTX_TRY_NUMBER=1
AIRFLOW_CTX_DAG_RUN_ID=scheduled__2023-11-21T00:00:00+00:00
[2023-11-26 18:02:41,240] {taskinstance.py:1889} ERROR - Task failed with exception
Traceback (most recent call last):
  File "/home/airflow/.local/lib/python3.7/site-packages/sqlalchemy/engine/base.py", line 1706, in _execute_context
    cursor, statement, parameters, context
  File "/home/airflow/.local/lib/python3.7/site-packages/sqlalchemy/engine/default.py", line 716, in do_execute
    cursor.execute(statement, parameters)
  File "/home/airflow/.local/lib/python3.7/site-packages/MySQLdb/cursors.py", line 206, in execute
    res = self._query(query)
  File "/home/airflow/.local/lib/python3.7/site-packages/MySQLdb/cursors.py", line 319, in _query
    db.query(q)
  File "/home/airflow/.local/lib/python3.7/site-packages/MySQLdb/connections.py", line 254, in query
    _mysql.connection.query(self, query)
MySQLdb._exceptions.OperationalError: (1051, "Unknown table 'finalproject.covid_jabar'")

The above exception was the direct cause of the following exception:

Traceback (most recent call last):
  File "/home/airflow/.local/lib/python3.7/site-packages/airflow/operators/python.py", line 171, in execute
    return_value = self.execute_callable()
  File "/home/airflow/.local/lib/python3.7/site-packages/airflow/operators/python.py", line 189, in execute_callable
    return self.python_callable(*self.op_args, **self.op_kwargs)
  File "/opt/airflow/dags/get_data.py", line 35, in ingest_data_staging
    df.to_sql("covid_jabar", staging_db_constring, if_exists="replace", index=False)
  File "/home/airflow/.local/lib/python3.7/site-packages/pandas/core/generic.py", line 2882, in to_sql
    method=method,
  File "/home/airflow/.local/lib/python3.7/site-packages/pandas/io/sql.py", line 728, in to_sql
    **engine_kwargs,
  File "/home/airflow/.local/lib/python3.7/site-packages/pandas/io/sql.py", line 1758, in to_sql
    dtype=dtype,
  File "/home/airflow/.local/lib/python3.7/site-packages/pandas/io/sql.py", line 1650, in prep_table
    table.create()
  File "/home/airflow/.local/lib/python3.7/site-packages/pandas/io/sql.py", line 860, in create
    self.pd_sql.drop_table(self.name, self.schema)
  File "/home/airflow/.local/lib/python3.7/site-packages/pandas/io/sql.py", line 1810, in drop_table
    self.get_table(table_name, schema).drop()
  File "/home/airflow/.local/lib/python3.7/site-packages/sqlalchemy/sql/schema.py", line 960, in drop
    bind._run_ddl_visitor(ddl.SchemaDropper, self, checkfirst=checkfirst)
  File "/home/airflow/.local/lib/python3.7/site-packages/sqlalchemy/engine/base.py", line 3008, in _run_ddl_visitor
    conn._run_ddl_visitor(visitorcallable, element, **kwargs)
  File "/home/airflow/.local/lib/python3.7/site-packages/sqlalchemy/engine/base.py", line 2016, in _run_ddl_visitor
    visitorcallable(self.dialect, self, **kwargs).traverse_single(element)
  File "/home/airflow/.local/lib/python3.7/site-packages/sqlalchemy/sql/visitors.py", line 483, in traverse_single
    return meth(obj, **kw)
  File "/home/airflow/.local/lib/python3.7/site-packages/sqlalchemy/sql/ddl.py", line 1097, in visit_table
    self.connection.execute(DropTable(table))
  File "/home/airflow/.local/lib/python3.7/site-packages/sqlalchemy/engine/base.py", line 1200, in execute
    return meth(self, multiparams, params, _EMPTY_EXECUTION_OPTS)
  File "/home/airflow/.local/lib/python3.7/site-packages/sqlalchemy/sql/ddl.py", line 78, in _execute_on_connection
    self, multiparams, params, execution_options
  File "/home/airflow/.local/lib/python3.7/site-packages/sqlalchemy/engine/base.py", line 1296, in _execute_ddl
    compiled,
  File "/home/airflow/.local/lib/python3.7/site-packages/sqlalchemy/engine/base.py", line 1749, in _execute_context
    e, statement, parameters, cursor, context
  File "/home/airflow/.local/lib/python3.7/site-packages/sqlalchemy/engine/base.py", line 1930, in _handle_dbapi_exception
    sqlalchemy_exception, with_traceback=exc_info[2], from_=e
  File "/home/airflow/.local/lib/python3.7/site-packages/sqlalchemy/util/compat.py", line 211, in raise_
    raise exception
  File "/home/airflow/.local/lib/python3.7/site-packages/sqlalchemy/engine/base.py", line 1706, in _execute_context
    cursor, statement, parameters, context
  File "/home/airflow/.local/lib/python3.7/site-packages/sqlalchemy/engine/default.py", line 716, in do_execute
    cursor.execute(statement, parameters)
  File "/home/airflow/.local/lib/python3.7/site-packages/MySQLdb/cursors.py", line 206, in execute
    res = self._query(query)
  File "/home/airflow/.local/lib/python3.7/site-packages/MySQLdb/cursors.py", line 319, in _query
    db.query(q)
  File "/home/airflow/.local/lib/python3.7/site-packages/MySQLdb/connections.py", line 254, in query
    _mysql.connection.query(self, query)
sqlalchemy.exc.OperationalError: (MySQLdb._exceptions.OperationalError) (1051, "Unknown table 'finalproject.covid_jabar'")
[SQL: 
DROP TABLE covid_jabar]
(Background on this error at: http://sqlalche.me/e/14/e3q8)
[2023-11-26 18:02:41,252] {taskinstance.py:1400} INFO - Marking task as UP_FOR_RETRY. dag_id=data_covid_etl, task_id=ingest_staging_db, execution_date=20231121T000000, start_date=20231126T180240, end_date=20231126T180241
[2023-11-26 18:02:41,264] {standard_task_runner.py:97} ERROR - Failed to execute job 171 for task ingest_staging_db ((MySQLdb._exceptions.OperationalError) (1051, "Unknown table 'finalproject.covid_jabar'")
[SQL: 
DROP TABLE covid_jabar]
(Background on this error at: http://sqlalche.me/e/14/e3q8); 1008)
[2023-11-26 18:02:41,288] {local_task_job.py:156} INFO - Task exited with return code 1
[2023-11-26 18:02:41,347] {local_task_job.py:273} INFO - 0 downstream tasks scheduled from follow-on schedule check
[2023-11-26 18:05:34,923] {taskinstance.py:1159} INFO - Dependencies all met for <TaskInstance: data_covid_etl.ingest_staging_db scheduled__2023-11-21T00:00:00+00:00 [queued]>
[2023-11-26 18:05:34,937] {taskinstance.py:1159} INFO - Dependencies all met for <TaskInstance: data_covid_etl.ingest_staging_db scheduled__2023-11-21T00:00:00+00:00 [queued]>
[2023-11-26 18:05:34,937] {taskinstance.py:1356} INFO - 
--------------------------------------------------------------------------------
[2023-11-26 18:05:34,937] {taskinstance.py:1357} INFO - Starting attempt 1 of 3
[2023-11-26 18:05:34,938] {taskinstance.py:1358} INFO - 
--------------------------------------------------------------------------------
[2023-11-26 18:05:34,958] {taskinstance.py:1377} INFO - Executing <Task(PythonOperator): ingest_staging_db> on 2023-11-21 00:00:00+00:00
[2023-11-26 18:05:34,964] {standard_task_runner.py:52} INFO - Started process 1151 to run task
[2023-11-26 18:05:34,967] {standard_task_runner.py:79} INFO - Running: ['***', 'tasks', 'run', 'data_covid_etl', 'ingest_staging_db', 'scheduled__2023-11-21T00:00:00+00:00', '--job-id', '192', '--raw', '--subdir', 'DAGS_FOLDER/get_data.py', '--cfg-path', '/tmp/tmpacqpbl6t', '--error-file', '/tmp/tmpoxzcht5y']
[2023-11-26 18:05:34,968] {standard_task_runner.py:80} INFO - Job 192: Subtask ingest_staging_db
[2023-11-26 18:05:35,038] {task_command.py:369} INFO - Running <TaskInstance: data_covid_etl.ingest_staging_db scheduled__2023-11-21T00:00:00+00:00 [running]> on host 79a606f4be36
[2023-11-26 18:05:35,122] {taskinstance.py:1571} INFO - Exporting the following env vars:
AIRFLOW_CTX_DAG_OWNER=oce
AIRFLOW_CTX_DAG_ID=data_covid_etl
AIRFLOW_CTX_TASK_ID=ingest_staging_db
AIRFLOW_CTX_EXECUTION_DATE=2023-11-21T00:00:00+00:00
AIRFLOW_CTX_TRY_NUMBER=1
AIRFLOW_CTX_DAG_RUN_ID=scheduled__2023-11-21T00:00:00+00:00
[2023-11-26 18:05:35,515] {taskinstance.py:1889} ERROR - Task failed with exception
Traceback (most recent call last):
  File "/home/airflow/.local/lib/python3.7/site-packages/sqlalchemy/engine/base.py", line 1706, in _execute_context
    cursor, statement, parameters, context
  File "/home/airflow/.local/lib/python3.7/site-packages/sqlalchemy/engine/default.py", line 716, in do_execute
    cursor.execute(statement, parameters)
  File "/home/airflow/.local/lib/python3.7/site-packages/MySQLdb/cursors.py", line 206, in execute
    res = self._query(query)
  File "/home/airflow/.local/lib/python3.7/site-packages/MySQLdb/cursors.py", line 319, in _query
    db.query(q)
  File "/home/airflow/.local/lib/python3.7/site-packages/MySQLdb/connections.py", line 254, in query
    _mysql.connection.query(self, query)
MySQLdb._exceptions.ProgrammingError: (1146, "Table 'finalproject.covid_jabar' doesn't exist")

The above exception was the direct cause of the following exception:

Traceback (most recent call last):
  File "/home/airflow/.local/lib/python3.7/site-packages/sqlalchemy/dialects/mysql/base.py", line 3373, in _show_create_table
    ).exec_driver_sql(st)
  File "/home/airflow/.local/lib/python3.7/site-packages/sqlalchemy/engine/base.py", line 1580, in exec_driver_sql
    future=True,
  File "/home/airflow/.local/lib/python3.7/site-packages/sqlalchemy/engine/base.py", line 1491, in _exec_driver_sql
    distilled_parameters,
  File "/home/airflow/.local/lib/python3.7/site-packages/sqlalchemy/engine/base.py", line 1749, in _execute_context
    e, statement, parameters, cursor, context
  File "/home/airflow/.local/lib/python3.7/site-packages/sqlalchemy/engine/base.py", line 1930, in _handle_dbapi_exception
    sqlalchemy_exception, with_traceback=exc_info[2], from_=e
  File "/home/airflow/.local/lib/python3.7/site-packages/sqlalchemy/util/compat.py", line 211, in raise_
    raise exception
  File "/home/airflow/.local/lib/python3.7/site-packages/sqlalchemy/engine/base.py", line 1706, in _execute_context
    cursor, statement, parameters, context
  File "/home/airflow/.local/lib/python3.7/site-packages/sqlalchemy/engine/default.py", line 716, in do_execute
    cursor.execute(statement, parameters)
  File "/home/airflow/.local/lib/python3.7/site-packages/MySQLdb/cursors.py", line 206, in execute
    res = self._query(query)
  File "/home/airflow/.local/lib/python3.7/site-packages/MySQLdb/cursors.py", line 319, in _query
    db.query(q)
  File "/home/airflow/.local/lib/python3.7/site-packages/MySQLdb/connections.py", line 254, in query
    _mysql.connection.query(self, query)
sqlalchemy.exc.ProgrammingError: (MySQLdb._exceptions.ProgrammingError) (1146, "Table 'finalproject.covid_jabar' doesn't exist")
[SQL: SHOW CREATE TABLE `covid_jabar`]
(Background on this error at: http://sqlalche.me/e/14/f405)

The above exception was the direct cause of the following exception:

Traceback (most recent call last):
  File "/home/airflow/.local/lib/python3.7/site-packages/airflow/operators/python.py", line 171, in execute
    return_value = self.execute_callable()
  File "/home/airflow/.local/lib/python3.7/site-packages/airflow/operators/python.py", line 189, in execute_callable
    return self.python_callable(*self.op_args, **self.op_kwargs)
  File "/opt/airflow/dags/get_data.py", line 35, in ingest_data_staging
    df.to_sql("covid_jabar", staging_db_constring, if_exists="replace", index=False)
  File "/home/airflow/.local/lib/python3.7/site-packages/pandas/core/generic.py", line 2882, in to_sql
    method=method,
  File "/home/airflow/.local/lib/python3.7/site-packages/pandas/io/sql.py", line 728, in to_sql
    **engine_kwargs,
  File "/home/airflow/.local/lib/python3.7/site-packages/pandas/io/sql.py", line 1758, in to_sql
    dtype=dtype,
  File "/home/airflow/.local/lib/python3.7/site-packages/pandas/io/sql.py", line 1650, in prep_table
    table.create()
  File "/home/airflow/.local/lib/python3.7/site-packages/pandas/io/sql.py", line 860, in create
    self.pd_sql.drop_table(self.name, self.schema)
  File "/home/airflow/.local/lib/python3.7/site-packages/pandas/io/sql.py", line 1809, in drop_table
    self.meta.reflect(only=[table_name], schema=schema)
  File "/home/airflow/.local/lib/python3.7/site-packages/sqlalchemy/sql/schema.py", line 4715, in reflect
    Table(name, self, **reflect_opts)
  File "<string>", line 2, in __new__
  File "/home/airflow/.local/lib/python3.7/site-packages/sqlalchemy/util/deprecations.py", line 298, in warned
    return fn(*args, **kwargs)
  File "/home/airflow/.local/lib/python3.7/site-packages/sqlalchemy/sql/schema.py", line 600, in __new__
    metadata._remove_table(name, schema)
  File "/home/airflow/.local/lib/python3.7/site-packages/sqlalchemy/util/langhelpers.py", line 72, in __exit__
    with_traceback=exc_tb,
  File "/home/airflow/.local/lib/python3.7/site-packages/sqlalchemy/util/compat.py", line 211, in raise_
    raise exception
  File "/home/airflow/.local/lib/python3.7/site-packages/sqlalchemy/sql/schema.py", line 595, in __new__
    table._init(name, metadata, *args, **kw)
  File "/home/airflow/.local/lib/python3.7/site-packages/sqlalchemy/sql/schema.py", line 675, in _init
    resolve_fks=resolve_fks,
  File "/home/airflow/.local/lib/python3.7/site-packages/sqlalchemy/sql/schema.py", line 710, in _autoload
    _extend_on=_extend_on,
  File "/home/airflow/.local/lib/python3.7/site-packages/sqlalchemy/engine/reflection.py", line 758, in reflect_table
    table_name, schema, **table.dialect_kwargs
  File "/home/airflow/.local/lib/python3.7/site-packages/sqlalchemy/engine/reflection.py", line 399, in get_table_options
    conn, table_name, schema, info_cache=self.info_cache, **kw
  File "<string>", line 2, in get_table_options
  File "/home/airflow/.local/lib/python3.7/site-packages/sqlalchemy/engine/reflection.py", line 55, in cache
    ret = fn(self, con, *args, **kw)
  File "/home/airflow/.local/lib/python3.7/site-packages/sqlalchemy/dialects/mysql/base.py", line 2997, in get_table_options
    connection, table_name, schema, **kw
  File "/home/airflow/.local/lib/python3.7/site-packages/sqlalchemy/dialects/mysql/base.py", line 3249, in _parsed_state_or_create
    info_cache=kw.get("info_cache", None),
  File "<string>", line 2, in _setup_parser
  File "/home/airflow/.local/lib/python3.7/site-packages/sqlalchemy/engine/reflection.py", line 55, in cache
    ret = fn(self, con, *args, **kw)
  File "/home/airflow/.local/lib/python3.7/site-packages/sqlalchemy/dialects/mysql/base.py", line 3273, in _setup_parser
    connection, None, charset, full_name=full_name
  File "/home/airflow/.local/lib/python3.7/site-packages/sqlalchemy/dialects/mysql/base.py", line 3376, in _show_create_table
    util.raise_(exc.NoSuchTableError(full_name), replace_context=e)
  File "/home/airflow/.local/lib/python3.7/site-packages/sqlalchemy/util/compat.py", line 211, in raise_
    raise exception
sqlalchemy.exc.NoSuchTableError: `covid_jabar`
[2023-11-26 18:05:35,536] {taskinstance.py:1400} INFO - Marking task as UP_FOR_RETRY. dag_id=data_covid_etl, task_id=ingest_staging_db, execution_date=20231121T000000, start_date=20231126T180534, end_date=20231126T180535
[2023-11-26 18:05:35,551] {standard_task_runner.py:97} ERROR - Failed to execute job 192 for task ingest_staging_db (`covid_jabar`; 1151)
[2023-11-26 18:05:35,579] {local_task_job.py:156} INFO - Task exited with return code 1
[2023-11-26 18:05:35,656] {local_task_job.py:273} INFO - 0 downstream tasks scheduled from follow-on schedule check
[2023-11-26 18:08:46,770] {taskinstance.py:1159} INFO - Dependencies all met for <TaskInstance: data_covid_etl.ingest_staging_db scheduled__2023-11-21T00:00:00+00:00 [queued]>
[2023-11-26 18:08:46,795] {taskinstance.py:1159} INFO - Dependencies all met for <TaskInstance: data_covid_etl.ingest_staging_db scheduled__2023-11-21T00:00:00+00:00 [queued]>
[2023-11-26 18:08:46,796] {taskinstance.py:1356} INFO - 
--------------------------------------------------------------------------------
[2023-11-26 18:08:46,796] {taskinstance.py:1357} INFO - Starting attempt 1 of 3
[2023-11-26 18:08:46,796] {taskinstance.py:1358} INFO - 
--------------------------------------------------------------------------------
[2023-11-26 18:08:46,826] {taskinstance.py:1377} INFO - Executing <Task(PythonOperator): ingest_staging_db> on 2023-11-21 00:00:00+00:00
[2023-11-26 18:08:46,832] {standard_task_runner.py:52} INFO - Started process 1327 to run task
[2023-11-26 18:08:46,845] {standard_task_runner.py:79} INFO - Running: ['***', 'tasks', 'run', 'data_covid_etl', 'ingest_staging_db', 'scheduled__2023-11-21T00:00:00+00:00', '--job-id', '217', '--raw', '--subdir', 'DAGS_FOLDER/get_data.py', '--cfg-path', '/tmp/tmpavos5pg7', '--error-file', '/tmp/tmpf0a8dz8y']
[2023-11-26 18:08:46,847] {standard_task_runner.py:80} INFO - Job 217: Subtask ingest_staging_db
[2023-11-26 18:08:46,936] {task_command.py:369} INFO - Running <TaskInstance: data_covid_etl.ingest_staging_db scheduled__2023-11-21T00:00:00+00:00 [running]> on host 79a606f4be36
[2023-11-26 18:08:47,057] {taskinstance.py:1571} INFO - Exporting the following env vars:
AIRFLOW_CTX_DAG_OWNER=oce
AIRFLOW_CTX_DAG_ID=data_covid_etl
AIRFLOW_CTX_TASK_ID=ingest_staging_db
AIRFLOW_CTX_EXECUTION_DATE=2023-11-21T00:00:00+00:00
AIRFLOW_CTX_TRY_NUMBER=1
AIRFLOW_CTX_DAG_RUN_ID=scheduled__2023-11-21T00:00:00+00:00
[2023-11-26 18:08:47,578] {python.py:173} INFO - Done. Returned value was: None
[2023-11-26 18:08:47,590] {taskinstance.py:1400} INFO - Marking task as SUCCESS. dag_id=data_covid_etl, task_id=ingest_staging_db, execution_date=20231121T000000, start_date=20231126T180846, end_date=20231126T180847
[2023-11-26 18:08:47,620] {local_task_job.py:156} INFO - Task exited with return code 0
[2023-11-26 18:08:47,669] {local_task_job.py:273} INFO - 1 downstream tasks scheduled from follow-on schedule check
[2023-11-26 18:15:24,268] {taskinstance.py:1159} INFO - Dependencies all met for <TaskInstance: data_covid_etl.ingest_staging_db scheduled__2023-11-21T00:00:00+00:00 [queued]>
[2023-11-26 18:15:24,287] {taskinstance.py:1159} INFO - Dependencies all met for <TaskInstance: data_covid_etl.ingest_staging_db scheduled__2023-11-21T00:00:00+00:00 [queued]>
[2023-11-26 18:15:24,287] {taskinstance.py:1356} INFO - 
--------------------------------------------------------------------------------
[2023-11-26 18:15:24,287] {taskinstance.py:1357} INFO - Starting attempt 1 of 3
[2023-11-26 18:15:24,287] {taskinstance.py:1358} INFO - 
--------------------------------------------------------------------------------
[2023-11-26 18:15:24,321] {taskinstance.py:1377} INFO - Executing <Task(PythonOperator): ingest_staging_db> on 2023-11-21 00:00:00+00:00
[2023-11-26 18:15:24,327] {standard_task_runner.py:52} INFO - Started process 1631 to run task
[2023-11-26 18:15:24,341] {standard_task_runner.py:79} INFO - Running: ['***', 'tasks', 'run', 'data_covid_etl', 'ingest_staging_db', 'scheduled__2023-11-21T00:00:00+00:00', '--job-id', '262', '--raw', '--subdir', 'DAGS_FOLDER/get_data.py', '--cfg-path', '/tmp/tmppjg2hsu_', '--error-file', '/tmp/tmpyqh_2a7f']
[2023-11-26 18:15:24,341] {standard_task_runner.py:80} INFO - Job 262: Subtask ingest_staging_db
[2023-11-26 18:15:24,446] {task_command.py:369} INFO - Running <TaskInstance: data_covid_etl.ingest_staging_db scheduled__2023-11-21T00:00:00+00:00 [running]> on host 79a606f4be36
[2023-11-26 18:15:24,561] {taskinstance.py:1571} INFO - Exporting the following env vars:
AIRFLOW_CTX_DAG_OWNER=oce
AIRFLOW_CTX_DAG_ID=data_covid_etl
AIRFLOW_CTX_TASK_ID=ingest_staging_db
AIRFLOW_CTX_EXECUTION_DATE=2023-11-21T00:00:00+00:00
AIRFLOW_CTX_TRY_NUMBER=1
AIRFLOW_CTX_DAG_RUN_ID=scheduled__2023-11-21T00:00:00+00:00
[2023-11-26 18:15:25,648] {python.py:173} INFO - Done. Returned value was: None
[2023-11-26 18:15:25,660] {taskinstance.py:1400} INFO - Marking task as SUCCESS. dag_id=data_covid_etl, task_id=ingest_staging_db, execution_date=20231121T000000, start_date=20231126T181524, end_date=20231126T181525
[2023-11-26 18:15:25,683] {local_task_job.py:156} INFO - Task exited with return code 0
[2023-11-26 18:15:25,742] {local_task_job.py:273} INFO - 1 downstream tasks scheduled from follow-on schedule check
