[2023-11-26 15:39:40,162] {taskinstance.py:1159} INFO - Dependencies all met for <TaskInstance: data_covid_etl.create_dim_province scheduled__2023-11-25T00:00:00+00:00 [queued]>
[2023-11-26 15:39:40,205] {taskinstance.py:1159} INFO - Dependencies all met for <TaskInstance: data_covid_etl.create_dim_province scheduled__2023-11-25T00:00:00+00:00 [queued]>
[2023-11-26 15:39:40,205] {taskinstance.py:1356} INFO - 
--------------------------------------------------------------------------------
[2023-11-26 15:39:40,205] {taskinstance.py:1357} INFO - Starting attempt 1 of 6
[2023-11-26 15:39:40,205] {taskinstance.py:1358} INFO - 
--------------------------------------------------------------------------------
[2023-11-26 15:39:40,285] {taskinstance.py:1377} INFO - Executing <Task(PythonOperator): create_dim_province> on 2023-11-25 00:00:00+00:00
[2023-11-26 15:39:40,290] {standard_task_runner.py:52} INFO - Started process 2581 to run task
[2023-11-26 15:39:40,303] {standard_task_runner.py:79} INFO - Running: ['***', 'tasks', 'run', 'data_covid_etl', 'create_dim_province', 'scheduled__2023-11-25T00:00:00+00:00', '--job-id', '62', '--raw', '--subdir', 'DAGS_FOLDER/get_data.py', '--cfg-path', '/tmp/tmpceo2nfvy', '--error-file', '/tmp/tmpu21qt6ps']
[2023-11-26 15:39:40,304] {standard_task_runner.py:80} INFO - Job 62: Subtask create_dim_province
[2023-11-26 15:39:40,487] {task_command.py:369} INFO - Running <TaskInstance: data_covid_etl.create_dim_province scheduled__2023-11-25T00:00:00+00:00 [running]> on host f384f2afcc4f
[2023-11-26 15:39:40,696] {taskinstance.py:1571} INFO - Exporting the following env vars:
AIRFLOW_CTX_DAG_OWNER=oce
AIRFLOW_CTX_DAG_ID=data_covid_etl
AIRFLOW_CTX_TASK_ID=create_dim_province
AIRFLOW_CTX_EXECUTION_DATE=2023-11-25T00:00:00+00:00
AIRFLOW_CTX_TRY_NUMBER=1
AIRFLOW_CTX_DAG_RUN_ID=scheduled__2023-11-25T00:00:00+00:00
[2023-11-26 15:39:40,696] {python.py:173} INFO - Done. Returned value was: None
[2023-11-26 15:39:40,731] {taskinstance.py:1400} INFO - Marking task as SUCCESS. dag_id=data_covid_etl, task_id=create_dim_province, execution_date=20231125T000000, start_date=20231126T153940, end_date=20231126T153940
[2023-11-26 15:39:40,796] {local_task_job.py:156} INFO - Task exited with return code 0
[2023-11-26 15:39:40,864] {local_task_job.py:273} INFO - 0 downstream tasks scheduled from follow-on schedule check
[2023-11-26 17:57:15,531] {taskinstance.py:1159} INFO - Dependencies all met for <TaskInstance: data_covid_etl.create_dim_province scheduled__2023-11-25T00:00:00+00:00 [queued]>
[2023-11-26 17:57:15,540] {taskinstance.py:1159} INFO - Dependencies all met for <TaskInstance: data_covid_etl.create_dim_province scheduled__2023-11-25T00:00:00+00:00 [queued]>
[2023-11-26 17:57:15,540] {taskinstance.py:1356} INFO - 
--------------------------------------------------------------------------------
[2023-11-26 17:57:15,540] {taskinstance.py:1357} INFO - Starting attempt 1 of 6
[2023-11-26 17:57:15,540] {taskinstance.py:1358} INFO - 
--------------------------------------------------------------------------------
[2023-11-26 17:57:15,554] {taskinstance.py:1377} INFO - Executing <Task(PythonOperator): create_dim_province> on 2023-11-25 00:00:00+00:00
[2023-11-26 17:57:15,558] {standard_task_runner.py:52} INFO - Started process 738 to run task
[2023-11-26 17:57:15,560] {standard_task_runner.py:79} INFO - Running: ['***', 'tasks', 'run', 'data_covid_etl', 'create_dim_province', 'scheduled__2023-11-25T00:00:00+00:00', '--job-id', '132', '--raw', '--subdir', 'DAGS_FOLDER/get_data.py', '--cfg-path', '/tmp/tmp9jbxb3g_', '--error-file', '/tmp/tmpv77r7svg']
[2023-11-26 17:57:15,561] {standard_task_runner.py:80} INFO - Job 132: Subtask create_dim_province
[2023-11-26 17:57:15,611] {task_command.py:369} INFO - Running <TaskInstance: data_covid_etl.create_dim_province scheduled__2023-11-25T00:00:00+00:00 [running]> on host 79a606f4be36
[2023-11-26 17:57:15,682] {taskinstance.py:1571} INFO - Exporting the following env vars:
AIRFLOW_CTX_DAG_OWNER=oce
AIRFLOW_CTX_DAG_ID=data_covid_etl
AIRFLOW_CTX_TASK_ID=create_dim_province
AIRFLOW_CTX_EXECUTION_DATE=2023-11-25T00:00:00+00:00
AIRFLOW_CTX_TRY_NUMBER=1
AIRFLOW_CTX_DAG_RUN_ID=scheduled__2023-11-25T00:00:00+00:00
[2023-11-26 17:57:15,683] {taskinstance.py:1889} ERROR - Task failed with exception
Traceback (most recent call last):
  File "/home/airflow/.local/lib/python3.7/site-packages/airflow/operators/python.py", line 171, in execute
    return_value = self.execute_callable()
  File "/home/airflow/.local/lib/python3.7/site-packages/airflow/operators/python.py", line 189, in execute_callable
    return self.python_callable(*self.op_args, **self.op_kwargs)
  File "/opt/airflow/dags/get_data.py", line 38, in create_dim_province
    engine = create_engine(staging_db_constring)
NameError: name 'create_engine' is not defined
[2023-11-26 17:57:15,690] {taskinstance.py:1400} INFO - Marking task as UP_FOR_RETRY. dag_id=data_covid_etl, task_id=create_dim_province, execution_date=20231125T000000, start_date=20231126T175715, end_date=20231126T175715
[2023-11-26 17:57:15,701] {standard_task_runner.py:97} ERROR - Failed to execute job 132 for task create_dim_province (name 'create_engine' is not defined; 738)
[2023-11-26 17:57:15,732] {local_task_job.py:156} INFO - Task exited with return code 1
[2023-11-26 17:57:15,788] {local_task_job.py:273} INFO - 0 downstream tasks scheduled from follow-on schedule check
[2023-11-26 18:00:56,129] {taskinstance.py:1159} INFO - Dependencies all met for <TaskInstance: data_covid_etl.create_dim_province scheduled__2023-11-25T00:00:00+00:00 [queued]>
[2023-11-26 18:00:56,139] {taskinstance.py:1159} INFO - Dependencies all met for <TaskInstance: data_covid_etl.create_dim_province scheduled__2023-11-25T00:00:00+00:00 [queued]>
[2023-11-26 18:00:56,139] {taskinstance.py:1356} INFO - 
--------------------------------------------------------------------------------
[2023-11-26 18:00:56,140] {taskinstance.py:1357} INFO - Starting attempt 1 of 6
[2023-11-26 18:00:56,140] {taskinstance.py:1358} INFO - 
--------------------------------------------------------------------------------
[2023-11-26 18:00:56,154] {taskinstance.py:1377} INFO - Executing <Task(PythonOperator): create_dim_province> on 2023-11-25 00:00:00+00:00
[2023-11-26 18:00:56,159] {standard_task_runner.py:52} INFO - Started process 931 to run task
[2023-11-26 18:00:56,162] {standard_task_runner.py:79} INFO - Running: ['***', 'tasks', 'run', 'data_covid_etl', 'create_dim_province', 'scheduled__2023-11-25T00:00:00+00:00', '--job-id', '162', '--raw', '--subdir', 'DAGS_FOLDER/get_data.py', '--cfg-path', '/tmp/tmp6u80d6w7', '--error-file', '/tmp/tmplx822laa']
[2023-11-26 18:00:56,162] {standard_task_runner.py:80} INFO - Job 162: Subtask create_dim_province
[2023-11-26 18:00:56,218] {task_command.py:369} INFO - Running <TaskInstance: data_covid_etl.create_dim_province scheduled__2023-11-25T00:00:00+00:00 [running]> on host 79a606f4be36
[2023-11-26 18:00:56,298] {taskinstance.py:1571} INFO - Exporting the following env vars:
AIRFLOW_CTX_DAG_OWNER=oce
AIRFLOW_CTX_DAG_ID=data_covid_etl
AIRFLOW_CTX_TASK_ID=create_dim_province
AIRFLOW_CTX_EXECUTION_DATE=2023-11-25T00:00:00+00:00
AIRFLOW_CTX_TRY_NUMBER=1
AIRFLOW_CTX_DAG_RUN_ID=scheduled__2023-11-25T00:00:00+00:00
[2023-11-26 18:00:56,324] {python.py:173} INFO - Done. Returned value was:     province_id province_name
0            32    Jawa Barat
1            32    Jawa Barat
2            32    Jawa Barat
3            32    Jawa Barat
4            32    Jawa Barat
..          ...           ...
140          32    Jawa Barat
141          32    Jawa Barat
142          32    Jawa Barat
143          32    Jawa Barat
144          32    Jawa Barat

[145 rows x 2 columns]
[2023-11-26 18:00:56,336] {xcom.py:585} ERROR - Could not serialize the XCom value into JSON. If you are using pickle instead of JSON for XCom, then you need to enable pickle support for XCom in your *** config.
[2023-11-26 18:00:56,337] {taskinstance.py:1889} ERROR - Task failed with exception
Traceback (most recent call last):
  File "/home/airflow/.local/lib/python3.7/site-packages/airflow/utils/session.py", line 68, in wrapper
    return func(*args, **kwargs)
  File "/home/airflow/.local/lib/python3.7/site-packages/airflow/models/taskinstance.py", line 2380, in xcom_push
    session=session,
  File "/home/airflow/.local/lib/python3.7/site-packages/airflow/utils/session.py", line 68, in wrapper
    return func(*args, **kwargs)
  File "/home/airflow/.local/lib/python3.7/site-packages/airflow/models/xcom.py", line 197, in set
    map_index=map_index,
  File "/home/airflow/.local/lib/python3.7/site-packages/airflow/models/xcom.py", line 582, in serialize_value
    return json.dumps(value).encode('UTF-8')
  File "/usr/local/lib/python3.7/json/__init__.py", line 231, in dumps
    return _default_encoder.encode(obj)
  File "/usr/local/lib/python3.7/json/encoder.py", line 199, in encode
    chunks = self.iterencode(o, _one_shot=True)
  File "/usr/local/lib/python3.7/json/encoder.py", line 257, in iterencode
    return _iterencode(o, 0)
  File "/usr/local/lib/python3.7/json/encoder.py", line 179, in default
    raise TypeError(f'Object of type {o.__class__.__name__} '
TypeError: Object of type DataFrame is not JSON serializable
[2023-11-26 18:00:56,345] {taskinstance.py:1400} INFO - Marking task as UP_FOR_RETRY. dag_id=data_covid_etl, task_id=create_dim_province, execution_date=20231125T000000, start_date=20231126T180056, end_date=20231126T180056
[2023-11-26 18:00:56,358] {standard_task_runner.py:97} ERROR - Failed to execute job 162 for task create_dim_province (Object of type DataFrame is not JSON serializable; 931)
[2023-11-26 18:00:56,374] {local_task_job.py:156} INFO - Task exited with return code 1
[2023-11-26 18:00:56,414] {local_task_job.py:273} INFO - 0 downstream tasks scheduled from follow-on schedule check
