[2023-11-26 14:26:17,511] {taskinstance.py:1159} INFO - Dependencies all met for <TaskInstance: data_covid_etl.ingest_staging_db scheduled__2023-11-24T00:00:00+00:00 [queued]>
[2023-11-26 14:26:17,537] {taskinstance.py:1159} INFO - Dependencies all met for <TaskInstance: data_covid_etl.ingest_staging_db scheduled__2023-11-24T00:00:00+00:00 [queued]>
[2023-11-26 14:26:17,537] {taskinstance.py:1356} INFO - 
--------------------------------------------------------------------------------
[2023-11-26 14:26:17,537] {taskinstance.py:1357} INFO - Starting attempt 1 of 6
[2023-11-26 14:26:17,537] {taskinstance.py:1358} INFO - 
--------------------------------------------------------------------------------
[2023-11-26 14:26:17,570] {taskinstance.py:1377} INFO - Executing <Task(PythonOperator): ingest_staging_db> on 2023-11-24 00:00:00+00:00
[2023-11-26 14:26:17,575] {standard_task_runner.py:52} INFO - Started process 678 to run task
[2023-11-26 14:26:17,582] {standard_task_runner.py:79} INFO - Running: ['***', 'tasks', 'run', 'data_covid_etl', 'ingest_staging_db', 'scheduled__2023-11-24T00:00:00+00:00', '--job-id', '16', '--raw', '--subdir', 'DAGS_FOLDER/get_data.py', '--cfg-path', '/tmp/tmpeo2e0c7z', '--error-file', '/tmp/tmp22jifpe8']
[2023-11-26 14:26:17,584] {standard_task_runner.py:80} INFO - Job 16: Subtask ingest_staging_db
[2023-11-26 14:26:17,686] {task_command.py:369} INFO - Running <TaskInstance: data_covid_etl.ingest_staging_db scheduled__2023-11-24T00:00:00+00:00 [running]> on host f384f2afcc4f
[2023-11-26 14:26:17,796] {taskinstance.py:1571} INFO - Exporting the following env vars:
AIRFLOW_CTX_DAG_OWNER=oce
AIRFLOW_CTX_DAG_ID=data_covid_etl
AIRFLOW_CTX_TASK_ID=ingest_staging_db
AIRFLOW_CTX_EXECUTION_DATE=2023-11-24T00:00:00+00:00
AIRFLOW_CTX_TRY_NUMBER=1
AIRFLOW_CTX_DAG_RUN_ID=scheduled__2023-11-24T00:00:00+00:00
[2023-11-26 14:26:18,870] {python.py:173} INFO - Done. Returned value was: None
[2023-11-26 14:26:18,884] {taskinstance.py:1400} INFO - Marking task as SUCCESS. dag_id=data_covid_etl, task_id=ingest_staging_db, execution_date=20231124T000000, start_date=20231126T142617, end_date=20231126T142618
[2023-11-26 14:26:18,921] {local_task_job.py:156} INFO - Task exited with return code 0
[2023-11-26 14:26:18,958] {local_task_job.py:273} INFO - 0 downstream tasks scheduled from follow-on schedule check
[2023-11-26 15:39:39,650] {taskinstance.py:1159} INFO - Dependencies all met for <TaskInstance: data_covid_etl.ingest_staging_db scheduled__2023-11-24T00:00:00+00:00 [queued]>
[2023-11-26 15:39:39,686] {taskinstance.py:1159} INFO - Dependencies all met for <TaskInstance: data_covid_etl.ingest_staging_db scheduled__2023-11-24T00:00:00+00:00 [queued]>
[2023-11-26 15:39:39,686] {taskinstance.py:1356} INFO - 
--------------------------------------------------------------------------------
[2023-11-26 15:39:39,687] {taskinstance.py:1357} INFO - Starting attempt 1 of 6
[2023-11-26 15:39:39,687] {taskinstance.py:1358} INFO - 
--------------------------------------------------------------------------------
[2023-11-26 15:39:39,742] {taskinstance.py:1377} INFO - Executing <Task(PythonOperator): ingest_staging_db> on 2023-11-24 00:00:00+00:00
[2023-11-26 15:39:39,747] {standard_task_runner.py:52} INFO - Started process 2575 to run task
[2023-11-26 15:39:39,769] {standard_task_runner.py:79} INFO - Running: ['***', 'tasks', 'run', 'data_covid_etl', 'ingest_staging_db', 'scheduled__2023-11-24T00:00:00+00:00', '--job-id', '59', '--raw', '--subdir', 'DAGS_FOLDER/get_data.py', '--cfg-path', '/tmp/tmp6717nltw', '--error-file', '/tmp/tmpyjtha4tk']
[2023-11-26 15:39:39,769] {standard_task_runner.py:80} INFO - Job 59: Subtask ingest_staging_db
[2023-11-26 15:39:39,888] {task_command.py:369} INFO - Running <TaskInstance: data_covid_etl.ingest_staging_db scheduled__2023-11-24T00:00:00+00:00 [running]> on host f384f2afcc4f
[2023-11-26 15:39:40,087] {taskinstance.py:1571} INFO - Exporting the following env vars:
AIRFLOW_CTX_DAG_OWNER=oce
AIRFLOW_CTX_DAG_ID=data_covid_etl
AIRFLOW_CTX_TASK_ID=ingest_staging_db
AIRFLOW_CTX_EXECUTION_DATE=2023-11-24T00:00:00+00:00
AIRFLOW_CTX_TRY_NUMBER=1
AIRFLOW_CTX_DAG_RUN_ID=scheduled__2023-11-24T00:00:00+00:00
[2023-11-26 15:39:56,917] {python.py:173} INFO - Done. Returned value was: None
[2023-11-26 15:39:56,928] {taskinstance.py:1400} INFO - Marking task as SUCCESS. dag_id=data_covid_etl, task_id=ingest_staging_db, execution_date=20231124T000000, start_date=20231126T153939, end_date=20231126T153956
[2023-11-26 15:39:56,953] {local_task_job.py:156} INFO - Task exited with return code 0
[2023-11-26 15:39:56,979] {local_task_job.py:273} INFO - 0 downstream tasks scheduled from follow-on schedule check
[2023-11-26 17:57:13,936] {taskinstance.py:1159} INFO - Dependencies all met for <TaskInstance: data_covid_etl.ingest_staging_db scheduled__2023-11-24T00:00:00+00:00 [queued]>
[2023-11-26 17:57:13,970] {taskinstance.py:1159} INFO - Dependencies all met for <TaskInstance: data_covid_etl.ingest_staging_db scheduled__2023-11-24T00:00:00+00:00 [queued]>
[2023-11-26 17:57:13,970] {taskinstance.py:1356} INFO - 
--------------------------------------------------------------------------------
[2023-11-26 17:57:13,970] {taskinstance.py:1357} INFO - Starting attempt 1 of 6
[2023-11-26 17:57:13,970] {taskinstance.py:1358} INFO - 
--------------------------------------------------------------------------------
[2023-11-26 17:57:14,014] {taskinstance.py:1377} INFO - Executing <Task(PythonOperator): ingest_staging_db> on 2023-11-24 00:00:00+00:00
[2023-11-26 17:57:14,029] {standard_task_runner.py:52} INFO - Started process 730 to run task
[2023-11-26 17:57:14,044] {standard_task_runner.py:79} INFO - Running: ['***', 'tasks', 'run', 'data_covid_etl', 'ingest_staging_db', 'scheduled__2023-11-24T00:00:00+00:00', '--job-id', '121', '--raw', '--subdir', 'DAGS_FOLDER/get_data.py', '--cfg-path', '/tmp/tmpnnq8iwp6', '--error-file', '/tmp/tmpj2oq3az0']
[2023-11-26 17:57:14,044] {standard_task_runner.py:80} INFO - Job 121: Subtask ingest_staging_db
[2023-11-26 17:57:14,199] {task_command.py:369} INFO - Running <TaskInstance: data_covid_etl.ingest_staging_db scheduled__2023-11-24T00:00:00+00:00 [running]> on host 79a606f4be36
[2023-11-26 17:57:14,341] {taskinstance.py:1571} INFO - Exporting the following env vars:
AIRFLOW_CTX_DAG_OWNER=oce
AIRFLOW_CTX_DAG_ID=data_covid_etl
AIRFLOW_CTX_TASK_ID=ingest_staging_db
AIRFLOW_CTX_EXECUTION_DATE=2023-11-24T00:00:00+00:00
AIRFLOW_CTX_TRY_NUMBER=1
AIRFLOW_CTX_DAG_RUN_ID=scheduled__2023-11-24T00:00:00+00:00
[2023-11-26 17:57:14,717] {taskinstance.py:1889} ERROR - Task failed with exception
Traceback (most recent call last):
  File "/home/airflow/.local/lib/python3.7/site-packages/sqlalchemy/engine/base.py", line 1706, in _execute_context
    cursor, statement, parameters, context
  File "/home/airflow/.local/lib/python3.7/site-packages/sqlalchemy/engine/default.py", line 716, in do_execute
    cursor.execute(statement, parameters)
  File "/home/airflow/.local/lib/python3.7/site-packages/MySQLdb/cursors.py", line 206, in execute
    res = self._query(query)
  File "/home/airflow/.local/lib/python3.7/site-packages/MySQLdb/cursors.py", line 319, in _query
    db.query(q)
  File "/home/airflow/.local/lib/python3.7/site-packages/MySQLdb/connections.py", line 254, in query
    _mysql.connection.query(self, query)
MySQLdb._exceptions.OperationalError: (1050, "Table 'covid_jabar' already exists")

The above exception was the direct cause of the following exception:

Traceback (most recent call last):
  File "/home/airflow/.local/lib/python3.7/site-packages/airflow/operators/python.py", line 171, in execute
    return_value = self.execute_callable()
  File "/home/airflow/.local/lib/python3.7/site-packages/airflow/operators/python.py", line 189, in execute_callable
    return self.python_callable(*self.op_args, **self.op_kwargs)
  File "/opt/airflow/dags/get_data.py", line 34, in ingest_data_staging
    df.to_sql("covid_jabar", staging_db_constring, if_exists="replace", index=False)
  File "/home/airflow/.local/lib/python3.7/site-packages/pandas/core/generic.py", line 2882, in to_sql
    method=method,
  File "/home/airflow/.local/lib/python3.7/site-packages/pandas/io/sql.py", line 728, in to_sql
    **engine_kwargs,
  File "/home/airflow/.local/lib/python3.7/site-packages/pandas/io/sql.py", line 1758, in to_sql
    dtype=dtype,
  File "/home/airflow/.local/lib/python3.7/site-packages/pandas/io/sql.py", line 1650, in prep_table
    table.create()
  File "/home/airflow/.local/lib/python3.7/site-packages/pandas/io/sql.py", line 867, in create
    self._execute_create()
  File "/home/airflow/.local/lib/python3.7/site-packages/pandas/io/sql.py", line 853, in _execute_create
    self.table.create()
  File "/home/airflow/.local/lib/python3.7/site-packages/sqlalchemy/sql/schema.py", line 943, in create
    bind._run_ddl_visitor(ddl.SchemaGenerator, self, checkfirst=checkfirst)
  File "/home/airflow/.local/lib/python3.7/site-packages/sqlalchemy/engine/base.py", line 3008, in _run_ddl_visitor
    conn._run_ddl_visitor(visitorcallable, element, **kwargs)
  File "/home/airflow/.local/lib/python3.7/site-packages/sqlalchemy/engine/base.py", line 2016, in _run_ddl_visitor
    visitorcallable(self.dialect, self, **kwargs).traverse_single(element)
  File "/home/airflow/.local/lib/python3.7/site-packages/sqlalchemy/sql/visitors.py", line 483, in traverse_single
    return meth(obj, **kw)
  File "/home/airflow/.local/lib/python3.7/site-packages/sqlalchemy/sql/ddl.py", line 895, in visit_table
    include_foreign_key_constraints,  # noqa
  File "/home/airflow/.local/lib/python3.7/site-packages/sqlalchemy/engine/base.py", line 1200, in execute
    return meth(self, multiparams, params, _EMPTY_EXECUTION_OPTS)
  File "/home/airflow/.local/lib/python3.7/site-packages/sqlalchemy/sql/ddl.py", line 78, in _execute_on_connection
    self, multiparams, params, execution_options
  File "/home/airflow/.local/lib/python3.7/site-packages/sqlalchemy/engine/base.py", line 1296, in _execute_ddl
    compiled,
  File "/home/airflow/.local/lib/python3.7/site-packages/sqlalchemy/engine/base.py", line 1749, in _execute_context
    e, statement, parameters, cursor, context
  File "/home/airflow/.local/lib/python3.7/site-packages/sqlalchemy/engine/base.py", line 1930, in _handle_dbapi_exception
    sqlalchemy_exception, with_traceback=exc_info[2], from_=e
  File "/home/airflow/.local/lib/python3.7/site-packages/sqlalchemy/util/compat.py", line 211, in raise_
    raise exception
  File "/home/airflow/.local/lib/python3.7/site-packages/sqlalchemy/engine/base.py", line 1706, in _execute_context
    cursor, statement, parameters, context
  File "/home/airflow/.local/lib/python3.7/site-packages/sqlalchemy/engine/default.py", line 716, in do_execute
    cursor.execute(statement, parameters)
  File "/home/airflow/.local/lib/python3.7/site-packages/MySQLdb/cursors.py", line 206, in execute
    res = self._query(query)
  File "/home/airflow/.local/lib/python3.7/site-packages/MySQLdb/cursors.py", line 319, in _query
    db.query(q)
  File "/home/airflow/.local/lib/python3.7/site-packages/MySQLdb/connections.py", line 254, in query
    _mysql.connection.query(self, query)
sqlalchemy.exc.OperationalError: (MySQLdb._exceptions.OperationalError) (1050, "Table 'covid_jabar' already exists")
[SQL: 
CREATE TABLE covid_jabar (
	`CLOSECONTACT` BIGINT, 
	`CONFIRMATION` BIGINT, 
	`PROBABLE` BIGINT, 
	`SUSPECT` BIGINT, 
	closecontact_dikarantina BIGINT, 
	closecontact_discarded BIGINT, 
	closecontact_meninggal BIGINT, 
	confirmation_meninggal BIGINT, 
	confirmation_sembuh BIGINT, 
	kode_kab TEXT, 
	kode_prov TEXT, 
	nama_kab TEXT, 
	nama_prov TEXT, 
	probable_diisolasi BIGINT, 
	probable_discarded BIGINT, 
	probable_meninggal BIGINT, 
	suspect_diisolasi BIGINT, 
	suspect_discarded BIGINT, 
	suspect_meninggal BIGINT, 
	tanggal TEXT
)

]
(Background on this error at: http://sqlalche.me/e/14/e3q8)
[2023-11-26 17:57:14,730] {taskinstance.py:1400} INFO - Marking task as UP_FOR_RETRY. dag_id=data_covid_etl, task_id=ingest_staging_db, execution_date=20231124T000000, start_date=20231126T175713, end_date=20231126T175714
[2023-11-26 17:57:14,751] {standard_task_runner.py:97} ERROR - Failed to execute job 121 for task ingest_staging_db ((MySQLdb._exceptions.OperationalError) (1050, "Table 'covid_jabar' already exists")
[SQL: 
CREATE TABLE covid_jabar (
	`CLOSECONTACT` BIGINT, 
	`CONFIRMATION` BIGINT, 
	`PROBABLE` BIGINT, 
	`SUSPECT` BIGINT, 
	closecontact_dikarantina BIGINT, 
	closecontact_discarded BIGINT, 
	closecontact_meninggal BIGINT, 
	confirmation_meninggal BIGINT, 
	confirmation_sembuh BIGINT, 
	kode_kab TEXT, 
	kode_prov TEXT, 
	nama_kab TEXT, 
	nama_prov TEXT, 
	probable_diisolasi BIGINT, 
	probable_discarded BIGINT, 
	probable_meninggal BIGINT, 
	suspect_diisolasi BIGINT, 
	suspect_discarded BIGINT, 
	suspect_meninggal BIGINT, 
	tanggal TEXT
)

]
(Background on this error at: http://sqlalche.me/e/14/e3q8); 730)
[2023-11-26 17:57:14,791] {local_task_job.py:156} INFO - Task exited with return code 1
[2023-11-26 17:57:14,841] {local_task_job.py:273} INFO - 0 downstream tasks scheduled from follow-on schedule check
[2023-11-26 18:00:54,580] {taskinstance.py:1159} INFO - Dependencies all met for <TaskInstance: data_covid_etl.ingest_staging_db scheduled__2023-11-24T00:00:00+00:00 [queued]>
[2023-11-26 18:00:54,593] {taskinstance.py:1159} INFO - Dependencies all met for <TaskInstance: data_covid_etl.ingest_staging_db scheduled__2023-11-24T00:00:00+00:00 [queued]>
[2023-11-26 18:00:54,593] {taskinstance.py:1356} INFO - 
--------------------------------------------------------------------------------
[2023-11-26 18:00:54,593] {taskinstance.py:1357} INFO - Starting attempt 1 of 6
[2023-11-26 18:00:54,593] {taskinstance.py:1358} INFO - 
--------------------------------------------------------------------------------
[2023-11-26 18:00:54,611] {taskinstance.py:1377} INFO - Executing <Task(PythonOperator): ingest_staging_db> on 2023-11-24 00:00:00+00:00
[2023-11-26 18:00:54,616] {standard_task_runner.py:52} INFO - Started process 919 to run task
[2023-11-26 18:00:54,622] {standard_task_runner.py:79} INFO - Running: ['***', 'tasks', 'run', 'data_covid_etl', 'ingest_staging_db', 'scheduled__2023-11-24T00:00:00+00:00', '--job-id', '156', '--raw', '--subdir', 'DAGS_FOLDER/get_data.py', '--cfg-path', '/tmp/tmphso_1xog', '--error-file', '/tmp/tmpxgb2yc8q']
[2023-11-26 18:00:54,622] {standard_task_runner.py:80} INFO - Job 156: Subtask ingest_staging_db
[2023-11-26 18:00:54,697] {task_command.py:369} INFO - Running <TaskInstance: data_covid_etl.ingest_staging_db scheduled__2023-11-24T00:00:00+00:00 [running]> on host 79a606f4be36
[2023-11-26 18:00:54,784] {taskinstance.py:1571} INFO - Exporting the following env vars:
AIRFLOW_CTX_DAG_OWNER=oce
AIRFLOW_CTX_DAG_ID=data_covid_etl
AIRFLOW_CTX_TASK_ID=ingest_staging_db
AIRFLOW_CTX_EXECUTION_DATE=2023-11-24T00:00:00+00:00
AIRFLOW_CTX_TRY_NUMBER=1
AIRFLOW_CTX_DAG_RUN_ID=scheduled__2023-11-24T00:00:00+00:00
[2023-11-26 18:00:55,390] {python.py:173} INFO - Done. Returned value was: None
[2023-11-26 18:00:55,414] {taskinstance.py:1400} INFO - Marking task as SUCCESS. dag_id=data_covid_etl, task_id=ingest_staging_db, execution_date=20231124T000000, start_date=20231126T180054, end_date=20231126T180055
[2023-11-26 18:00:55,473] {local_task_job.py:156} INFO - Task exited with return code 0
[2023-11-26 18:00:55,605] {local_task_job.py:273} INFO - 0 downstream tasks scheduled from follow-on schedule check
[2023-11-26 18:02:42,096] {taskinstance.py:1159} INFO - Dependencies all met for <TaskInstance: data_covid_etl.ingest_staging_db scheduled__2023-11-24T00:00:00+00:00 [queued]>
[2023-11-26 18:02:42,113] {taskinstance.py:1159} INFO - Dependencies all met for <TaskInstance: data_covid_etl.ingest_staging_db scheduled__2023-11-24T00:00:00+00:00 [queued]>
[2023-11-26 18:02:42,113] {taskinstance.py:1356} INFO - 
--------------------------------------------------------------------------------
[2023-11-26 18:02:42,113] {taskinstance.py:1357} INFO - Starting attempt 1 of 4
[2023-11-26 18:02:42,113] {taskinstance.py:1358} INFO - 
--------------------------------------------------------------------------------
[2023-11-26 18:02:42,137] {taskinstance.py:1377} INFO - Executing <Task(PythonOperator): ingest_staging_db> on 2023-11-24 00:00:00+00:00
[2023-11-26 18:02:42,142] {standard_task_runner.py:52} INFO - Started process 1030 to run task
[2023-11-26 18:02:42,146] {standard_task_runner.py:79} INFO - Running: ['***', 'tasks', 'run', 'data_covid_etl', 'ingest_staging_db', 'scheduled__2023-11-24T00:00:00+00:00', '--job-id', '176', '--raw', '--subdir', 'DAGS_FOLDER/get_data.py', '--cfg-path', '/tmp/tmpnoe6qyi5', '--error-file', '/tmp/tmptf4r1r51']
[2023-11-26 18:02:42,147] {standard_task_runner.py:80} INFO - Job 176: Subtask ingest_staging_db
[2023-11-26 18:02:42,207] {task_command.py:369} INFO - Running <TaskInstance: data_covid_etl.ingest_staging_db scheduled__2023-11-24T00:00:00+00:00 [running]> on host 79a606f4be36
[2023-11-26 18:02:42,278] {taskinstance.py:1571} INFO - Exporting the following env vars:
AIRFLOW_CTX_DAG_OWNER=oce
AIRFLOW_CTX_DAG_ID=data_covid_etl
AIRFLOW_CTX_TASK_ID=ingest_staging_db
AIRFLOW_CTX_EXECUTION_DATE=2023-11-24T00:00:00+00:00
AIRFLOW_CTX_TRY_NUMBER=1
AIRFLOW_CTX_DAG_RUN_ID=scheduled__2023-11-24T00:00:00+00:00
[2023-11-26 18:02:42,900] {python.py:173} INFO - Done. Returned value was: None
[2023-11-26 18:02:42,920] {taskinstance.py:1400} INFO - Marking task as SUCCESS. dag_id=data_covid_etl, task_id=ingest_staging_db, execution_date=20231124T000000, start_date=20231126T180242, end_date=20231126T180242
[2023-11-26 18:02:42,963] {local_task_job.py:156} INFO - Task exited with return code 0
[2023-11-26 18:02:43,006] {local_task_job.py:273} INFO - 1 downstream tasks scheduled from follow-on schedule check
[2023-11-26 18:05:34,914] {taskinstance.py:1159} INFO - Dependencies all met for <TaskInstance: data_covid_etl.ingest_staging_db scheduled__2023-11-24T00:00:00+00:00 [queued]>
[2023-11-26 18:05:34,924] {taskinstance.py:1159} INFO - Dependencies all met for <TaskInstance: data_covid_etl.ingest_staging_db scheduled__2023-11-24T00:00:00+00:00 [queued]>
[2023-11-26 18:05:34,924] {taskinstance.py:1356} INFO - 
--------------------------------------------------------------------------------
[2023-11-26 18:05:34,924] {taskinstance.py:1357} INFO - Starting attempt 1 of 3
[2023-11-26 18:05:34,924] {taskinstance.py:1358} INFO - 
--------------------------------------------------------------------------------
[2023-11-26 18:05:34,940] {taskinstance.py:1377} INFO - Executing <Task(PythonOperator): ingest_staging_db> on 2023-11-24 00:00:00+00:00
[2023-11-26 18:05:34,945] {standard_task_runner.py:52} INFO - Started process 1150 to run task
[2023-11-26 18:05:34,948] {standard_task_runner.py:79} INFO - Running: ['***', 'tasks', 'run', 'data_covid_etl', 'ingest_staging_db', 'scheduled__2023-11-24T00:00:00+00:00', '--job-id', '191', '--raw', '--subdir', 'DAGS_FOLDER/get_data.py', '--cfg-path', '/tmp/tmp9eq6bgef', '--error-file', '/tmp/tmpikr540cq']
[2023-11-26 18:05:34,949] {standard_task_runner.py:80} INFO - Job 191: Subtask ingest_staging_db
[2023-11-26 18:05:35,009] {task_command.py:369} INFO - Running <TaskInstance: data_covid_etl.ingest_staging_db scheduled__2023-11-24T00:00:00+00:00 [running]> on host 79a606f4be36
[2023-11-26 18:05:35,078] {taskinstance.py:1571} INFO - Exporting the following env vars:
AIRFLOW_CTX_DAG_OWNER=oce
AIRFLOW_CTX_DAG_ID=data_covid_etl
AIRFLOW_CTX_TASK_ID=ingest_staging_db
AIRFLOW_CTX_EXECUTION_DATE=2023-11-24T00:00:00+00:00
AIRFLOW_CTX_TRY_NUMBER=1
AIRFLOW_CTX_DAG_RUN_ID=scheduled__2023-11-24T00:00:00+00:00
[2023-11-26 18:05:35,643] {python.py:173} INFO - Done. Returned value was: None
[2023-11-26 18:05:35,704] {taskinstance.py:1400} INFO - Marking task as SUCCESS. dag_id=data_covid_etl, task_id=ingest_staging_db, execution_date=20231124T000000, start_date=20231126T180534, end_date=20231126T180535
[2023-11-26 18:05:35,761] {local_task_job.py:156} INFO - Task exited with return code 0
[2023-11-26 18:05:35,802] {local_task_job.py:273} INFO - 1 downstream tasks scheduled from follow-on schedule check
[2023-11-26 18:08:47,263] {taskinstance.py:1159} INFO - Dependencies all met for <TaskInstance: data_covid_etl.ingest_staging_db scheduled__2023-11-24T00:00:00+00:00 [queued]>
[2023-11-26 18:08:47,275] {taskinstance.py:1159} INFO - Dependencies all met for <TaskInstance: data_covid_etl.ingest_staging_db scheduled__2023-11-24T00:00:00+00:00 [queued]>
[2023-11-26 18:08:47,275] {taskinstance.py:1356} INFO - 
--------------------------------------------------------------------------------
[2023-11-26 18:08:47,276] {taskinstance.py:1357} INFO - Starting attempt 1 of 3
[2023-11-26 18:08:47,276] {taskinstance.py:1358} INFO - 
--------------------------------------------------------------------------------
[2023-11-26 18:08:47,304] {taskinstance.py:1377} INFO - Executing <Task(PythonOperator): ingest_staging_db> on 2023-11-24 00:00:00+00:00
[2023-11-26 18:08:47,313] {standard_task_runner.py:52} INFO - Started process 1333 to run task
[2023-11-26 18:08:47,319] {standard_task_runner.py:79} INFO - Running: ['***', 'tasks', 'run', 'data_covid_etl', 'ingest_staging_db', 'scheduled__2023-11-24T00:00:00+00:00', '--job-id', '223', '--raw', '--subdir', 'DAGS_FOLDER/get_data.py', '--cfg-path', '/tmp/tmpkxnny1ok', '--error-file', '/tmp/tmpzvur1_lg']
[2023-11-26 18:08:47,328] {standard_task_runner.py:80} INFO - Job 223: Subtask ingest_staging_db
[2023-11-26 18:08:47,405] {task_command.py:369} INFO - Running <TaskInstance: data_covid_etl.ingest_staging_db scheduled__2023-11-24T00:00:00+00:00 [running]> on host 79a606f4be36
[2023-11-26 18:08:47,475] {taskinstance.py:1571} INFO - Exporting the following env vars:
AIRFLOW_CTX_DAG_OWNER=oce
AIRFLOW_CTX_DAG_ID=data_covid_etl
AIRFLOW_CTX_TASK_ID=ingest_staging_db
AIRFLOW_CTX_EXECUTION_DATE=2023-11-24T00:00:00+00:00
AIRFLOW_CTX_TRY_NUMBER=1
AIRFLOW_CTX_DAG_RUN_ID=scheduled__2023-11-24T00:00:00+00:00
[2023-11-26 18:08:47,919] {python.py:173} INFO - Done. Returned value was: None
[2023-11-26 18:08:47,935] {taskinstance.py:1400} INFO - Marking task as SUCCESS. dag_id=data_covid_etl, task_id=ingest_staging_db, execution_date=20231124T000000, start_date=20231126T180847, end_date=20231126T180847
[2023-11-26 18:08:47,970] {local_task_job.py:156} INFO - Task exited with return code 0
[2023-11-26 18:08:48,015] {local_task_job.py:273} INFO - 1 downstream tasks scheduled from follow-on schedule check
[2023-11-26 18:15:24,261] {taskinstance.py:1159} INFO - Dependencies all met for <TaskInstance: data_covid_etl.ingest_staging_db scheduled__2023-11-24T00:00:00+00:00 [queued]>
[2023-11-26 18:15:24,287] {taskinstance.py:1159} INFO - Dependencies all met for <TaskInstance: data_covid_etl.ingest_staging_db scheduled__2023-11-24T00:00:00+00:00 [queued]>
[2023-11-26 18:15:24,287] {taskinstance.py:1356} INFO - 
--------------------------------------------------------------------------------
[2023-11-26 18:15:24,288] {taskinstance.py:1357} INFO - Starting attempt 1 of 3
[2023-11-26 18:15:24,288] {taskinstance.py:1358} INFO - 
--------------------------------------------------------------------------------
[2023-11-26 18:15:24,308] {taskinstance.py:1377} INFO - Executing <Task(PythonOperator): ingest_staging_db> on 2023-11-24 00:00:00+00:00
[2023-11-26 18:15:24,313] {standard_task_runner.py:52} INFO - Started process 1630 to run task
[2023-11-26 18:15:24,323] {standard_task_runner.py:79} INFO - Running: ['***', 'tasks', 'run', 'data_covid_etl', 'ingest_staging_db', 'scheduled__2023-11-24T00:00:00+00:00', '--job-id', '261', '--raw', '--subdir', 'DAGS_FOLDER/get_data.py', '--cfg-path', '/tmp/tmpew3m_cy8', '--error-file', '/tmp/tmpl2tsixyo']
[2023-11-26 18:15:24,326] {standard_task_runner.py:80} INFO - Job 261: Subtask ingest_staging_db
[2023-11-26 18:15:24,419] {task_command.py:369} INFO - Running <TaskInstance: data_covid_etl.ingest_staging_db scheduled__2023-11-24T00:00:00+00:00 [running]> on host 79a606f4be36
[2023-11-26 18:15:24,541] {taskinstance.py:1571} INFO - Exporting the following env vars:
AIRFLOW_CTX_DAG_OWNER=oce
AIRFLOW_CTX_DAG_ID=data_covid_etl
AIRFLOW_CTX_TASK_ID=ingest_staging_db
AIRFLOW_CTX_EXECUTION_DATE=2023-11-24T00:00:00+00:00
AIRFLOW_CTX_TRY_NUMBER=1
AIRFLOW_CTX_DAG_RUN_ID=scheduled__2023-11-24T00:00:00+00:00
[2023-11-26 18:15:25,085] {taskinstance.py:1889} ERROR - Task failed with exception
Traceback (most recent call last):
  File "/home/airflow/.local/lib/python3.7/site-packages/sqlalchemy/engine/base.py", line 1706, in _execute_context
    cursor, statement, parameters, context
  File "/home/airflow/.local/lib/python3.7/site-packages/sqlalchemy/engine/default.py", line 716, in do_execute
    cursor.execute(statement, parameters)
  File "/home/airflow/.local/lib/python3.7/site-packages/MySQLdb/cursors.py", line 206, in execute
    res = self._query(query)
  File "/home/airflow/.local/lib/python3.7/site-packages/MySQLdb/cursors.py", line 319, in _query
    db.query(q)
  File "/home/airflow/.local/lib/python3.7/site-packages/MySQLdb/connections.py", line 254, in query
    _mysql.connection.query(self, query)
MySQLdb._exceptions.ProgrammingError: (1146, "Table 'finalproject.covid_jabar' doesn't exist")

The above exception was the direct cause of the following exception:

Traceback (most recent call last):
  File "/home/airflow/.local/lib/python3.7/site-packages/sqlalchemy/dialects/mysql/base.py", line 3373, in _show_create_table
    ).exec_driver_sql(st)
  File "/home/airflow/.local/lib/python3.7/site-packages/sqlalchemy/engine/base.py", line 1580, in exec_driver_sql
    future=True,
  File "/home/airflow/.local/lib/python3.7/site-packages/sqlalchemy/engine/base.py", line 1491, in _exec_driver_sql
    distilled_parameters,
  File "/home/airflow/.local/lib/python3.7/site-packages/sqlalchemy/engine/base.py", line 1749, in _execute_context
    e, statement, parameters, cursor, context
  File "/home/airflow/.local/lib/python3.7/site-packages/sqlalchemy/engine/base.py", line 1930, in _handle_dbapi_exception
    sqlalchemy_exception, with_traceback=exc_info[2], from_=e
  File "/home/airflow/.local/lib/python3.7/site-packages/sqlalchemy/util/compat.py", line 211, in raise_
    raise exception
  File "/home/airflow/.local/lib/python3.7/site-packages/sqlalchemy/engine/base.py", line 1706, in _execute_context
    cursor, statement, parameters, context
  File "/home/airflow/.local/lib/python3.7/site-packages/sqlalchemy/engine/default.py", line 716, in do_execute
    cursor.execute(statement, parameters)
  File "/home/airflow/.local/lib/python3.7/site-packages/MySQLdb/cursors.py", line 206, in execute
    res = self._query(query)
  File "/home/airflow/.local/lib/python3.7/site-packages/MySQLdb/cursors.py", line 319, in _query
    db.query(q)
  File "/home/airflow/.local/lib/python3.7/site-packages/MySQLdb/connections.py", line 254, in query
    _mysql.connection.query(self, query)
sqlalchemy.exc.ProgrammingError: (MySQLdb._exceptions.ProgrammingError) (1146, "Table 'finalproject.covid_jabar' doesn't exist")
[SQL: SHOW CREATE TABLE `covid_jabar`]
(Background on this error at: http://sqlalche.me/e/14/f405)

The above exception was the direct cause of the following exception:

Traceback (most recent call last):
  File "/home/airflow/.local/lib/python3.7/site-packages/airflow/operators/python.py", line 171, in execute
    return_value = self.execute_callable()
  File "/home/airflow/.local/lib/python3.7/site-packages/airflow/operators/python.py", line 189, in execute_callable
    return self.python_callable(*self.op_args, **self.op_kwargs)
  File "/opt/airflow/dags/get_data.py", line 35, in ingest_data_staging
    df.to_sql("covid_jabar", staging_db_constring, if_exists="replace", index=False)
  File "/home/airflow/.local/lib/python3.7/site-packages/pandas/core/generic.py", line 2882, in to_sql
    method=method,
  File "/home/airflow/.local/lib/python3.7/site-packages/pandas/io/sql.py", line 728, in to_sql
    **engine_kwargs,
  File "/home/airflow/.local/lib/python3.7/site-packages/pandas/io/sql.py", line 1758, in to_sql
    dtype=dtype,
  File "/home/airflow/.local/lib/python3.7/site-packages/pandas/io/sql.py", line 1650, in prep_table
    table.create()
  File "/home/airflow/.local/lib/python3.7/site-packages/pandas/io/sql.py", line 860, in create
    self.pd_sql.drop_table(self.name, self.schema)
  File "/home/airflow/.local/lib/python3.7/site-packages/pandas/io/sql.py", line 1809, in drop_table
    self.meta.reflect(only=[table_name], schema=schema)
  File "/home/airflow/.local/lib/python3.7/site-packages/sqlalchemy/sql/schema.py", line 4715, in reflect
    Table(name, self, **reflect_opts)
  File "<string>", line 2, in __new__
  File "/home/airflow/.local/lib/python3.7/site-packages/sqlalchemy/util/deprecations.py", line 298, in warned
    return fn(*args, **kwargs)
  File "/home/airflow/.local/lib/python3.7/site-packages/sqlalchemy/sql/schema.py", line 600, in __new__
    metadata._remove_table(name, schema)
  File "/home/airflow/.local/lib/python3.7/site-packages/sqlalchemy/util/langhelpers.py", line 72, in __exit__
    with_traceback=exc_tb,
  File "/home/airflow/.local/lib/python3.7/site-packages/sqlalchemy/util/compat.py", line 211, in raise_
    raise exception
  File "/home/airflow/.local/lib/python3.7/site-packages/sqlalchemy/sql/schema.py", line 595, in __new__
    table._init(name, metadata, *args, **kw)
  File "/home/airflow/.local/lib/python3.7/site-packages/sqlalchemy/sql/schema.py", line 675, in _init
    resolve_fks=resolve_fks,
  File "/home/airflow/.local/lib/python3.7/site-packages/sqlalchemy/sql/schema.py", line 710, in _autoload
    _extend_on=_extend_on,
  File "/home/airflow/.local/lib/python3.7/site-packages/sqlalchemy/engine/reflection.py", line 758, in reflect_table
    table_name, schema, **table.dialect_kwargs
  File "/home/airflow/.local/lib/python3.7/site-packages/sqlalchemy/engine/reflection.py", line 399, in get_table_options
    conn, table_name, schema, info_cache=self.info_cache, **kw
  File "<string>", line 2, in get_table_options
  File "/home/airflow/.local/lib/python3.7/site-packages/sqlalchemy/engine/reflection.py", line 55, in cache
    ret = fn(self, con, *args, **kw)
  File "/home/airflow/.local/lib/python3.7/site-packages/sqlalchemy/dialects/mysql/base.py", line 2997, in get_table_options
    connection, table_name, schema, **kw
  File "/home/airflow/.local/lib/python3.7/site-packages/sqlalchemy/dialects/mysql/base.py", line 3249, in _parsed_state_or_create
    info_cache=kw.get("info_cache", None),
  File "<string>", line 2, in _setup_parser
  File "/home/airflow/.local/lib/python3.7/site-packages/sqlalchemy/engine/reflection.py", line 55, in cache
    ret = fn(self, con, *args, **kw)
  File "/home/airflow/.local/lib/python3.7/site-packages/sqlalchemy/dialects/mysql/base.py", line 3273, in _setup_parser
    connection, None, charset, full_name=full_name
  File "/home/airflow/.local/lib/python3.7/site-packages/sqlalchemy/dialects/mysql/base.py", line 3376, in _show_create_table
    util.raise_(exc.NoSuchTableError(full_name), replace_context=e)
  File "/home/airflow/.local/lib/python3.7/site-packages/sqlalchemy/util/compat.py", line 211, in raise_
    raise exception
sqlalchemy.exc.NoSuchTableError: `covid_jabar`
[2023-11-26 18:15:25,107] {taskinstance.py:1400} INFO - Marking task as UP_FOR_RETRY. dag_id=data_covid_etl, task_id=ingest_staging_db, execution_date=20231124T000000, start_date=20231126T181524, end_date=20231126T181525
[2023-11-26 18:15:25,127] {standard_task_runner.py:97} ERROR - Failed to execute job 261 for task ingest_staging_db (`covid_jabar`; 1630)
[2023-11-26 18:15:25,178] {local_task_job.py:156} INFO - Task exited with return code 1
[2023-11-26 18:15:25,247] {local_task_job.py:273} INFO - 0 downstream tasks scheduled from follow-on schedule check
