[2023-11-27 14:16:03,180] {taskinstance.py:1159} INFO - Dependencies all met for <TaskInstance: final_project_data_covid_etl.create_fact_district_daily scheduled__2023-11-26T00:00:00+00:00 [queued]>
[2023-11-27 14:16:03,191] {taskinstance.py:1159} INFO - Dependencies all met for <TaskInstance: final_project_data_covid_etl.create_fact_district_daily scheduled__2023-11-26T00:00:00+00:00 [queued]>
[2023-11-27 14:16:03,191] {taskinstance.py:1356} INFO - 
--------------------------------------------------------------------------------
[2023-11-27 14:16:03,191] {taskinstance.py:1357} INFO - Starting attempt 3 of 5
[2023-11-27 14:16:03,191] {taskinstance.py:1358} INFO - 
--------------------------------------------------------------------------------
[2023-11-27 14:16:03,207] {taskinstance.py:1377} INFO - Executing <Task(PythonOperator): create_fact_district_daily> on 2023-11-26 00:00:00+00:00
[2023-11-27 14:16:03,212] {standard_task_runner.py:52} INFO - Started process 646 to run task
[2023-11-27 14:16:03,214] {standard_task_runner.py:79} INFO - Running: ['***', 'tasks', 'run', 'final_project_data_covid_etl', 'create_fact_district_daily', 'scheduled__2023-11-26T00:00:00+00:00', '--job-id', '443', '--raw', '--subdir', 'DAGS_FOLDER/get_data.py', '--cfg-path', '/tmp/tmpkkcsio5q', '--error-file', '/tmp/tmpn4jrf9e_']
[2023-11-27 14:16:03,215] {standard_task_runner.py:80} INFO - Job 443: Subtask create_fact_district_daily
[2023-11-27 14:16:03,270] {task_command.py:369} INFO - Running <TaskInstance: final_project_data_covid_etl.create_fact_district_daily scheduled__2023-11-26T00:00:00+00:00 [running]> on host 9bd194bc0dbc
[2023-11-27 14:16:03,355] {taskinstance.py:1571} INFO - Exporting the following env vars:
AIRFLOW_CTX_DAG_OWNER=ricky
AIRFLOW_CTX_DAG_ID=final_project_data_covid_etl
AIRFLOW_CTX_TASK_ID=create_fact_district_daily
AIRFLOW_CTX_EXECUTION_DATE=2023-11-26T00:00:00+00:00
AIRFLOW_CTX_TRY_NUMBER=3
AIRFLOW_CTX_DAG_RUN_ID=scheduled__2023-11-26T00:00:00+00:00
[2023-11-27 14:16:03,446] {taskinstance.py:1889} ERROR - Task failed with exception
Traceback (most recent call last):
  File "/home/airflow/.local/lib/python3.7/site-packages/sqlalchemy/engine/base.py", line 1194, in execute
    meth = statement._execute_on_connection
  File "/home/airflow/.local/lib/python3.7/site-packages/pandas/core/generic.py", line 5487, in __getattr__
    return object.__getattribute__(self, name)
AttributeError: 'DataFrame' object has no attribute '_execute_on_connection'

The above exception was the direct cause of the following exception:

Traceback (most recent call last):
  File "/home/airflow/.local/lib/python3.7/site-packages/airflow/operators/python.py", line 171, in execute
    return_value = self.execute_callable()
  File "/home/airflow/.local/lib/python3.7/site-packages/airflow/operators/python.py", line 189, in execute_callable
    return self.python_callable(*self.op_args, **self.op_kwargs)
  File "/opt/airflow/dags/get_data.py", line 92, in create_fact_district_daily
    df = pd.read_sql(sql_query, engine)
  File "/home/airflow/.local/lib/python3.7/site-packages/pandas/io/sql.py", line 634, in read_sql
    chunksize=chunksize,
  File "/home/airflow/.local/lib/python3.7/site-packages/pandas/io/sql.py", line 1579, in read_query
    result = self.execute(*args)
  File "/home/airflow/.local/lib/python3.7/site-packages/pandas/io/sql.py", line 1424, in execute
    return self.connectable.execution_options().execute(*args, **kwargs)
  File "<string>", line 2, in execute
  File "/home/airflow/.local/lib/python3.7/site-packages/sqlalchemy/util/deprecations.py", line 390, in warned
    return fn(*args, **kwargs)
  File "/home/airflow/.local/lib/python3.7/site-packages/sqlalchemy/engine/base.py", line 3037, in execute
    return connection.execute(statement, *multiparams, **params)
  File "/home/airflow/.local/lib/python3.7/site-packages/sqlalchemy/engine/base.py", line 1197, in execute
    exc.ObjectNotExecutableError(statement), replace_context=err
  File "/home/airflow/.local/lib/python3.7/site-packages/sqlalchemy/util/compat.py", line 211, in raise_
    raise exception
sqlalchemy.exc.ObjectNotExecutableError: Not an executable object:      CLOSECONTACT  CONFIRMATION  ...  suspect_meninggal     tanggal
0             274             0  ...                  0  2020-08-05
1             534             0  ...                  0  2020-08-05
2            2127             0  ...                  0  2020-08-05
3               0             0  ...                  0  2020-08-05
4            1295             0  ...                  0  2020-08-05
..            ...           ...  ...                ...         ...
140            32             0  ...                  2  2020-08-10
141             0             0  ...                  0  2020-08-10
142             0             2  ...                  0  2020-08-10
143            12             0  ...                  0  2020-08-10
144            28             1  ...                  0  2020-08-10

[145 rows x 20 columns]
[2023-11-27 14:16:03,459] {taskinstance.py:1400} INFO - Marking task as UP_FOR_RETRY. dag_id=final_project_data_covid_etl, task_id=create_fact_district_daily, execution_date=20231126T000000, start_date=20231127T141603, end_date=20231127T141603
[2023-11-27 14:16:03,472] {standard_task_runner.py:97} ERROR - Failed to execute job 443 for task create_fact_district_daily (Not an executable object:      CLOSECONTACT  CONFIRMATION  ...  suspect_meninggal     tanggal
0             274             0  ...                  0  2020-08-05
1             534             0  ...                  0  2020-08-05
2            2127             0  ...                  0  2020-08-05
3               0             0  ...                  0  2020-08-05
4            1295             0  ...                  0  2020-08-05
..            ...           ...  ...                ...         ...
140            32             0  ...                  2  2020-08-10
141             0             0  ...                  0  2020-08-10
142             0             2  ...                  0  2020-08-10
143            12             0  ...                  0  2020-08-10
144            28             1  ...                  0  2020-08-10

[145 rows x 20 columns]; 646)
[2023-11-27 14:16:03,506] {local_task_job.py:156} INFO - Task exited with return code 1
[2023-11-27 14:16:03,561] {local_task_job.py:273} INFO - 0 downstream tasks scheduled from follow-on schedule check
[2023-11-27 14:30:37,695] {taskinstance.py:1159} INFO - Dependencies all met for <TaskInstance: final_project_data_covid_etl.create_fact_district_daily scheduled__2023-11-26T00:00:00+00:00 [queued]>
[2023-11-27 14:30:37,706] {taskinstance.py:1159} INFO - Dependencies all met for <TaskInstance: final_project_data_covid_etl.create_fact_district_daily scheduled__2023-11-26T00:00:00+00:00 [queued]>
[2023-11-27 14:30:37,707] {taskinstance.py:1356} INFO - 
--------------------------------------------------------------------------------
[2023-11-27 14:30:37,707] {taskinstance.py:1357} INFO - Starting attempt 3 of 5
[2023-11-27 14:30:37,707] {taskinstance.py:1358} INFO - 
--------------------------------------------------------------------------------
[2023-11-27 14:30:37,722] {taskinstance.py:1377} INFO - Executing <Task(PythonOperator): create_fact_district_daily> on 2023-11-26 00:00:00+00:00
[2023-11-27 14:30:37,726] {standard_task_runner.py:52} INFO - Started process 1086 to run task
[2023-11-27 14:30:37,729] {standard_task_runner.py:79} INFO - Running: ['***', 'tasks', 'run', 'final_project_data_covid_etl', 'create_fact_district_daily', 'scheduled__2023-11-26T00:00:00+00:00', '--job-id', '467', '--raw', '--subdir', 'DAGS_FOLDER/get_data.py', '--cfg-path', '/tmp/tmpq2o34xye', '--error-file', '/tmp/tmp33n8w6l8']
[2023-11-27 14:30:37,730] {standard_task_runner.py:80} INFO - Job 467: Subtask create_fact_district_daily
[2023-11-27 14:30:37,794] {task_command.py:369} INFO - Running <TaskInstance: final_project_data_covid_etl.create_fact_district_daily scheduled__2023-11-26T00:00:00+00:00 [running]> on host 9bd194bc0dbc
[2023-11-27 14:30:37,893] {taskinstance.py:1571} INFO - Exporting the following env vars:
AIRFLOW_CTX_DAG_OWNER=ricky
AIRFLOW_CTX_DAG_ID=final_project_data_covid_etl
AIRFLOW_CTX_TASK_ID=create_fact_district_daily
AIRFLOW_CTX_EXECUTION_DATE=2023-11-26T00:00:00+00:00
AIRFLOW_CTX_TRY_NUMBER=3
AIRFLOW_CTX_DAG_RUN_ID=scheduled__2023-11-26T00:00:00+00:00
[2023-11-27 14:30:37,940] {logging_mixin.py:115} INFO -    CLOSECONTACT  CONFIRMATION  ...  suspect_meninggal     tanggal
0           274             0  ...                  0  2020-08-05
1           534             0  ...                  0  2020-08-05
2          2127             0  ...                  0  2020-08-05
3             0             0  ...                  0  2020-08-05
4          1295             0  ...                  0  2020-08-05

[5 rows x 20 columns]
[2023-11-27 14:30:37,940] {python.py:173} INFO - Done. Returned value was: None
[2023-11-27 14:30:37,954] {taskinstance.py:1400} INFO - Marking task as SUCCESS. dag_id=final_project_data_covid_etl, task_id=create_fact_district_daily, execution_date=20231126T000000, start_date=20231127T143037, end_date=20231127T143037
[2023-11-27 14:30:37,981] {local_task_job.py:156} INFO - Task exited with return code 0
[2023-11-27 14:30:38,017] {local_task_job.py:273} INFO - 1 downstream tasks scheduled from follow-on schedule check
