[2023-11-27 14:48:20,189] {taskinstance.py:1159} INFO - Dependencies all met for <TaskInstance: final_project_data_covid_etl.create_fact_district_daily scheduled__2023-11-26T00:00:00+00:00 [queued]>
[2023-11-27 14:48:20,198] {taskinstance.py:1159} INFO - Dependencies all met for <TaskInstance: final_project_data_covid_etl.create_fact_district_daily scheduled__2023-11-26T00:00:00+00:00 [queued]>
[2023-11-27 14:48:20,198] {taskinstance.py:1356} INFO - 
--------------------------------------------------------------------------------
[2023-11-27 14:48:20,198] {taskinstance.py:1357} INFO - Starting attempt 8 of 10
[2023-11-27 14:48:20,198] {taskinstance.py:1358} INFO - 
--------------------------------------------------------------------------------
[2023-11-27 14:48:20,213] {taskinstance.py:1377} INFO - Executing <Task(PythonOperator): create_fact_district_daily> on 2023-11-26 00:00:00+00:00
[2023-11-27 14:48:20,217] {standard_task_runner.py:52} INFO - Started process 1545 to run task
[2023-11-27 14:48:20,219] {standard_task_runner.py:79} INFO - Running: ['***', 'tasks', 'run', 'final_project_data_covid_etl', 'create_fact_district_daily', 'scheduled__2023-11-26T00:00:00+00:00', '--job-id', '476', '--raw', '--subdir', 'DAGS_FOLDER/get_data.py', '--cfg-path', '/tmp/tmpy6ihuzkp', '--error-file', '/tmp/tmp_f2h2ebg']
[2023-11-27 14:48:20,220] {standard_task_runner.py:80} INFO - Job 476: Subtask create_fact_district_daily
[2023-11-27 14:48:20,271] {task_command.py:369} INFO - Running <TaskInstance: final_project_data_covid_etl.create_fact_district_daily scheduled__2023-11-26T00:00:00+00:00 [running]> on host 9bd194bc0dbc
[2023-11-27 14:48:20,341] {taskinstance.py:1571} INFO - Exporting the following env vars:
AIRFLOW_CTX_DAG_OWNER=ricky
AIRFLOW_CTX_DAG_ID=final_project_data_covid_etl
AIRFLOW_CTX_TASK_ID=create_fact_district_daily
AIRFLOW_CTX_EXECUTION_DATE=2023-11-26T00:00:00+00:00
AIRFLOW_CTX_TRY_NUMBER=8
AIRFLOW_CTX_DAG_RUN_ID=scheduled__2023-11-26T00:00:00+00:00
[2023-11-27 14:48:20,382] {logging_mixin.py:115} INFO -    CLOSECONTACT  CONFIRMATION  ...  suspect_meninggal     tanggal
0           274             0  ...                  0  2020-08-05
1           534             0  ...                  0  2020-08-05
2          2127             0  ...                  0  2020-08-05
3             0             0  ...                  0  2020-08-05
4          1295             0  ...                  0  2020-08-05

[5 rows x 20 columns]
[2023-11-27 14:48:20,418] {taskinstance.py:1889} ERROR - Task failed with exception
Traceback (most recent call last):
  File "/home/airflow/.local/lib/python3.7/site-packages/airflow/operators/python.py", line 171, in execute
    return_value = self.execute_callable()
  File "/home/airflow/.local/lib/python3.7/site-packages/airflow/operators/python.py", line 189, in execute_callable
    return self.python_callable(*self.op_args, **self.op_kwargs)
  File "/opt/airflow/dags/get_data.py", line 102, in create_fact_district_daily
    df_pivoted = pd.pivot_table(df_pg, index=['date', 'province_id'], columns='status', values='total', aggfunc='sum', fill_value=0)
  File "/home/airflow/.local/lib/python3.7/site-packages/pandas/core/reshape/pivot.py", line 106, in pivot_table
    sort,
  File "/home/airflow/.local/lib/python3.7/site-packages/pandas/core/reshape/pivot.py", line 141, in __internal_pivot_table
    raise KeyError(i)
KeyError: 'total'
[2023-11-27 14:48:20,428] {taskinstance.py:1400} INFO - Marking task as UP_FOR_RETRY. dag_id=final_project_data_covid_etl, task_id=create_fact_district_daily, execution_date=20231126T000000, start_date=20231127T144820, end_date=20231127T144820
[2023-11-27 14:48:20,442] {standard_task_runner.py:97} ERROR - Failed to execute job 476 for task create_fact_district_daily ('total'; 1545)
[2023-11-27 14:48:20,472] {local_task_job.py:156} INFO - Task exited with return code 1
[2023-11-27 14:48:20,524] {local_task_job.py:273} INFO - 0 downstream tasks scheduled from follow-on schedule check
