[2023-11-26 14:26:17,405] {taskinstance.py:1159} INFO - Dependencies all met for <TaskInstance: data_covid_etl.ingest_staging_db manual__2023-11-26T14:26:13.801347+00:00 [queued]>
[2023-11-26 14:26:17,438] {taskinstance.py:1159} INFO - Dependencies all met for <TaskInstance: data_covid_etl.ingest_staging_db manual__2023-11-26T14:26:13.801347+00:00 [queued]>
[2023-11-26 14:26:17,438] {taskinstance.py:1356} INFO - 
--------------------------------------------------------------------------------
[2023-11-26 14:26:17,438] {taskinstance.py:1357} INFO - Starting attempt 1 of 6
[2023-11-26 14:26:17,438] {taskinstance.py:1358} INFO - 
--------------------------------------------------------------------------------
[2023-11-26 14:26:17,489] {taskinstance.py:1377} INFO - Executing <Task(PythonOperator): ingest_staging_db> on 2023-11-26 14:26:13.801347+00:00
[2023-11-26 14:26:17,503] {standard_task_runner.py:52} INFO - Started process 676 to run task
[2023-11-26 14:26:17,516] {standard_task_runner.py:79} INFO - Running: ['***', 'tasks', 'run', 'data_covid_etl', 'ingest_staging_db', 'manual__2023-11-26T14:26:13.801347+00:00', '--job-id', '15', '--raw', '--subdir', 'DAGS_FOLDER/get_data.py', '--cfg-path', '/tmp/tmp_qgqqhwj', '--error-file', '/tmp/tmpq_bowozk']
[2023-11-26 14:26:17,520] {standard_task_runner.py:80} INFO - Job 15: Subtask ingest_staging_db
[2023-11-26 14:26:17,631] {task_command.py:369} INFO - Running <TaskInstance: data_covid_etl.ingest_staging_db manual__2023-11-26T14:26:13.801347+00:00 [running]> on host f384f2afcc4f
[2023-11-26 14:26:17,777] {taskinstance.py:1571} INFO - Exporting the following env vars:
AIRFLOW_CTX_DAG_OWNER=oce
AIRFLOW_CTX_DAG_ID=data_covid_etl
AIRFLOW_CTX_TASK_ID=ingest_staging_db
AIRFLOW_CTX_EXECUTION_DATE=2023-11-26T14:26:13.801347+00:00
AIRFLOW_CTX_TRY_NUMBER=1
AIRFLOW_CTX_DAG_RUN_ID=manual__2023-11-26T14:26:13.801347+00:00
[2023-11-26 14:26:18,765] {taskinstance.py:1889} ERROR - Task failed with exception
Traceback (most recent call last):
  File "/home/airflow/.local/lib/python3.7/site-packages/sqlalchemy/engine/base.py", line 1706, in _execute_context
    cursor, statement, parameters, context
  File "/home/airflow/.local/lib/python3.7/site-packages/sqlalchemy/engine/default.py", line 716, in do_execute
    cursor.execute(statement, parameters)
  File "/home/airflow/.local/lib/python3.7/site-packages/MySQLdb/cursors.py", line 206, in execute
    res = self._query(query)
  File "/home/airflow/.local/lib/python3.7/site-packages/MySQLdb/cursors.py", line 319, in _query
    db.query(q)
  File "/home/airflow/.local/lib/python3.7/site-packages/MySQLdb/connections.py", line 254, in query
    _mysql.connection.query(self, query)
MySQLdb._exceptions.OperationalError: (1051, "Unknown table 'finalproject.covid_jabar'")

The above exception was the direct cause of the following exception:

Traceback (most recent call last):
  File "/home/airflow/.local/lib/python3.7/site-packages/airflow/operators/python.py", line 171, in execute
    return_value = self.execute_callable()
  File "/home/airflow/.local/lib/python3.7/site-packages/airflow/operators/python.py", line 189, in execute_callable
    return self.python_callable(*self.op_args, **self.op_kwargs)
  File "/opt/airflow/dags/get_data.py", line 36, in ingest_data_staging
    df.to_sql("covid_jabar", staging_db_constring, if_exists="replace", index=False)
  File "/home/airflow/.local/lib/python3.7/site-packages/pandas/core/generic.py", line 2882, in to_sql
    method=method,
  File "/home/airflow/.local/lib/python3.7/site-packages/pandas/io/sql.py", line 728, in to_sql
    **engine_kwargs,
  File "/home/airflow/.local/lib/python3.7/site-packages/pandas/io/sql.py", line 1758, in to_sql
    dtype=dtype,
  File "/home/airflow/.local/lib/python3.7/site-packages/pandas/io/sql.py", line 1650, in prep_table
    table.create()
  File "/home/airflow/.local/lib/python3.7/site-packages/pandas/io/sql.py", line 860, in create
    self.pd_sql.drop_table(self.name, self.schema)
  File "/home/airflow/.local/lib/python3.7/site-packages/pandas/io/sql.py", line 1810, in drop_table
    self.get_table(table_name, schema).drop()
  File "/home/airflow/.local/lib/python3.7/site-packages/sqlalchemy/sql/schema.py", line 960, in drop
    bind._run_ddl_visitor(ddl.SchemaDropper, self, checkfirst=checkfirst)
  File "/home/airflow/.local/lib/python3.7/site-packages/sqlalchemy/engine/base.py", line 3008, in _run_ddl_visitor
    conn._run_ddl_visitor(visitorcallable, element, **kwargs)
  File "/home/airflow/.local/lib/python3.7/site-packages/sqlalchemy/engine/base.py", line 2016, in _run_ddl_visitor
    visitorcallable(self.dialect, self, **kwargs).traverse_single(element)
  File "/home/airflow/.local/lib/python3.7/site-packages/sqlalchemy/sql/visitors.py", line 483, in traverse_single
    return meth(obj, **kw)
  File "/home/airflow/.local/lib/python3.7/site-packages/sqlalchemy/sql/ddl.py", line 1097, in visit_table
    self.connection.execute(DropTable(table))
  File "/home/airflow/.local/lib/python3.7/site-packages/sqlalchemy/engine/base.py", line 1200, in execute
    return meth(self, multiparams, params, _EMPTY_EXECUTION_OPTS)
  File "/home/airflow/.local/lib/python3.7/site-packages/sqlalchemy/sql/ddl.py", line 78, in _execute_on_connection
    self, multiparams, params, execution_options
  File "/home/airflow/.local/lib/python3.7/site-packages/sqlalchemy/engine/base.py", line 1296, in _execute_ddl
    compiled,
  File "/home/airflow/.local/lib/python3.7/site-packages/sqlalchemy/engine/base.py", line 1749, in _execute_context
    e, statement, parameters, cursor, context
  File "/home/airflow/.local/lib/python3.7/site-packages/sqlalchemy/engine/base.py", line 1930, in _handle_dbapi_exception
    sqlalchemy_exception, with_traceback=exc_info[2], from_=e
  File "/home/airflow/.local/lib/python3.7/site-packages/sqlalchemy/util/compat.py", line 211, in raise_
    raise exception
  File "/home/airflow/.local/lib/python3.7/site-packages/sqlalchemy/engine/base.py", line 1706, in _execute_context
    cursor, statement, parameters, context
  File "/home/airflow/.local/lib/python3.7/site-packages/sqlalchemy/engine/default.py", line 716, in do_execute
    cursor.execute(statement, parameters)
  File "/home/airflow/.local/lib/python3.7/site-packages/MySQLdb/cursors.py", line 206, in execute
    res = self._query(query)
  File "/home/airflow/.local/lib/python3.7/site-packages/MySQLdb/cursors.py", line 319, in _query
    db.query(q)
  File "/home/airflow/.local/lib/python3.7/site-packages/MySQLdb/connections.py", line 254, in query
    _mysql.connection.query(self, query)
sqlalchemy.exc.OperationalError: (MySQLdb._exceptions.OperationalError) (1051, "Unknown table 'finalproject.covid_jabar'")
[SQL: 
DROP TABLE covid_jabar]
(Background on this error at: http://sqlalche.me/e/14/e3q8)
[2023-11-26 14:26:18,782] {taskinstance.py:1400} INFO - Marking task as UP_FOR_RETRY. dag_id=data_covid_etl, task_id=ingest_staging_db, execution_date=20231126T142613, start_date=20231126T142617, end_date=20231126T142618
[2023-11-26 14:26:18,821] {standard_task_runner.py:97} ERROR - Failed to execute job 15 for task ingest_staging_db ((MySQLdb._exceptions.OperationalError) (1051, "Unknown table 'finalproject.covid_jabar'")
[SQL: 
DROP TABLE covid_jabar]
(Background on this error at: http://sqlalche.me/e/14/e3q8); 676)
[2023-11-26 14:26:18,853] {local_task_job.py:156} INFO - Task exited with return code 1
[2023-11-26 14:26:18,896] {local_task_job.py:273} INFO - 0 downstream tasks scheduled from follow-on schedule check
