[2023-11-27 14:28:29,689] {taskinstance.py:1159} INFO - Dependencies all met for <TaskInstance: final_project_data_covid_etl.create_fact_district_daily manual__2023-11-27T14:23:20.785587+00:00 [queued]>
[2023-11-27 14:28:29,698] {taskinstance.py:1159} INFO - Dependencies all met for <TaskInstance: final_project_data_covid_etl.create_fact_district_daily manual__2023-11-27T14:23:20.785587+00:00 [queued]>
[2023-11-27 14:28:29,699] {taskinstance.py:1356} INFO - 
--------------------------------------------------------------------------------
[2023-11-27 14:28:29,699] {taskinstance.py:1357} INFO - Starting attempt 1 of 3
[2023-11-27 14:28:29,699] {taskinstance.py:1358} INFO - 
--------------------------------------------------------------------------------
[2023-11-27 14:28:29,713] {taskinstance.py:1377} INFO - Executing <Task(PythonOperator): create_fact_district_daily> on 2023-11-27 14:23:20.785587+00:00
[2023-11-27 14:28:29,718] {standard_task_runner.py:52} INFO - Started process 1029 to run task
[2023-11-27 14:28:29,720] {standard_task_runner.py:79} INFO - Running: ['***', 'tasks', 'run', 'final_project_data_covid_etl', 'create_fact_district_daily', 'manual__2023-11-27T14:23:20.785587+00:00', '--job-id', '465', '--raw', '--subdir', 'DAGS_FOLDER/get_data.py', '--cfg-path', '/tmp/tmp6sq1l795', '--error-file', '/tmp/tmpzuu07m93']
[2023-11-27 14:28:29,720] {standard_task_runner.py:80} INFO - Job 465: Subtask create_fact_district_daily
[2023-11-27 14:28:29,767] {task_command.py:369} INFO - Running <TaskInstance: final_project_data_covid_etl.create_fact_district_daily manual__2023-11-27T14:23:20.785587+00:00 [running]> on host 9bd194bc0dbc
[2023-11-27 14:28:29,836] {taskinstance.py:1571} INFO - Exporting the following env vars:
AIRFLOW_CTX_DAG_OWNER=ricky
AIRFLOW_CTX_DAG_ID=final_project_data_covid_etl
AIRFLOW_CTX_TASK_ID=create_fact_district_daily
AIRFLOW_CTX_EXECUTION_DATE=2023-11-27T14:23:20.785587+00:00
AIRFLOW_CTX_TRY_NUMBER=1
AIRFLOW_CTX_DAG_RUN_ID=manual__2023-11-27T14:23:20.785587+00:00
[2023-11-27 14:28:29,878] {taskinstance.py:1889} ERROR - Task failed with exception
Traceback (most recent call last):
  File "/home/airflow/.local/lib/python3.7/site-packages/sqlalchemy/engine/base.py", line 1194, in execute
    meth = statement._execute_on_connection
  File "/home/airflow/.local/lib/python3.7/site-packages/pandas/core/generic.py", line 5487, in __getattr__
    return object.__getattribute__(self, name)
AttributeError: 'DataFrame' object has no attribute '_execute_on_connection'

The above exception was the direct cause of the following exception:

Traceback (most recent call last):
  File "/home/airflow/.local/lib/python3.7/site-packages/airflow/operators/python.py", line 171, in execute
    return_value = self.execute_callable()
  File "/home/airflow/.local/lib/python3.7/site-packages/airflow/operators/python.py", line 189, in execute_callable
    return self.python_callable(*self.op_args, **self.op_kwargs)
  File "/opt/airflow/dags/get_data.py", line 93, in create_fact_district_daily
    df = pd.read_sql_query(sql_query, engine)
  File "/home/airflow/.local/lib/python3.7/site-packages/pandas/io/sql.py", line 443, in read_sql_query
    dtype=dtype,
  File "/home/airflow/.local/lib/python3.7/site-packages/pandas/io/sql.py", line 1579, in read_query
    result = self.execute(*args)
  File "/home/airflow/.local/lib/python3.7/site-packages/pandas/io/sql.py", line 1424, in execute
    return self.connectable.execution_options().execute(*args, **kwargs)
  File "<string>", line 2, in execute
  File "/home/airflow/.local/lib/python3.7/site-packages/sqlalchemy/util/deprecations.py", line 390, in warned
    return fn(*args, **kwargs)
  File "/home/airflow/.local/lib/python3.7/site-packages/sqlalchemy/engine/base.py", line 3037, in execute
    return connection.execute(statement, *multiparams, **params)
  File "/home/airflow/.local/lib/python3.7/site-packages/sqlalchemy/engine/base.py", line 1197, in execute
    exc.ObjectNotExecutableError(statement), replace_context=err
  File "/home/airflow/.local/lib/python3.7/site-packages/sqlalchemy/util/compat.py", line 211, in raise_
    raise exception
sqlalchemy.exc.ObjectNotExecutableError: Not an executable object:      CLOSECONTACT  CONFIRMATION  ...  suspect_meninggal     tanggal
0             274             0  ...                  0  2020-08-05
1             534             0  ...                  0  2020-08-05
2            2127             0  ...                  0  2020-08-05
3               0             0  ...                  0  2020-08-05
4            1295             0  ...                  0  2020-08-05
..            ...           ...  ...                ...         ...
140            32             0  ...                  2  2020-08-10
141             0             0  ...                  0  2020-08-10
142             0             2  ...                  0  2020-08-10
143            12             0  ...                  0  2020-08-10
144            28             1  ...                  0  2020-08-10

[145 rows x 20 columns]
[2023-11-27 14:28:29,888] {taskinstance.py:1400} INFO - Marking task as UP_FOR_RETRY. dag_id=final_project_data_covid_etl, task_id=create_fact_district_daily, execution_date=20231127T142320, start_date=20231127T142829, end_date=20231127T142829
[2023-11-27 14:28:29,903] {standard_task_runner.py:97} ERROR - Failed to execute job 465 for task create_fact_district_daily (Not an executable object:      CLOSECONTACT  CONFIRMATION  ...  suspect_meninggal     tanggal
0             274             0  ...                  0  2020-08-05
1             534             0  ...                  0  2020-08-05
2            2127             0  ...                  0  2020-08-05
3               0             0  ...                  0  2020-08-05
4            1295             0  ...                  0  2020-08-05
..            ...           ...  ...                ...         ...
140            32             0  ...                  2  2020-08-10
141             0             0  ...                  0  2020-08-10
142             0             2  ...                  0  2020-08-10
143            12             0  ...                  0  2020-08-10
144            28             1  ...                  0  2020-08-10

[145 rows x 20 columns]; 1029)
[2023-11-27 14:28:29,933] {local_task_job.py:156} INFO - Task exited with return code 1
[2023-11-27 14:28:29,996] {local_task_job.py:273} INFO - 0 downstream tasks scheduled from follow-on schedule check
