[2023-11-26 17:58:07,164] {taskinstance.py:1159} INFO - Dependencies all met for <TaskInstance: data_covid_etl.create_dim_province manual__2023-11-26T17:57:07.249623+00:00 [queued]>
[2023-11-26 17:58:07,175] {taskinstance.py:1159} INFO - Dependencies all met for <TaskInstance: data_covid_etl.create_dim_province manual__2023-11-26T17:57:07.249623+00:00 [queued]>
[2023-11-26 17:58:07,175] {taskinstance.py:1356} INFO - 
--------------------------------------------------------------------------------
[2023-11-26 17:58:07,175] {taskinstance.py:1357} INFO - Starting attempt 2 of 7
[2023-11-26 17:58:07,176] {taskinstance.py:1358} INFO - 
--------------------------------------------------------------------------------
[2023-11-26 17:58:07,199] {taskinstance.py:1377} INFO - Executing <Task(PythonOperator): create_dim_province> on 2023-11-26 17:57:07.249623+00:00
[2023-11-26 17:58:07,204] {standard_task_runner.py:52} INFO - Started process 781 to run task
[2023-11-26 17:58:07,208] {standard_task_runner.py:79} INFO - Running: ['***', 'tasks', 'run', 'data_covid_etl', 'create_dim_province', 'manual__2023-11-26T17:57:07.249623+00:00', '--job-id', '139', '--raw', '--subdir', 'DAGS_FOLDER/get_data.py', '--cfg-path', '/tmp/tmpt9om3pd3', '--error-file', '/tmp/tmpdyw4v40_']
[2023-11-26 17:58:07,209] {standard_task_runner.py:80} INFO - Job 139: Subtask create_dim_province
[2023-11-26 17:58:07,259] {task_command.py:369} INFO - Running <TaskInstance: data_covid_etl.create_dim_province manual__2023-11-26T17:57:07.249623+00:00 [running]> on host 79a606f4be36
[2023-11-26 17:58:07,329] {taskinstance.py:1571} INFO - Exporting the following env vars:
AIRFLOW_CTX_DAG_OWNER=oce
AIRFLOW_CTX_DAG_ID=data_covid_etl
AIRFLOW_CTX_TASK_ID=create_dim_province
AIRFLOW_CTX_EXECUTION_DATE=2023-11-26T17:57:07.249623+00:00
AIRFLOW_CTX_TRY_NUMBER=2
AIRFLOW_CTX_DAG_RUN_ID=manual__2023-11-26T17:57:07.249623+00:00
[2023-11-26 17:58:07,330] {taskinstance.py:1889} ERROR - Task failed with exception
Traceback (most recent call last):
  File "/home/airflow/.local/lib/python3.7/site-packages/airflow/operators/python.py", line 171, in execute
    return_value = self.execute_callable()
  File "/home/airflow/.local/lib/python3.7/site-packages/airflow/operators/python.py", line 189, in execute_callable
    return self.python_callable(*self.op_args, **self.op_kwargs)
  File "/opt/airflow/dags/get_data.py", line 38, in create_dim_province
    engine = create_engine(staging_db_constring)
NameError: name 'create_engine' is not defined
[2023-11-26 17:58:07,340] {taskinstance.py:1400} INFO - Marking task as UP_FOR_RETRY. dag_id=data_covid_etl, task_id=create_dim_province, execution_date=20231126T175707, start_date=20231126T175807, end_date=20231126T175807
[2023-11-26 17:58:07,354] {standard_task_runner.py:97} ERROR - Failed to execute job 139 for task create_dim_province (name 'create_engine' is not defined; 781)
[2023-11-26 17:58:07,379] {local_task_job.py:156} INFO - Task exited with return code 1
[2023-11-26 17:58:07,424] {local_task_job.py:273} INFO - 0 downstream tasks scheduled from follow-on schedule check
