[2023-11-26 17:53:36,150] {taskinstance.py:1159} INFO - Dependencies all met for <TaskInstance: data_covid_etl.create_dim_province manual__2023-11-26T17:53:35.308758+00:00 [queued]>
[2023-11-26 17:53:36,163] {taskinstance.py:1159} INFO - Dependencies all met for <TaskInstance: data_covid_etl.create_dim_province manual__2023-11-26T17:53:35.308758+00:00 [queued]>
[2023-11-26 17:53:36,164] {taskinstance.py:1356} INFO - 
--------------------------------------------------------------------------------
[2023-11-26 17:53:36,165] {taskinstance.py:1357} INFO - Starting attempt 1 of 6
[2023-11-26 17:53:36,166] {taskinstance.py:1358} INFO - 
--------------------------------------------------------------------------------
[2023-11-26 17:53:36,185] {taskinstance.py:1377} INFO - Executing <Task(PythonOperator): create_dim_province> on 2023-11-26 17:53:35.308758+00:00
[2023-11-26 17:53:36,190] {standard_task_runner.py:52} INFO - Started process 523 to run task
[2023-11-26 17:53:36,198] {standard_task_runner.py:79} INFO - Running: ['***', 'tasks', 'run', 'data_covid_etl', 'create_dim_province', 'manual__2023-11-26T17:53:35.308758+00:00', '--job-id', '82', '--raw', '--subdir', 'DAGS_FOLDER/get_data.py', '--cfg-path', '/tmp/tmpmjt14_9b', '--error-file', '/tmp/tmprk2rmsza']
[2023-11-26 17:53:36,200] {standard_task_runner.py:80} INFO - Job 82: Subtask create_dim_province
[2023-11-26 17:53:36,297] {task_command.py:369} INFO - Running <TaskInstance: data_covid_etl.create_dim_province manual__2023-11-26T17:53:35.308758+00:00 [running]> on host 79a606f4be36
[2023-11-26 17:53:36,422] {taskinstance.py:1571} INFO - Exporting the following env vars:
AIRFLOW_CTX_DAG_OWNER=oce
AIRFLOW_CTX_DAG_ID=data_covid_etl
AIRFLOW_CTX_TASK_ID=create_dim_province
AIRFLOW_CTX_EXECUTION_DATE=2023-11-26T17:53:35.308758+00:00
AIRFLOW_CTX_TRY_NUMBER=1
AIRFLOW_CTX_DAG_RUN_ID=manual__2023-11-26T17:53:35.308758+00:00
[2023-11-26 17:53:36,423] {taskinstance.py:1889} ERROR - Task failed with exception
Traceback (most recent call last):
  File "/home/airflow/.local/lib/python3.7/site-packages/airflow/operators/python.py", line 171, in execute
    return_value = self.execute_callable()
  File "/home/airflow/.local/lib/python3.7/site-packages/airflow/operators/python.py", line 189, in execute_callable
    return self.python_callable(*self.op_args, **self.op_kwargs)
  File "/opt/airflow/dags/get_data.py", line 38, in create_dim_province
    engine = create_engine(staging_db_constring)
NameError: name 'create_engine' is not defined
[2023-11-26 17:53:36,431] {taskinstance.py:1400} INFO - Marking task as UP_FOR_RETRY. dag_id=data_covid_etl, task_id=create_dim_province, execution_date=20231126T175335, start_date=20231126T175336, end_date=20231126T175336
[2023-11-26 17:53:36,453] {standard_task_runner.py:97} ERROR - Failed to execute job 82 for task create_dim_province (name 'create_engine' is not defined; 523)
[2023-11-26 17:53:36,467] {local_task_job.py:156} INFO - Task exited with return code 1
[2023-11-26 17:53:36,513] {local_task_job.py:273} INFO - 0 downstream tasks scheduled from follow-on schedule check
