[2023-11-26 14:35:12,615] {taskinstance.py:1159} INFO - Dependencies all met for <TaskInstance: data_covid_etl.ingest_staging_db scheduled__2023-11-20T00:00:00+00:00 [queued]>
[2023-11-26 14:35:12,625] {taskinstance.py:1159} INFO - Dependencies all met for <TaskInstance: data_covid_etl.ingest_staging_db scheduled__2023-11-20T00:00:00+00:00 [queued]>
[2023-11-26 14:35:12,625] {taskinstance.py:1356} INFO - 
--------------------------------------------------------------------------------
[2023-11-26 14:35:12,625] {taskinstance.py:1357} INFO - Starting attempt 2 of 7
[2023-11-26 14:35:12,625] {taskinstance.py:1358} INFO - 
--------------------------------------------------------------------------------
[2023-11-26 14:35:12,640] {taskinstance.py:1377} INFO - Executing <Task(PythonOperator): ingest_staging_db> on 2023-11-20 00:00:00+00:00
[2023-11-26 14:35:12,644] {standard_task_runner.py:52} INFO - Started process 905 to run task
[2023-11-26 14:35:12,648] {standard_task_runner.py:79} INFO - Running: ['***', 'tasks', 'run', 'data_covid_etl', 'ingest_staging_db', 'scheduled__2023-11-20T00:00:00+00:00', '--job-id', '24', '--raw', '--subdir', 'DAGS_FOLDER/get_data.py', '--cfg-path', '/tmp/tmpk82x7gr_', '--error-file', '/tmp/tmpp0zabppg']
[2023-11-26 14:35:12,649] {standard_task_runner.py:80} INFO - Job 24: Subtask ingest_staging_db
[2023-11-26 14:35:12,730] {task_command.py:369} INFO - Running <TaskInstance: data_covid_etl.ingest_staging_db scheduled__2023-11-20T00:00:00+00:00 [running]> on host f384f2afcc4f
[2023-11-26 14:35:12,829] {taskinstance.py:1571} INFO - Exporting the following env vars:
AIRFLOW_CTX_DAG_OWNER=oce
AIRFLOW_CTX_DAG_ID=data_covid_etl
AIRFLOW_CTX_TASK_ID=ingest_staging_db
AIRFLOW_CTX_EXECUTION_DATE=2023-11-20T00:00:00+00:00
AIRFLOW_CTX_TRY_NUMBER=2
AIRFLOW_CTX_DAG_RUN_ID=scheduled__2023-11-20T00:00:00+00:00
[2023-11-26 14:35:14,005] {python.py:173} INFO - Done. Returned value was: None
[2023-11-26 14:35:14,019] {taskinstance.py:1400} INFO - Marking task as SUCCESS. dag_id=data_covid_etl, task_id=ingest_staging_db, execution_date=20231120T000000, start_date=20231126T143512, end_date=20231126T143514
[2023-11-26 14:35:14,065] {local_task_job.py:156} INFO - Task exited with return code 0
[2023-11-26 14:35:14,098] {local_task_job.py:273} INFO - 0 downstream tasks scheduled from follow-on schedule check
[2023-11-26 15:44:59,389] {taskinstance.py:1159} INFO - Dependencies all met for <TaskInstance: data_covid_etl.ingest_staging_db scheduled__2023-11-20T00:00:00+00:00 [queued]>
[2023-11-26 15:44:59,400] {taskinstance.py:1159} INFO - Dependencies all met for <TaskInstance: data_covid_etl.ingest_staging_db scheduled__2023-11-20T00:00:00+00:00 [queued]>
[2023-11-26 15:44:59,400] {taskinstance.py:1356} INFO - 
--------------------------------------------------------------------------------
[2023-11-26 15:44:59,400] {taskinstance.py:1357} INFO - Starting attempt 2 of 6
[2023-11-26 15:44:59,401] {taskinstance.py:1358} INFO - 
--------------------------------------------------------------------------------
[2023-11-26 15:44:59,425] {taskinstance.py:1377} INFO - Executing <Task(PythonOperator): ingest_staging_db> on 2023-11-20 00:00:00+00:00
[2023-11-26 15:44:59,431] {standard_task_runner.py:52} INFO - Started process 2736 to run task
[2023-11-26 15:44:59,434] {standard_task_runner.py:79} INFO - Running: ['***', 'tasks', 'run', 'data_covid_etl', 'ingest_staging_db', 'scheduled__2023-11-20T00:00:00+00:00', '--job-id', '76', '--raw', '--subdir', 'DAGS_FOLDER/get_data.py', '--cfg-path', '/tmp/tmp8nx214pp', '--error-file', '/tmp/tmp90aiahze']
[2023-11-26 15:44:59,434] {standard_task_runner.py:80} INFO - Job 76: Subtask ingest_staging_db
[2023-11-26 15:44:59,482] {task_command.py:369} INFO - Running <TaskInstance: data_covid_etl.ingest_staging_db scheduled__2023-11-20T00:00:00+00:00 [running]> on host f384f2afcc4f
[2023-11-26 15:44:59,558] {taskinstance.py:1571} INFO - Exporting the following env vars:
AIRFLOW_CTX_DAG_OWNER=oce
AIRFLOW_CTX_DAG_ID=data_covid_etl
AIRFLOW_CTX_TASK_ID=ingest_staging_db
AIRFLOW_CTX_EXECUTION_DATE=2023-11-20T00:00:00+00:00
AIRFLOW_CTX_TRY_NUMBER=2
AIRFLOW_CTX_DAG_RUN_ID=scheduled__2023-11-20T00:00:00+00:00
[2023-11-26 15:45:06,219] {taskinstance.py:1889} ERROR - Task failed with exception
Traceback (most recent call last):
  File "/home/airflow/.local/lib/python3.7/site-packages/sqlalchemy/engine/base.py", line 1706, in _execute_context
    cursor, statement, parameters, context
  File "/home/airflow/.local/lib/python3.7/site-packages/sqlalchemy/engine/default.py", line 716, in do_execute
    cursor.execute(statement, parameters)
  File "/home/airflow/.local/lib/python3.7/site-packages/MySQLdb/cursors.py", line 206, in execute
    res = self._query(query)
  File "/home/airflow/.local/lib/python3.7/site-packages/MySQLdb/cursors.py", line 319, in _query
    db.query(q)
  File "/home/airflow/.local/lib/python3.7/site-packages/MySQLdb/connections.py", line 254, in query
    _mysql.connection.query(self, query)
MySQLdb._exceptions.ProgrammingError: (1146, "Table 'finalproject.covid_jabar' doesn't exist")

The above exception was the direct cause of the following exception:

Traceback (most recent call last):
  File "/home/airflow/.local/lib/python3.7/site-packages/sqlalchemy/dialects/mysql/base.py", line 3373, in _show_create_table
    ).exec_driver_sql(st)
  File "/home/airflow/.local/lib/python3.7/site-packages/sqlalchemy/engine/base.py", line 1580, in exec_driver_sql
    future=True,
  File "/home/airflow/.local/lib/python3.7/site-packages/sqlalchemy/engine/base.py", line 1491, in _exec_driver_sql
    distilled_parameters,
  File "/home/airflow/.local/lib/python3.7/site-packages/sqlalchemy/engine/base.py", line 1749, in _execute_context
    e, statement, parameters, cursor, context
  File "/home/airflow/.local/lib/python3.7/site-packages/sqlalchemy/engine/base.py", line 1930, in _handle_dbapi_exception
    sqlalchemy_exception, with_traceback=exc_info[2], from_=e
  File "/home/airflow/.local/lib/python3.7/site-packages/sqlalchemy/util/compat.py", line 211, in raise_
    raise exception
  File "/home/airflow/.local/lib/python3.7/site-packages/sqlalchemy/engine/base.py", line 1706, in _execute_context
    cursor, statement, parameters, context
  File "/home/airflow/.local/lib/python3.7/site-packages/sqlalchemy/engine/default.py", line 716, in do_execute
    cursor.execute(statement, parameters)
  File "/home/airflow/.local/lib/python3.7/site-packages/MySQLdb/cursors.py", line 206, in execute
    res = self._query(query)
  File "/home/airflow/.local/lib/python3.7/site-packages/MySQLdb/cursors.py", line 319, in _query
    db.query(q)
  File "/home/airflow/.local/lib/python3.7/site-packages/MySQLdb/connections.py", line 254, in query
    _mysql.connection.query(self, query)
sqlalchemy.exc.ProgrammingError: (MySQLdb._exceptions.ProgrammingError) (1146, "Table 'finalproject.covid_jabar' doesn't exist")
[SQL: SHOW CREATE TABLE `covid_jabar`]
(Background on this error at: http://sqlalche.me/e/14/f405)

The above exception was the direct cause of the following exception:

Traceback (most recent call last):
  File "/home/airflow/.local/lib/python3.7/site-packages/airflow/operators/python.py", line 171, in execute
    return_value = self.execute_callable()
  File "/home/airflow/.local/lib/python3.7/site-packages/airflow/operators/python.py", line 189, in execute_callable
    return self.python_callable(*self.op_args, **self.op_kwargs)
  File "/opt/airflow/dags/get_data.py", line 36, in ingest_data_staging
    df.to_sql("covid_jabar", staging_db_constring, if_exists="replace", index=False)
  File "/home/airflow/.local/lib/python3.7/site-packages/pandas/core/generic.py", line 2882, in to_sql
    method=method,
  File "/home/airflow/.local/lib/python3.7/site-packages/pandas/io/sql.py", line 728, in to_sql
    **engine_kwargs,
  File "/home/airflow/.local/lib/python3.7/site-packages/pandas/io/sql.py", line 1758, in to_sql
    dtype=dtype,
  File "/home/airflow/.local/lib/python3.7/site-packages/pandas/io/sql.py", line 1650, in prep_table
    table.create()
  File "/home/airflow/.local/lib/python3.7/site-packages/pandas/io/sql.py", line 860, in create
    self.pd_sql.drop_table(self.name, self.schema)
  File "/home/airflow/.local/lib/python3.7/site-packages/pandas/io/sql.py", line 1809, in drop_table
    self.meta.reflect(only=[table_name], schema=schema)
  File "/home/airflow/.local/lib/python3.7/site-packages/sqlalchemy/sql/schema.py", line 4715, in reflect
    Table(name, self, **reflect_opts)
  File "<string>", line 2, in __new__
  File "/home/airflow/.local/lib/python3.7/site-packages/sqlalchemy/util/deprecations.py", line 298, in warned
    return fn(*args, **kwargs)
  File "/home/airflow/.local/lib/python3.7/site-packages/sqlalchemy/sql/schema.py", line 600, in __new__
    metadata._remove_table(name, schema)
  File "/home/airflow/.local/lib/python3.7/site-packages/sqlalchemy/util/langhelpers.py", line 72, in __exit__
    with_traceback=exc_tb,
  File "/home/airflow/.local/lib/python3.7/site-packages/sqlalchemy/util/compat.py", line 211, in raise_
    raise exception
  File "/home/airflow/.local/lib/python3.7/site-packages/sqlalchemy/sql/schema.py", line 595, in __new__
    table._init(name, metadata, *args, **kw)
  File "/home/airflow/.local/lib/python3.7/site-packages/sqlalchemy/sql/schema.py", line 675, in _init
    resolve_fks=resolve_fks,
  File "/home/airflow/.local/lib/python3.7/site-packages/sqlalchemy/sql/schema.py", line 710, in _autoload
    _extend_on=_extend_on,
  File "/home/airflow/.local/lib/python3.7/site-packages/sqlalchemy/engine/reflection.py", line 758, in reflect_table
    table_name, schema, **table.dialect_kwargs
  File "/home/airflow/.local/lib/python3.7/site-packages/sqlalchemy/engine/reflection.py", line 399, in get_table_options
    conn, table_name, schema, info_cache=self.info_cache, **kw
  File "<string>", line 2, in get_table_options
  File "/home/airflow/.local/lib/python3.7/site-packages/sqlalchemy/engine/reflection.py", line 55, in cache
    ret = fn(self, con, *args, **kw)
  File "/home/airflow/.local/lib/python3.7/site-packages/sqlalchemy/dialects/mysql/base.py", line 2997, in get_table_options
    connection, table_name, schema, **kw
  File "/home/airflow/.local/lib/python3.7/site-packages/sqlalchemy/dialects/mysql/base.py", line 3249, in _parsed_state_or_create
    info_cache=kw.get("info_cache", None),
  File "<string>", line 2, in _setup_parser
  File "/home/airflow/.local/lib/python3.7/site-packages/sqlalchemy/engine/reflection.py", line 55, in cache
    ret = fn(self, con, *args, **kw)
  File "/home/airflow/.local/lib/python3.7/site-packages/sqlalchemy/dialects/mysql/base.py", line 3273, in _setup_parser
    connection, None, charset, full_name=full_name
  File "/home/airflow/.local/lib/python3.7/site-packages/sqlalchemy/dialects/mysql/base.py", line 3376, in _show_create_table
    util.raise_(exc.NoSuchTableError(full_name), replace_context=e)
  File "/home/airflow/.local/lib/python3.7/site-packages/sqlalchemy/util/compat.py", line 211, in raise_
    raise exception
sqlalchemy.exc.NoSuchTableError: `covid_jabar`
[2023-11-26 15:45:06,238] {taskinstance.py:1400} INFO - Marking task as UP_FOR_RETRY. dag_id=data_covid_etl, task_id=ingest_staging_db, execution_date=20231120T000000, start_date=20231126T154459, end_date=20231126T154506
[2023-11-26 15:45:06,255] {standard_task_runner.py:97} ERROR - Failed to execute job 76 for task ingest_staging_db (`covid_jabar`; 2736)
[2023-11-26 15:45:06,282] {local_task_job.py:156} INFO - Task exited with return code 1
[2023-11-26 15:45:06,319] {local_task_job.py:273} INFO - 0 downstream tasks scheduled from follow-on schedule check
[2023-11-26 18:13:48,661] {taskinstance.py:1159} INFO - Dependencies all met for <TaskInstance: data_covid_etl.ingest_staging_db scheduled__2023-11-20T00:00:00+00:00 [queued]>
[2023-11-26 18:13:48,671] {taskinstance.py:1159} INFO - Dependencies all met for <TaskInstance: data_covid_etl.ingest_staging_db scheduled__2023-11-20T00:00:00+00:00 [queued]>
[2023-11-26 18:13:48,672] {taskinstance.py:1356} INFO - 
--------------------------------------------------------------------------------
[2023-11-26 18:13:48,672] {taskinstance.py:1357} INFO - Starting attempt 2 of 3
[2023-11-26 18:13:48,672] {taskinstance.py:1358} INFO - 
--------------------------------------------------------------------------------
[2023-11-26 18:13:48,687] {taskinstance.py:1377} INFO - Executing <Task(PythonOperator): ingest_staging_db> on 2023-11-20 00:00:00+00:00
[2023-11-26 18:13:48,693] {standard_task_runner.py:52} INFO - Started process 1495 to run task
[2023-11-26 18:13:48,698] {standard_task_runner.py:79} INFO - Running: ['***', 'tasks', 'run', 'data_covid_etl', 'ingest_staging_db', 'scheduled__2023-11-20T00:00:00+00:00', '--job-id', '234', '--raw', '--subdir', 'DAGS_FOLDER/get_data.py', '--cfg-path', '/tmp/tmpk6nmajvw', '--error-file', '/tmp/tmphh2m09oh']
[2023-11-26 18:13:48,699] {standard_task_runner.py:80} INFO - Job 234: Subtask ingest_staging_db
[2023-11-26 18:13:48,789] {task_command.py:369} INFO - Running <TaskInstance: data_covid_etl.ingest_staging_db scheduled__2023-11-20T00:00:00+00:00 [running]> on host 79a606f4be36
[2023-11-26 18:13:48,864] {taskinstance.py:1571} INFO - Exporting the following env vars:
AIRFLOW_CTX_DAG_OWNER=oce
AIRFLOW_CTX_DAG_ID=data_covid_etl
AIRFLOW_CTX_TASK_ID=ingest_staging_db
AIRFLOW_CTX_EXECUTION_DATE=2023-11-20T00:00:00+00:00
AIRFLOW_CTX_TRY_NUMBER=2
AIRFLOW_CTX_DAG_RUN_ID=scheduled__2023-11-20T00:00:00+00:00
[2023-11-26 18:13:49,440] {python.py:173} INFO - Done. Returned value was: None
[2023-11-26 18:13:49,505] {taskinstance.py:1400} INFO - Marking task as SUCCESS. dag_id=data_covid_etl, task_id=ingest_staging_db, execution_date=20231120T000000, start_date=20231126T181348, end_date=20231126T181349
[2023-11-26 18:13:49,557] {local_task_job.py:156} INFO - Task exited with return code 0
[2023-11-26 18:13:49,660] {local_task_job.py:273} INFO - 0 downstream tasks scheduled from follow-on schedule check
[2023-11-26 18:20:26,077] {taskinstance.py:1159} INFO - Dependencies all met for <TaskInstance: data_covid_etl.ingest_staging_db scheduled__2023-11-20T00:00:00+00:00 [queued]>
[2023-11-26 18:20:26,087] {taskinstance.py:1159} INFO - Dependencies all met for <TaskInstance: data_covid_etl.ingest_staging_db scheduled__2023-11-20T00:00:00+00:00 [queued]>
[2023-11-26 18:20:26,087] {taskinstance.py:1356} INFO - 
--------------------------------------------------------------------------------
[2023-11-26 18:20:26,087] {taskinstance.py:1357} INFO - Starting attempt 2 of 3
[2023-11-26 18:20:26,087] {taskinstance.py:1358} INFO - 
--------------------------------------------------------------------------------
[2023-11-26 18:20:26,106] {taskinstance.py:1377} INFO - Executing <Task(PythonOperator): ingest_staging_db> on 2023-11-20 00:00:00+00:00
[2023-11-26 18:20:26,111] {standard_task_runner.py:52} INFO - Started process 1804 to run task
[2023-11-26 18:20:26,118] {standard_task_runner.py:79} INFO - Running: ['***', 'tasks', 'run', 'data_covid_etl', 'ingest_staging_db', 'scheduled__2023-11-20T00:00:00+00:00', '--job-id', '278', '--raw', '--subdir', 'DAGS_FOLDER/get_data.py', '--cfg-path', '/tmp/tmpv80aro0e', '--error-file', '/tmp/tmp71q4b1_7']
[2023-11-26 18:20:26,123] {standard_task_runner.py:80} INFO - Job 278: Subtask ingest_staging_db
[2023-11-26 18:20:26,190] {task_command.py:369} INFO - Running <TaskInstance: data_covid_etl.ingest_staging_db scheduled__2023-11-20T00:00:00+00:00 [running]> on host 79a606f4be36
[2023-11-26 18:20:26,306] {taskinstance.py:1571} INFO - Exporting the following env vars:
AIRFLOW_CTX_DAG_OWNER=oce
AIRFLOW_CTX_DAG_ID=data_covid_etl
AIRFLOW_CTX_TASK_ID=ingest_staging_db
AIRFLOW_CTX_EXECUTION_DATE=2023-11-20T00:00:00+00:00
AIRFLOW_CTX_TRY_NUMBER=2
AIRFLOW_CTX_DAG_RUN_ID=scheduled__2023-11-20T00:00:00+00:00
[2023-11-26 18:20:26,781] {taskinstance.py:1889} ERROR - Task failed with exception
Traceback (most recent call last):
  File "/home/airflow/.local/lib/python3.7/site-packages/sqlalchemy/engine/base.py", line 1706, in _execute_context
    cursor, statement, parameters, context
  File "/home/airflow/.local/lib/python3.7/site-packages/sqlalchemy/engine/default.py", line 716, in do_execute
    cursor.execute(statement, parameters)
  File "/home/airflow/.local/lib/python3.7/site-packages/MySQLdb/cursors.py", line 206, in execute
    res = self._query(query)
  File "/home/airflow/.local/lib/python3.7/site-packages/MySQLdb/cursors.py", line 319, in _query
    db.query(q)
  File "/home/airflow/.local/lib/python3.7/site-packages/MySQLdb/connections.py", line 254, in query
    _mysql.connection.query(self, query)
MySQLdb._exceptions.ProgrammingError: (1146, "Table 'finalproject.covid_jabar' doesn't exist")

The above exception was the direct cause of the following exception:

Traceback (most recent call last):
  File "/home/airflow/.local/lib/python3.7/site-packages/sqlalchemy/dialects/mysql/base.py", line 3373, in _show_create_table
    ).exec_driver_sql(st)
  File "/home/airflow/.local/lib/python3.7/site-packages/sqlalchemy/engine/base.py", line 1580, in exec_driver_sql
    future=True,
  File "/home/airflow/.local/lib/python3.7/site-packages/sqlalchemy/engine/base.py", line 1491, in _exec_driver_sql
    distilled_parameters,
  File "/home/airflow/.local/lib/python3.7/site-packages/sqlalchemy/engine/base.py", line 1749, in _execute_context
    e, statement, parameters, cursor, context
  File "/home/airflow/.local/lib/python3.7/site-packages/sqlalchemy/engine/base.py", line 1930, in _handle_dbapi_exception
    sqlalchemy_exception, with_traceback=exc_info[2], from_=e
  File "/home/airflow/.local/lib/python3.7/site-packages/sqlalchemy/util/compat.py", line 211, in raise_
    raise exception
  File "/home/airflow/.local/lib/python3.7/site-packages/sqlalchemy/engine/base.py", line 1706, in _execute_context
    cursor, statement, parameters, context
  File "/home/airflow/.local/lib/python3.7/site-packages/sqlalchemy/engine/default.py", line 716, in do_execute
    cursor.execute(statement, parameters)
  File "/home/airflow/.local/lib/python3.7/site-packages/MySQLdb/cursors.py", line 206, in execute
    res = self._query(query)
  File "/home/airflow/.local/lib/python3.7/site-packages/MySQLdb/cursors.py", line 319, in _query
    db.query(q)
  File "/home/airflow/.local/lib/python3.7/site-packages/MySQLdb/connections.py", line 254, in query
    _mysql.connection.query(self, query)
sqlalchemy.exc.ProgrammingError: (MySQLdb._exceptions.ProgrammingError) (1146, "Table 'finalproject.covid_jabar' doesn't exist")
[SQL: SHOW CREATE TABLE `covid_jabar`]
(Background on this error at: http://sqlalche.me/e/14/f405)

The above exception was the direct cause of the following exception:

Traceback (most recent call last):
  File "/home/airflow/.local/lib/python3.7/site-packages/airflow/operators/python.py", line 171, in execute
    return_value = self.execute_callable()
  File "/home/airflow/.local/lib/python3.7/site-packages/airflow/operators/python.py", line 189, in execute_callable
    return self.python_callable(*self.op_args, **self.op_kwargs)
  File "/opt/airflow/dags/get_data.py", line 35, in ingest_data_staging
    df.to_sql("covid_jabar", staging_db_constring, if_exists="replace", index=False)
  File "/home/airflow/.local/lib/python3.7/site-packages/pandas/core/generic.py", line 2882, in to_sql
    method=method,
  File "/home/airflow/.local/lib/python3.7/site-packages/pandas/io/sql.py", line 728, in to_sql
    **engine_kwargs,
  File "/home/airflow/.local/lib/python3.7/site-packages/pandas/io/sql.py", line 1758, in to_sql
    dtype=dtype,
  File "/home/airflow/.local/lib/python3.7/site-packages/pandas/io/sql.py", line 1650, in prep_table
    table.create()
  File "/home/airflow/.local/lib/python3.7/site-packages/pandas/io/sql.py", line 860, in create
    self.pd_sql.drop_table(self.name, self.schema)
  File "/home/airflow/.local/lib/python3.7/site-packages/pandas/io/sql.py", line 1809, in drop_table
    self.meta.reflect(only=[table_name], schema=schema)
  File "/home/airflow/.local/lib/python3.7/site-packages/sqlalchemy/sql/schema.py", line 4715, in reflect
    Table(name, self, **reflect_opts)
  File "<string>", line 2, in __new__
  File "/home/airflow/.local/lib/python3.7/site-packages/sqlalchemy/util/deprecations.py", line 298, in warned
    return fn(*args, **kwargs)
  File "/home/airflow/.local/lib/python3.7/site-packages/sqlalchemy/sql/schema.py", line 600, in __new__
    metadata._remove_table(name, schema)
  File "/home/airflow/.local/lib/python3.7/site-packages/sqlalchemy/util/langhelpers.py", line 72, in __exit__
    with_traceback=exc_tb,
  File "/home/airflow/.local/lib/python3.7/site-packages/sqlalchemy/util/compat.py", line 211, in raise_
    raise exception
  File "/home/airflow/.local/lib/python3.7/site-packages/sqlalchemy/sql/schema.py", line 595, in __new__
    table._init(name, metadata, *args, **kw)
  File "/home/airflow/.local/lib/python3.7/site-packages/sqlalchemy/sql/schema.py", line 675, in _init
    resolve_fks=resolve_fks,
  File "/home/airflow/.local/lib/python3.7/site-packages/sqlalchemy/sql/schema.py", line 710, in _autoload
    _extend_on=_extend_on,
  File "/home/airflow/.local/lib/python3.7/site-packages/sqlalchemy/engine/reflection.py", line 758, in reflect_table
    table_name, schema, **table.dialect_kwargs
  File "/home/airflow/.local/lib/python3.7/site-packages/sqlalchemy/engine/reflection.py", line 399, in get_table_options
    conn, table_name, schema, info_cache=self.info_cache, **kw
  File "<string>", line 2, in get_table_options
  File "/home/airflow/.local/lib/python3.7/site-packages/sqlalchemy/engine/reflection.py", line 55, in cache
    ret = fn(self, con, *args, **kw)
  File "/home/airflow/.local/lib/python3.7/site-packages/sqlalchemy/dialects/mysql/base.py", line 2997, in get_table_options
    connection, table_name, schema, **kw
  File "/home/airflow/.local/lib/python3.7/site-packages/sqlalchemy/dialects/mysql/base.py", line 3249, in _parsed_state_or_create
    info_cache=kw.get("info_cache", None),
  File "<string>", line 2, in _setup_parser
  File "/home/airflow/.local/lib/python3.7/site-packages/sqlalchemy/engine/reflection.py", line 55, in cache
    ret = fn(self, con, *args, **kw)
  File "/home/airflow/.local/lib/python3.7/site-packages/sqlalchemy/dialects/mysql/base.py", line 3273, in _setup_parser
    connection, None, charset, full_name=full_name
  File "/home/airflow/.local/lib/python3.7/site-packages/sqlalchemy/dialects/mysql/base.py", line 3376, in _show_create_table
    util.raise_(exc.NoSuchTableError(full_name), replace_context=e)
  File "/home/airflow/.local/lib/python3.7/site-packages/sqlalchemy/util/compat.py", line 211, in raise_
    raise exception
sqlalchemy.exc.NoSuchTableError: `covid_jabar`
[2023-11-26 18:20:26,797] {taskinstance.py:1400} INFO - Marking task as UP_FOR_RETRY. dag_id=data_covid_etl, task_id=ingest_staging_db, execution_date=20231120T000000, start_date=20231126T182026, end_date=20231126T182026
[2023-11-26 18:20:26,817] {standard_task_runner.py:97} ERROR - Failed to execute job 278 for task ingest_staging_db (`covid_jabar`; 1804)
[2023-11-26 18:20:26,860] {local_task_job.py:156} INFO - Task exited with return code 1
[2023-11-26 18:20:26,898] {local_task_job.py:273} INFO - 0 downstream tasks scheduled from follow-on schedule check
