[2023-11-27 09:13:56,220] {taskinstance.py:1159} INFO - Dependencies all met for <TaskInstance: final_project_data_covid_etl.create_dim_case manual__2023-11-27T09:13:48.667181+00:00 [queued]>
[2023-11-27 09:13:56,229] {taskinstance.py:1159} INFO - Dependencies all met for <TaskInstance: final_project_data_covid_etl.create_dim_case manual__2023-11-27T09:13:48.667181+00:00 [queued]>
[2023-11-27 09:13:56,229] {taskinstance.py:1356} INFO - 
--------------------------------------------------------------------------------
[2023-11-27 09:13:56,229] {taskinstance.py:1357} INFO - Starting attempt 1 of 3
[2023-11-27 09:13:56,229] {taskinstance.py:1358} INFO - 
--------------------------------------------------------------------------------
[2023-11-27 09:13:56,243] {taskinstance.py:1377} INFO - Executing <Task(PythonOperator): create_dim_case> on 2023-11-27 09:13:48.667181+00:00
[2023-11-27 09:13:56,247] {standard_task_runner.py:52} INFO - Started process 256 to run task
[2023-11-27 09:13:56,249] {standard_task_runner.py:79} INFO - Running: ['***', 'tasks', 'run', 'final_project_data_covid_etl', 'create_dim_case', 'manual__2023-11-27T09:13:48.667181+00:00', '--job-id', '364', '--raw', '--subdir', 'DAGS_FOLDER/get_data.py', '--cfg-path', '/tmp/tmpu7hz3rc5', '--error-file', '/tmp/tmpfg66symj']
[2023-11-27 09:13:56,249] {standard_task_runner.py:80} INFO - Job 364: Subtask create_dim_case
[2023-11-27 09:13:56,308] {task_command.py:369} INFO - Running <TaskInstance: final_project_data_covid_etl.create_dim_case manual__2023-11-27T09:13:48.667181+00:00 [running]> on host f38c0c12695c
[2023-11-27 09:13:56,385] {taskinstance.py:1571} INFO - Exporting the following env vars:
AIRFLOW_CTX_DAG_OWNER=ricky
AIRFLOW_CTX_DAG_ID=final_project_data_covid_etl
AIRFLOW_CTX_TASK_ID=create_dim_case
AIRFLOW_CTX_EXECUTION_DATE=2023-11-27T09:13:48.667181+00:00
AIRFLOW_CTX_TRY_NUMBER=1
AIRFLOW_CTX_DAG_RUN_ID=manual__2023-11-27T09:13:48.667181+00:00
[2023-11-27 09:13:56,413] {taskinstance.py:1889} ERROR - Task failed with exception
Traceback (most recent call last):
  File "/home/airflow/.local/lib/python3.7/site-packages/sqlalchemy/engine/base.py", line 1706, in _execute_context
    cursor, statement, parameters, context
  File "/home/airflow/.local/lib/python3.7/site-packages/sqlalchemy/engine/default.py", line 716, in do_execute
    cursor.execute(statement, parameters)
  File "/home/airflow/.local/lib/python3.7/site-packages/MySQLdb/cursors.py", line 206, in execute
    res = self._query(query)
  File "/home/airflow/.local/lib/python3.7/site-packages/MySQLdb/cursors.py", line 319, in _query
    db.query(q)
  File "/home/airflow/.local/lib/python3.7/site-packages/MySQLdb/connections.py", line 254, in query
    _mysql.connection.query(self, query)
MySQLdb._exceptions.OperationalError: (1054, "Unknown column 'robable_discarded' in 'field list'")

The above exception was the direct cause of the following exception:

Traceback (most recent call last):
  File "/home/airflow/.local/lib/python3.7/site-packages/airflow/operators/python.py", line 171, in execute
    return_value = self.execute_callable()
  File "/home/airflow/.local/lib/python3.7/site-packages/airflow/operators/python.py", line 189, in execute_callable
    return self.python_callable(*self.op_args, **self.op_kwargs)
  File "/opt/airflow/dags/get_data.py", line 63, in create_dim_case
    '''select closecontact_dikarantina, closecontact_discarded, closecontact_meninggal, confirmation_meninggal, confirmation_sembuh, probable_diisolasi, robable_discarded, probable_meninggal, suspect_diisolasi, suspect_discarded, suspect_meninggal from covid_jabar''', engine)
  File "/home/airflow/.local/lib/python3.7/site-packages/pandas/io/sql.py", line 443, in read_sql_query
    dtype=dtype,
  File "/home/airflow/.local/lib/python3.7/site-packages/pandas/io/sql.py", line 1579, in read_query
    result = self.execute(*args)
  File "/home/airflow/.local/lib/python3.7/site-packages/pandas/io/sql.py", line 1424, in execute
    return self.connectable.execution_options().execute(*args, **kwargs)
  File "<string>", line 2, in execute
  File "/home/airflow/.local/lib/python3.7/site-packages/sqlalchemy/util/deprecations.py", line 390, in warned
    return fn(*args, **kwargs)
  File "/home/airflow/.local/lib/python3.7/site-packages/sqlalchemy/engine/base.py", line 3037, in execute
    return connection.execute(statement, *multiparams, **params)
  File "/home/airflow/.local/lib/python3.7/site-packages/sqlalchemy/engine/base.py", line 1190, in execute
    future=False,
  File "/home/airflow/.local/lib/python3.7/site-packages/sqlalchemy/engine/base.py", line 1491, in _exec_driver_sql
    distilled_parameters,
  File "/home/airflow/.local/lib/python3.7/site-packages/sqlalchemy/engine/base.py", line 1749, in _execute_context
    e, statement, parameters, cursor, context
  File "/home/airflow/.local/lib/python3.7/site-packages/sqlalchemy/engine/base.py", line 1930, in _handle_dbapi_exception
    sqlalchemy_exception, with_traceback=exc_info[2], from_=e
  File "/home/airflow/.local/lib/python3.7/site-packages/sqlalchemy/util/compat.py", line 211, in raise_
    raise exception
  File "/home/airflow/.local/lib/python3.7/site-packages/sqlalchemy/engine/base.py", line 1706, in _execute_context
    cursor, statement, parameters, context
  File "/home/airflow/.local/lib/python3.7/site-packages/sqlalchemy/engine/default.py", line 716, in do_execute
    cursor.execute(statement, parameters)
  File "/home/airflow/.local/lib/python3.7/site-packages/MySQLdb/cursors.py", line 206, in execute
    res = self._query(query)
  File "/home/airflow/.local/lib/python3.7/site-packages/MySQLdb/cursors.py", line 319, in _query
    db.query(q)
  File "/home/airflow/.local/lib/python3.7/site-packages/MySQLdb/connections.py", line 254, in query
    _mysql.connection.query(self, query)
sqlalchemy.exc.OperationalError: (MySQLdb._exceptions.OperationalError) (1054, "Unknown column 'robable_discarded' in 'field list'")
[SQL: select closecontact_dikarantina, closecontact_discarded, closecontact_meninggal, confirmation_meninggal, confirmation_sembuh, probable_diisolasi, robable_discarded, probable_meninggal, suspect_diisolasi, suspect_discarded, suspect_meninggal from covid_jabar]
(Background on this error at: http://sqlalche.me/e/14/e3q8)
[2023-11-27 09:13:56,423] {taskinstance.py:1400} INFO - Marking task as UP_FOR_RETRY. dag_id=final_project_data_covid_etl, task_id=create_dim_case, execution_date=20231127T091348, start_date=20231127T091356, end_date=20231127T091356
[2023-11-27 09:13:56,436] {standard_task_runner.py:97} ERROR - Failed to execute job 364 for task create_dim_case ((MySQLdb._exceptions.OperationalError) (1054, "Unknown column 'robable_discarded' in 'field list'")
[SQL: select closecontact_dikarantina, closecontact_discarded, closecontact_meninggal, confirmation_meninggal, confirmation_sembuh, probable_diisolasi, robable_discarded, probable_meninggal, suspect_diisolasi, suspect_discarded, suspect_meninggal from covid_jabar]
(Background on this error at: http://sqlalche.me/e/14/e3q8); 256)
[2023-11-27 09:13:56,461] {local_task_job.py:156} INFO - Task exited with return code 1
[2023-11-27 09:13:56,515] {local_task_job.py:273} INFO - 0 downstream tasks scheduled from follow-on schedule check
