[2023-11-27 14:12:31,648] {taskinstance.py:1159} INFO - Dependencies all met for <TaskInstance: final_project_data_covid_etl.create_dim_province manual__2023-11-27T14:12:26.943848+00:00 [queued]>
[2023-11-27 14:12:31,657] {taskinstance.py:1159} INFO - Dependencies all met for <TaskInstance: final_project_data_covid_etl.create_dim_province manual__2023-11-27T14:12:26.943848+00:00 [queued]>
[2023-11-27 14:12:31,658] {taskinstance.py:1356} INFO - 
--------------------------------------------------------------------------------
[2023-11-27 14:12:31,658] {taskinstance.py:1357} INFO - Starting attempt 1 of 3
[2023-11-27 14:12:31,658] {taskinstance.py:1358} INFO - 
--------------------------------------------------------------------------------
[2023-11-27 14:12:31,673] {taskinstance.py:1377} INFO - Executing <Task(PythonOperator): create_dim_province> on 2023-11-27 14:12:26.943848+00:00
[2023-11-27 14:12:31,678] {standard_task_runner.py:52} INFO - Started process 540 to run task
[2023-11-27 14:12:31,680] {standard_task_runner.py:79} INFO - Running: ['***', 'tasks', 'run', 'final_project_data_covid_etl', 'create_dim_province', 'manual__2023-11-27T14:12:26.943848+00:00', '--job-id', '437', '--raw', '--subdir', 'DAGS_FOLDER/get_data.py', '--cfg-path', '/tmp/tmp3j43n1sm', '--error-file', '/tmp/tmpmcx6bxfe']
[2023-11-27 14:12:31,681] {standard_task_runner.py:80} INFO - Job 437: Subtask create_dim_province
[2023-11-27 14:12:31,730] {task_command.py:369} INFO - Running <TaskInstance: final_project_data_covid_etl.create_dim_province manual__2023-11-27T14:12:26.943848+00:00 [running]> on host 9bd194bc0dbc
[2023-11-27 14:12:31,795] {taskinstance.py:1571} INFO - Exporting the following env vars:
AIRFLOW_CTX_DAG_OWNER=ricky
AIRFLOW_CTX_DAG_ID=final_project_data_covid_etl
AIRFLOW_CTX_TASK_ID=create_dim_province
AIRFLOW_CTX_EXECUTION_DATE=2023-11-27T14:12:26.943848+00:00
AIRFLOW_CTX_TRY_NUMBER=1
AIRFLOW_CTX_DAG_RUN_ID=manual__2023-11-27T14:12:26.943848+00:00
[2023-11-27 14:12:31,819] {logging_mixin.py:115} INFO - province_id province_name
         32    Jawa Barat
[2023-11-27 14:12:31,867] {taskinstance.py:1889} ERROR - Task failed with exception
Traceback (most recent call last):
  File "/home/airflow/.local/lib/python3.7/site-packages/sqlalchemy/engine/base.py", line 1706, in _execute_context
    cursor, statement, parameters, context
  File "/home/airflow/.local/lib/python3.7/site-packages/sqlalchemy/engine/default.py", line 716, in do_execute
    cursor.execute(statement, parameters)
psycopg2.errors.UndefinedTable: relation "dim_province" does not exist
LINE 1: INSERT INTO dim_province (province_id, province_name) VALUES...
                    ^


The above exception was the direct cause of the following exception:

Traceback (most recent call last):
  File "/home/airflow/.local/lib/python3.7/site-packages/airflow/operators/python.py", line 171, in execute
    return_value = self.execute_callable()
  File "/home/airflow/.local/lib/python3.7/site-packages/airflow/operators/python.py", line 189, in execute_callable
    return self.python_callable(*self.op_args, **self.op_kwargs)
  File "/opt/airflow/dags/get_data.py", line 46, in create_dim_province
    df.to_sql('dim_province', engine_postgres, index=False, if_exists='replace')
  File "/home/airflow/.local/lib/python3.7/site-packages/pandas/core/generic.py", line 2882, in to_sql
    method=method,
  File "/home/airflow/.local/lib/python3.7/site-packages/pandas/io/sql.py", line 728, in to_sql
    **engine_kwargs,
  File "/home/airflow/.local/lib/python3.7/site-packages/pandas/io/sql.py", line 1770, in to_sql
    **engine_kwargs,
  File "/home/airflow/.local/lib/python3.7/site-packages/pandas/io/sql.py", line 1350, in insert_records
    raise err
  File "/home/airflow/.local/lib/python3.7/site-packages/pandas/io/sql.py", line 1340, in insert_records
    table.insert(chunksize=chunksize, method=method)
  File "/home/airflow/.local/lib/python3.7/site-packages/pandas/io/sql.py", line 967, in insert
    exec_insert(conn, keys, chunk_iter)
  File "/home/airflow/.local/lib/python3.7/site-packages/pandas/io/sql.py", line 882, in _execute_insert
    conn.execute(self.table.insert(), data)
  File "/home/airflow/.local/lib/python3.7/site-packages/sqlalchemy/engine/base.py", line 1200, in execute
    return meth(self, multiparams, params, _EMPTY_EXECUTION_OPTS)
  File "/home/airflow/.local/lib/python3.7/site-packages/sqlalchemy/sql/elements.py", line 314, in _execute_on_connection
    self, multiparams, params, execution_options
  File "/home/airflow/.local/lib/python3.7/site-packages/sqlalchemy/engine/base.py", line 1399, in _execute_clauseelement
    cache_hit=cache_hit,
  File "/home/airflow/.local/lib/python3.7/site-packages/sqlalchemy/engine/base.py", line 1749, in _execute_context
    e, statement, parameters, cursor, context
  File "/home/airflow/.local/lib/python3.7/site-packages/sqlalchemy/engine/base.py", line 1930, in _handle_dbapi_exception
    sqlalchemy_exception, with_traceback=exc_info[2], from_=e
  File "/home/airflow/.local/lib/python3.7/site-packages/sqlalchemy/util/compat.py", line 211, in raise_
    raise exception
  File "/home/airflow/.local/lib/python3.7/site-packages/sqlalchemy/engine/base.py", line 1706, in _execute_context
    cursor, statement, parameters, context
  File "/home/airflow/.local/lib/python3.7/site-packages/sqlalchemy/engine/default.py", line 716, in do_execute
    cursor.execute(statement, parameters)
sqlalchemy.exc.ProgrammingError: (psycopg2.errors.UndefinedTable) relation "dim_province" does not exist
LINE 1: INSERT INTO dim_province (province_id, province_name) VALUES...
                    ^

[SQL: INSERT INTO dim_province (province_id, province_name) VALUES (%(province_id)s, %(province_name)s)]
[parameters: {'province_id': '32', 'province_name': 'Jawa Barat'}]
(Background on this error at: http://sqlalche.me/e/14/f405)
[2023-11-27 14:12:31,878] {taskinstance.py:1400} INFO - Marking task as UP_FOR_RETRY. dag_id=final_project_data_covid_etl, task_id=create_dim_province, execution_date=20231127T141226, start_date=20231127T141231, end_date=20231127T141231
[2023-11-27 14:12:31,891] {standard_task_runner.py:97} ERROR - Failed to execute job 437 for task create_dim_province ((psycopg2.errors.UndefinedTable) relation "dim_province" does not exist
LINE 1: INSERT INTO dim_province (province_id, province_name) VALUES...
                    ^

[SQL: INSERT INTO dim_province (province_id, province_name) VALUES (%(province_id)s, %(province_name)s)]
[parameters: {'province_id': '32', 'province_name': 'Jawa Barat'}]
(Background on this error at: http://sqlalche.me/e/14/f405); 540)
[2023-11-27 14:12:31,933] {local_task_job.py:156} INFO - Task exited with return code 1
[2023-11-27 14:12:31,975] {local_task_job.py:273} INFO - 0 downstream tasks scheduled from follow-on schedule check
