[2023-11-27 07:13:20,092] {taskinstance.py:1159} INFO - Dependencies all met for <TaskInstance: final_project_data_covid_etl.insert_data_staging scheduled__2023-11-26T00:00:00+00:00 [queued]>
[2023-11-27 07:13:20,108] {taskinstance.py:1159} INFO - Dependencies all met for <TaskInstance: final_project_data_covid_etl.insert_data_staging scheduled__2023-11-26T00:00:00+00:00 [queued]>
[2023-11-27 07:13:20,108] {taskinstance.py:1356} INFO - 
--------------------------------------------------------------------------------
[2023-11-27 07:13:20,108] {taskinstance.py:1357} INFO - Starting attempt 1 of 3
[2023-11-27 07:13:20,108] {taskinstance.py:1358} INFO - 
--------------------------------------------------------------------------------
[2023-11-27 07:13:20,141] {taskinstance.py:1377} INFO - Executing <Task(PythonOperator): insert_data_staging> on 2023-11-26 00:00:00+00:00
[2023-11-27 07:13:20,146] {standard_task_runner.py:52} INFO - Started process 204 to run task
[2023-11-27 07:13:20,149] {standard_task_runner.py:79} INFO - Running: ['***', 'tasks', 'run', 'final_project_data_covid_etl', 'insert_data_staging', 'scheduled__2023-11-26T00:00:00+00:00', '--job-id', '330', '--raw', '--subdir', 'DAGS_FOLDER/get_data.py', '--cfg-path', '/tmp/tmpet5k0ps0', '--error-file', '/tmp/tmplbfxrrjg']
[2023-11-27 07:13:20,149] {standard_task_runner.py:80} INFO - Job 330: Subtask insert_data_staging
[2023-11-27 07:13:20,205] {task_command.py:369} INFO - Running <TaskInstance: final_project_data_covid_etl.insert_data_staging scheduled__2023-11-26T00:00:00+00:00 [running]> on host 671693f20ed3
[2023-11-27 07:13:20,279] {taskinstance.py:1571} INFO - Exporting the following env vars:
AIRFLOW_CTX_DAG_OWNER=ricky
AIRFLOW_CTX_DAG_ID=final_project_data_covid_etl
AIRFLOW_CTX_TASK_ID=insert_data_staging
AIRFLOW_CTX_EXECUTION_DATE=2023-11-26T00:00:00+00:00
AIRFLOW_CTX_TRY_NUMBER=1
AIRFLOW_CTX_DAG_RUN_ID=scheduled__2023-11-26T00:00:00+00:00
[2023-11-27 07:13:20,638] {python.py:173} INFO - Done. Returned value was: None
[2023-11-27 07:13:20,653] {taskinstance.py:1400} INFO - Marking task as SUCCESS. dag_id=final_project_data_covid_etl, task_id=insert_data_staging, execution_date=20231126T000000, start_date=20231127T071320, end_date=20231127T071320
[2023-11-27 07:13:20,682] {local_task_job.py:156} INFO - Task exited with return code 0
[2023-11-27 07:13:20,734] {local_task_job.py:273} INFO - 1 downstream tasks scheduled from follow-on schedule check
[2023-11-27 07:14:53,841] {taskinstance.py:1159} INFO - Dependencies all met for <TaskInstance: final_project_data_covid_etl.insert_data_staging scheduled__2023-11-26T00:00:00+00:00 [queued]>
[2023-11-27 07:14:53,851] {taskinstance.py:1159} INFO - Dependencies all met for <TaskInstance: final_project_data_covid_etl.insert_data_staging scheduled__2023-11-26T00:00:00+00:00 [queued]>
[2023-11-27 07:14:53,852] {taskinstance.py:1356} INFO - 
--------------------------------------------------------------------------------
[2023-11-27 07:14:53,852] {taskinstance.py:1357} INFO - Starting attempt 1 of 3
[2023-11-27 07:14:53,852] {taskinstance.py:1358} INFO - 
--------------------------------------------------------------------------------
[2023-11-27 07:14:53,865] {taskinstance.py:1377} INFO - Executing <Task(PythonOperator): insert_data_staging> on 2023-11-26 00:00:00+00:00
[2023-11-27 07:14:53,869] {standard_task_runner.py:52} INFO - Started process 219 to run task
[2023-11-27 07:14:53,871] {standard_task_runner.py:79} INFO - Running: ['***', 'tasks', 'run', 'final_project_data_covid_etl', 'insert_data_staging', 'scheduled__2023-11-26T00:00:00+00:00', '--job-id', '345', '--raw', '--subdir', 'DAGS_FOLDER/get_data.py', '--cfg-path', '/tmp/tmpmpec2zyl', '--error-file', '/tmp/tmpu_7j55oq']
[2023-11-27 07:14:53,872] {standard_task_runner.py:80} INFO - Job 345: Subtask insert_data_staging
[2023-11-27 07:14:53,923] {task_command.py:369} INFO - Running <TaskInstance: final_project_data_covid_etl.insert_data_staging scheduled__2023-11-26T00:00:00+00:00 [running]> on host 671693f20ed3
[2023-11-27 07:14:54,011] {taskinstance.py:1571} INFO - Exporting the following env vars:
AIRFLOW_CTX_DAG_OWNER=ricky
AIRFLOW_CTX_DAG_ID=final_project_data_covid_etl
AIRFLOW_CTX_TASK_ID=insert_data_staging
AIRFLOW_CTX_EXECUTION_DATE=2023-11-26T00:00:00+00:00
AIRFLOW_CTX_TRY_NUMBER=1
AIRFLOW_CTX_DAG_RUN_ID=scheduled__2023-11-26T00:00:00+00:00
[2023-11-27 07:14:54,535] {taskinstance.py:1889} ERROR - Task failed with exception
Traceback (most recent call last):
  File "/home/airflow/.local/lib/python3.7/site-packages/sqlalchemy/engine/base.py", line 1706, in _execute_context
    cursor, statement, parameters, context
  File "/home/airflow/.local/lib/python3.7/site-packages/sqlalchemy/engine/default.py", line 716, in do_execute
    cursor.execute(statement, parameters)
  File "/home/airflow/.local/lib/python3.7/site-packages/MySQLdb/cursors.py", line 206, in execute
    res = self._query(query)
  File "/home/airflow/.local/lib/python3.7/site-packages/MySQLdb/cursors.py", line 319, in _query
    db.query(q)
  File "/home/airflow/.local/lib/python3.7/site-packages/MySQLdb/connections.py", line 254, in query
    _mysql.connection.query(self, query)
MySQLdb._exceptions.ProgrammingError: (1146, "Table 'finalproject.covid_jabar' doesn't exist")

The above exception was the direct cause of the following exception:

Traceback (most recent call last):
  File "/home/airflow/.local/lib/python3.7/site-packages/sqlalchemy/dialects/mysql/base.py", line 3373, in _show_create_table
    ).exec_driver_sql(st)
  File "/home/airflow/.local/lib/python3.7/site-packages/sqlalchemy/engine/base.py", line 1580, in exec_driver_sql
    future=True,
  File "/home/airflow/.local/lib/python3.7/site-packages/sqlalchemy/engine/base.py", line 1491, in _exec_driver_sql
    distilled_parameters,
  File "/home/airflow/.local/lib/python3.7/site-packages/sqlalchemy/engine/base.py", line 1749, in _execute_context
    e, statement, parameters, cursor, context
  File "/home/airflow/.local/lib/python3.7/site-packages/sqlalchemy/engine/base.py", line 1930, in _handle_dbapi_exception
    sqlalchemy_exception, with_traceback=exc_info[2], from_=e
  File "/home/airflow/.local/lib/python3.7/site-packages/sqlalchemy/util/compat.py", line 211, in raise_
    raise exception
  File "/home/airflow/.local/lib/python3.7/site-packages/sqlalchemy/engine/base.py", line 1706, in _execute_context
    cursor, statement, parameters, context
  File "/home/airflow/.local/lib/python3.7/site-packages/sqlalchemy/engine/default.py", line 716, in do_execute
    cursor.execute(statement, parameters)
  File "/home/airflow/.local/lib/python3.7/site-packages/MySQLdb/cursors.py", line 206, in execute
    res = self._query(query)
  File "/home/airflow/.local/lib/python3.7/site-packages/MySQLdb/cursors.py", line 319, in _query
    db.query(q)
  File "/home/airflow/.local/lib/python3.7/site-packages/MySQLdb/connections.py", line 254, in query
    _mysql.connection.query(self, query)
sqlalchemy.exc.ProgrammingError: (MySQLdb._exceptions.ProgrammingError) (1146, "Table 'finalproject.covid_jabar' doesn't exist")
[SQL: SHOW CREATE TABLE `covid_jabar`]
(Background on this error at: http://sqlalche.me/e/14/f405)

The above exception was the direct cause of the following exception:

Traceback (most recent call last):
  File "/home/airflow/.local/lib/python3.7/site-packages/airflow/operators/python.py", line 171, in execute
    return_value = self.execute_callable()
  File "/home/airflow/.local/lib/python3.7/site-packages/airflow/operators/python.py", line 189, in execute_callable
    return self.python_callable(*self.op_args, **self.op_kwargs)
  File "/opt/airflow/dags/get_data.py", line 35, in insert_data_staging
    df.to_sql("covid_jabar", staging_db_constring, if_exists="replace", index=False)
  File "/home/airflow/.local/lib/python3.7/site-packages/pandas/core/generic.py", line 2882, in to_sql
    method=method,
  File "/home/airflow/.local/lib/python3.7/site-packages/pandas/io/sql.py", line 728, in to_sql
    **engine_kwargs,
  File "/home/airflow/.local/lib/python3.7/site-packages/pandas/io/sql.py", line 1758, in to_sql
    dtype=dtype,
  File "/home/airflow/.local/lib/python3.7/site-packages/pandas/io/sql.py", line 1650, in prep_table
    table.create()
  File "/home/airflow/.local/lib/python3.7/site-packages/pandas/io/sql.py", line 860, in create
    self.pd_sql.drop_table(self.name, self.schema)
  File "/home/airflow/.local/lib/python3.7/site-packages/pandas/io/sql.py", line 1809, in drop_table
    self.meta.reflect(only=[table_name], schema=schema)
  File "/home/airflow/.local/lib/python3.7/site-packages/sqlalchemy/sql/schema.py", line 4715, in reflect
    Table(name, self, **reflect_opts)
  File "<string>", line 2, in __new__
  File "/home/airflow/.local/lib/python3.7/site-packages/sqlalchemy/util/deprecations.py", line 298, in warned
    return fn(*args, **kwargs)
  File "/home/airflow/.local/lib/python3.7/site-packages/sqlalchemy/sql/schema.py", line 600, in __new__
    metadata._remove_table(name, schema)
  File "/home/airflow/.local/lib/python3.7/site-packages/sqlalchemy/util/langhelpers.py", line 72, in __exit__
    with_traceback=exc_tb,
  File "/home/airflow/.local/lib/python3.7/site-packages/sqlalchemy/util/compat.py", line 211, in raise_
    raise exception
  File "/home/airflow/.local/lib/python3.7/site-packages/sqlalchemy/sql/schema.py", line 595, in __new__
    table._init(name, metadata, *args, **kw)
  File "/home/airflow/.local/lib/python3.7/site-packages/sqlalchemy/sql/schema.py", line 675, in _init
    resolve_fks=resolve_fks,
  File "/home/airflow/.local/lib/python3.7/site-packages/sqlalchemy/sql/schema.py", line 710, in _autoload
    _extend_on=_extend_on,
  File "/home/airflow/.local/lib/python3.7/site-packages/sqlalchemy/engine/reflection.py", line 758, in reflect_table
    table_name, schema, **table.dialect_kwargs
  File "/home/airflow/.local/lib/python3.7/site-packages/sqlalchemy/engine/reflection.py", line 399, in get_table_options
    conn, table_name, schema, info_cache=self.info_cache, **kw
  File "<string>", line 2, in get_table_options
  File "/home/airflow/.local/lib/python3.7/site-packages/sqlalchemy/engine/reflection.py", line 55, in cache
    ret = fn(self, con, *args, **kw)
  File "/home/airflow/.local/lib/python3.7/site-packages/sqlalchemy/dialects/mysql/base.py", line 2997, in get_table_options
    connection, table_name, schema, **kw
  File "/home/airflow/.local/lib/python3.7/site-packages/sqlalchemy/dialects/mysql/base.py", line 3249, in _parsed_state_or_create
    info_cache=kw.get("info_cache", None),
  File "<string>", line 2, in _setup_parser
  File "/home/airflow/.local/lib/python3.7/site-packages/sqlalchemy/engine/reflection.py", line 55, in cache
    ret = fn(self, con, *args, **kw)
  File "/home/airflow/.local/lib/python3.7/site-packages/sqlalchemy/dialects/mysql/base.py", line 3273, in _setup_parser
    connection, None, charset, full_name=full_name
  File "/home/airflow/.local/lib/python3.7/site-packages/sqlalchemy/dialects/mysql/base.py", line 3376, in _show_create_table
    util.raise_(exc.NoSuchTableError(full_name), replace_context=e)
  File "/home/airflow/.local/lib/python3.7/site-packages/sqlalchemy/util/compat.py", line 211, in raise_
    raise exception
sqlalchemy.exc.NoSuchTableError: `covid_jabar`
[2023-11-27 07:14:54,548] {taskinstance.py:1400} INFO - Marking task as UP_FOR_RETRY. dag_id=final_project_data_covid_etl, task_id=insert_data_staging, execution_date=20231126T000000, start_date=20231127T071453, end_date=20231127T071454
[2023-11-27 07:14:54,565] {standard_task_runner.py:97} ERROR - Failed to execute job 345 for task insert_data_staging (`covid_jabar`; 219)
[2023-11-27 07:14:54,610] {local_task_job.py:156} INFO - Task exited with return code 1
[2023-11-27 07:14:54,652] {local_task_job.py:273} INFO - 0 downstream tasks scheduled from follow-on schedule check
[2023-11-27 09:13:51,192] {taskinstance.py:1159} INFO - Dependencies all met for <TaskInstance: final_project_data_covid_etl.insert_data_staging scheduled__2023-11-26T00:00:00+00:00 [queued]>
[2023-11-27 09:13:51,201] {taskinstance.py:1159} INFO - Dependencies all met for <TaskInstance: final_project_data_covid_etl.insert_data_staging scheduled__2023-11-26T00:00:00+00:00 [queued]>
[2023-11-27 09:13:51,201] {taskinstance.py:1356} INFO - 
--------------------------------------------------------------------------------
[2023-11-27 09:13:51,201] {taskinstance.py:1357} INFO - Starting attempt 1 of 3
[2023-11-27 09:13:51,201] {taskinstance.py:1358} INFO - 
--------------------------------------------------------------------------------
[2023-11-27 09:13:51,215] {taskinstance.py:1377} INFO - Executing <Task(PythonOperator): insert_data_staging> on 2023-11-26 00:00:00+00:00
[2023-11-27 09:13:51,219] {standard_task_runner.py:52} INFO - Started process 246 to run task
[2023-11-27 09:13:51,221] {standard_task_runner.py:79} INFO - Running: ['***', 'tasks', 'run', 'final_project_data_covid_etl', 'insert_data_staging', 'scheduled__2023-11-26T00:00:00+00:00', '--job-id', '360', '--raw', '--subdir', 'DAGS_FOLDER/get_data.py', '--cfg-path', '/tmp/tmpf12nsycd', '--error-file', '/tmp/tmprg635yk6']
[2023-11-27 09:13:51,221] {standard_task_runner.py:80} INFO - Job 360: Subtask insert_data_staging
[2023-11-27 09:13:51,264] {task_command.py:369} INFO - Running <TaskInstance: final_project_data_covid_etl.insert_data_staging scheduled__2023-11-26T00:00:00+00:00 [running]> on host f38c0c12695c
[2023-11-27 09:13:51,330] {taskinstance.py:1571} INFO - Exporting the following env vars:
AIRFLOW_CTX_DAG_OWNER=ricky
AIRFLOW_CTX_DAG_ID=final_project_data_covid_etl
AIRFLOW_CTX_TASK_ID=insert_data_staging
AIRFLOW_CTX_EXECUTION_DATE=2023-11-26T00:00:00+00:00
AIRFLOW_CTX_TRY_NUMBER=1
AIRFLOW_CTX_DAG_RUN_ID=scheduled__2023-11-26T00:00:00+00:00
[2023-11-27 09:13:52,297] {taskinstance.py:1889} ERROR - Task failed with exception
Traceback (most recent call last):
  File "/home/airflow/.local/lib/python3.7/site-packages/sqlalchemy/engine/base.py", line 1706, in _execute_context
    cursor, statement, parameters, context
  File "/home/airflow/.local/lib/python3.7/site-packages/sqlalchemy/engine/default.py", line 716, in do_execute
    cursor.execute(statement, parameters)
  File "/home/airflow/.local/lib/python3.7/site-packages/MySQLdb/cursors.py", line 206, in execute
    res = self._query(query)
  File "/home/airflow/.local/lib/python3.7/site-packages/MySQLdb/cursors.py", line 319, in _query
    db.query(q)
  File "/home/airflow/.local/lib/python3.7/site-packages/MySQLdb/connections.py", line 254, in query
    _mysql.connection.query(self, query)
MySQLdb._exceptions.OperationalError: (1051, "Unknown table 'finalproject.covid_jabar'")

The above exception was the direct cause of the following exception:

Traceback (most recent call last):
  File "/home/airflow/.local/lib/python3.7/site-packages/airflow/operators/python.py", line 171, in execute
    return_value = self.execute_callable()
  File "/home/airflow/.local/lib/python3.7/site-packages/airflow/operators/python.py", line 189, in execute_callable
    return self.python_callable(*self.op_args, **self.op_kwargs)
  File "/opt/airflow/dags/get_data.py", line 35, in insert_data_staging
    df.to_sql("covid_jabar", staging_db_constring, if_exists="replace", index=False)
  File "/home/airflow/.local/lib/python3.7/site-packages/pandas/core/generic.py", line 2882, in to_sql
    method=method,
  File "/home/airflow/.local/lib/python3.7/site-packages/pandas/io/sql.py", line 728, in to_sql
    **engine_kwargs,
  File "/home/airflow/.local/lib/python3.7/site-packages/pandas/io/sql.py", line 1758, in to_sql
    dtype=dtype,
  File "/home/airflow/.local/lib/python3.7/site-packages/pandas/io/sql.py", line 1650, in prep_table
    table.create()
  File "/home/airflow/.local/lib/python3.7/site-packages/pandas/io/sql.py", line 860, in create
    self.pd_sql.drop_table(self.name, self.schema)
  File "/home/airflow/.local/lib/python3.7/site-packages/pandas/io/sql.py", line 1810, in drop_table
    self.get_table(table_name, schema).drop()
  File "/home/airflow/.local/lib/python3.7/site-packages/sqlalchemy/sql/schema.py", line 960, in drop
    bind._run_ddl_visitor(ddl.SchemaDropper, self, checkfirst=checkfirst)
  File "/home/airflow/.local/lib/python3.7/site-packages/sqlalchemy/engine/base.py", line 3008, in _run_ddl_visitor
    conn._run_ddl_visitor(visitorcallable, element, **kwargs)
  File "/home/airflow/.local/lib/python3.7/site-packages/sqlalchemy/engine/base.py", line 2016, in _run_ddl_visitor
    visitorcallable(self.dialect, self, **kwargs).traverse_single(element)
  File "/home/airflow/.local/lib/python3.7/site-packages/sqlalchemy/sql/visitors.py", line 483, in traverse_single
    return meth(obj, **kw)
  File "/home/airflow/.local/lib/python3.7/site-packages/sqlalchemy/sql/ddl.py", line 1097, in visit_table
    self.connection.execute(DropTable(table))
  File "/home/airflow/.local/lib/python3.7/site-packages/sqlalchemy/engine/base.py", line 1200, in execute
    return meth(self, multiparams, params, _EMPTY_EXECUTION_OPTS)
  File "/home/airflow/.local/lib/python3.7/site-packages/sqlalchemy/sql/ddl.py", line 78, in _execute_on_connection
    self, multiparams, params, execution_options
  File "/home/airflow/.local/lib/python3.7/site-packages/sqlalchemy/engine/base.py", line 1296, in _execute_ddl
    compiled,
  File "/home/airflow/.local/lib/python3.7/site-packages/sqlalchemy/engine/base.py", line 1749, in _execute_context
    e, statement, parameters, cursor, context
  File "/home/airflow/.local/lib/python3.7/site-packages/sqlalchemy/engine/base.py", line 1930, in _handle_dbapi_exception
    sqlalchemy_exception, with_traceback=exc_info[2], from_=e
  File "/home/airflow/.local/lib/python3.7/site-packages/sqlalchemy/util/compat.py", line 211, in raise_
    raise exception
  File "/home/airflow/.local/lib/python3.7/site-packages/sqlalchemy/engine/base.py", line 1706, in _execute_context
    cursor, statement, parameters, context
  File "/home/airflow/.local/lib/python3.7/site-packages/sqlalchemy/engine/default.py", line 716, in do_execute
    cursor.execute(statement, parameters)
  File "/home/airflow/.local/lib/python3.7/site-packages/MySQLdb/cursors.py", line 206, in execute
    res = self._query(query)
  File "/home/airflow/.local/lib/python3.7/site-packages/MySQLdb/cursors.py", line 319, in _query
    db.query(q)
  File "/home/airflow/.local/lib/python3.7/site-packages/MySQLdb/connections.py", line 254, in query
    _mysql.connection.query(self, query)
sqlalchemy.exc.OperationalError: (MySQLdb._exceptions.OperationalError) (1051, "Unknown table 'finalproject.covid_jabar'")
[SQL: 
DROP TABLE covid_jabar]
(Background on this error at: http://sqlalche.me/e/14/e3q8)
[2023-11-27 09:13:52,311] {taskinstance.py:1400} INFO - Marking task as UP_FOR_RETRY. dag_id=final_project_data_covid_etl, task_id=insert_data_staging, execution_date=20231126T000000, start_date=20231127T091351, end_date=20231127T091352
[2023-11-27 09:13:52,332] {standard_task_runner.py:97} ERROR - Failed to execute job 360 for task insert_data_staging ((MySQLdb._exceptions.OperationalError) (1051, "Unknown table 'finalproject.covid_jabar'")
[SQL: 
DROP TABLE covid_jabar]
(Background on this error at: http://sqlalche.me/e/14/e3q8); 246)
[2023-11-27 09:13:52,363] {local_task_job.py:156} INFO - Task exited with return code 1
[2023-11-27 09:13:52,437] {local_task_job.py:273} INFO - 0 downstream tasks scheduled from follow-on schedule check
[2023-11-27 09:22:20,892] {taskinstance.py:1159} INFO - Dependencies all met for <TaskInstance: final_project_data_covid_etl.insert_data_staging scheduled__2023-11-26T00:00:00+00:00 [queued]>
[2023-11-27 09:22:20,907] {taskinstance.py:1159} INFO - Dependencies all met for <TaskInstance: final_project_data_covid_etl.insert_data_staging scheduled__2023-11-26T00:00:00+00:00 [queued]>
[2023-11-27 09:22:20,907] {taskinstance.py:1356} INFO - 
--------------------------------------------------------------------------------
[2023-11-27 09:22:20,908] {taskinstance.py:1357} INFO - Starting attempt 1 of 3
[2023-11-27 09:22:20,908] {taskinstance.py:1358} INFO - 
--------------------------------------------------------------------------------
[2023-11-27 09:22:20,934] {taskinstance.py:1377} INFO - Executing <Task(PythonOperator): insert_data_staging> on 2023-11-26 00:00:00+00:00
[2023-11-27 09:22:20,941] {standard_task_runner.py:52} INFO - Started process 501 to run task
[2023-11-27 09:22:20,943] {standard_task_runner.py:79} INFO - Running: ['***', 'tasks', 'run', 'final_project_data_covid_etl', 'insert_data_staging', 'scheduled__2023-11-26T00:00:00+00:00', '--job-id', '377', '--raw', '--subdir', 'DAGS_FOLDER/get_data.py', '--cfg-path', '/tmp/tmpc_lnddxv', '--error-file', '/tmp/tmpan99xauz']
[2023-11-27 09:22:20,944] {standard_task_runner.py:80} INFO - Job 377: Subtask insert_data_staging
[2023-11-27 09:22:21,005] {task_command.py:369} INFO - Running <TaskInstance: final_project_data_covid_etl.insert_data_staging scheduled__2023-11-26T00:00:00+00:00 [running]> on host f38c0c12695c
[2023-11-27 09:22:21,082] {taskinstance.py:1571} INFO - Exporting the following env vars:
AIRFLOW_CTX_DAG_OWNER=ricky
AIRFLOW_CTX_DAG_ID=final_project_data_covid_etl
AIRFLOW_CTX_TASK_ID=insert_data_staging
AIRFLOW_CTX_EXECUTION_DATE=2023-11-26T00:00:00+00:00
AIRFLOW_CTX_TRY_NUMBER=1
AIRFLOW_CTX_DAG_RUN_ID=scheduled__2023-11-26T00:00:00+00:00
[2023-11-27 09:22:21,842] {taskinstance.py:1889} ERROR - Task failed with exception
Traceback (most recent call last):
  File "/home/airflow/.local/lib/python3.7/site-packages/sqlalchemy/engine/base.py", line 1706, in _execute_context
    cursor, statement, parameters, context
  File "/home/airflow/.local/lib/python3.7/site-packages/sqlalchemy/engine/default.py", line 716, in do_execute
    cursor.execute(statement, parameters)
  File "/home/airflow/.local/lib/python3.7/site-packages/MySQLdb/cursors.py", line 206, in execute
    res = self._query(query)
  File "/home/airflow/.local/lib/python3.7/site-packages/MySQLdb/cursors.py", line 319, in _query
    db.query(q)
  File "/home/airflow/.local/lib/python3.7/site-packages/MySQLdb/connections.py", line 254, in query
    _mysql.connection.query(self, query)
MySQLdb._exceptions.ProgrammingError: (1146, "Table 'finalproject.covid_jabar' doesn't exist")

The above exception was the direct cause of the following exception:

Traceback (most recent call last):
  File "/home/airflow/.local/lib/python3.7/site-packages/sqlalchemy/dialects/mysql/base.py", line 3373, in _show_create_table
    ).exec_driver_sql(st)
  File "/home/airflow/.local/lib/python3.7/site-packages/sqlalchemy/engine/base.py", line 1580, in exec_driver_sql
    future=True,
  File "/home/airflow/.local/lib/python3.7/site-packages/sqlalchemy/engine/base.py", line 1491, in _exec_driver_sql
    distilled_parameters,
  File "/home/airflow/.local/lib/python3.7/site-packages/sqlalchemy/engine/base.py", line 1749, in _execute_context
    e, statement, parameters, cursor, context
  File "/home/airflow/.local/lib/python3.7/site-packages/sqlalchemy/engine/base.py", line 1930, in _handle_dbapi_exception
    sqlalchemy_exception, with_traceback=exc_info[2], from_=e
  File "/home/airflow/.local/lib/python3.7/site-packages/sqlalchemy/util/compat.py", line 211, in raise_
    raise exception
  File "/home/airflow/.local/lib/python3.7/site-packages/sqlalchemy/engine/base.py", line 1706, in _execute_context
    cursor, statement, parameters, context
  File "/home/airflow/.local/lib/python3.7/site-packages/sqlalchemy/engine/default.py", line 716, in do_execute
    cursor.execute(statement, parameters)
  File "/home/airflow/.local/lib/python3.7/site-packages/MySQLdb/cursors.py", line 206, in execute
    res = self._query(query)
  File "/home/airflow/.local/lib/python3.7/site-packages/MySQLdb/cursors.py", line 319, in _query
    db.query(q)
  File "/home/airflow/.local/lib/python3.7/site-packages/MySQLdb/connections.py", line 254, in query
    _mysql.connection.query(self, query)
sqlalchemy.exc.ProgrammingError: (MySQLdb._exceptions.ProgrammingError) (1146, "Table 'finalproject.covid_jabar' doesn't exist")
[SQL: SHOW CREATE TABLE `covid_jabar`]
(Background on this error at: http://sqlalche.me/e/14/f405)

The above exception was the direct cause of the following exception:

Traceback (most recent call last):
  File "/home/airflow/.local/lib/python3.7/site-packages/airflow/operators/python.py", line 171, in execute
    return_value = self.execute_callable()
  File "/home/airflow/.local/lib/python3.7/site-packages/airflow/operators/python.py", line 189, in execute_callable
    return self.python_callable(*self.op_args, **self.op_kwargs)
  File "/opt/airflow/dags/get_data.py", line 35, in insert_data_staging
    df.to_sql("covid_jabar", staging_db_constring, if_exists="replace", index=False)
  File "/home/airflow/.local/lib/python3.7/site-packages/pandas/core/generic.py", line 2882, in to_sql
    method=method,
  File "/home/airflow/.local/lib/python3.7/site-packages/pandas/io/sql.py", line 728, in to_sql
    **engine_kwargs,
  File "/home/airflow/.local/lib/python3.7/site-packages/pandas/io/sql.py", line 1758, in to_sql
    dtype=dtype,
  File "/home/airflow/.local/lib/python3.7/site-packages/pandas/io/sql.py", line 1650, in prep_table
    table.create()
  File "/home/airflow/.local/lib/python3.7/site-packages/pandas/io/sql.py", line 860, in create
    self.pd_sql.drop_table(self.name, self.schema)
  File "/home/airflow/.local/lib/python3.7/site-packages/pandas/io/sql.py", line 1809, in drop_table
    self.meta.reflect(only=[table_name], schema=schema)
  File "/home/airflow/.local/lib/python3.7/site-packages/sqlalchemy/sql/schema.py", line 4715, in reflect
    Table(name, self, **reflect_opts)
  File "<string>", line 2, in __new__
  File "/home/airflow/.local/lib/python3.7/site-packages/sqlalchemy/util/deprecations.py", line 298, in warned
    return fn(*args, **kwargs)
  File "/home/airflow/.local/lib/python3.7/site-packages/sqlalchemy/sql/schema.py", line 600, in __new__
    metadata._remove_table(name, schema)
  File "/home/airflow/.local/lib/python3.7/site-packages/sqlalchemy/util/langhelpers.py", line 72, in __exit__
    with_traceback=exc_tb,
  File "/home/airflow/.local/lib/python3.7/site-packages/sqlalchemy/util/compat.py", line 211, in raise_
    raise exception
  File "/home/airflow/.local/lib/python3.7/site-packages/sqlalchemy/sql/schema.py", line 595, in __new__
    table._init(name, metadata, *args, **kw)
  File "/home/airflow/.local/lib/python3.7/site-packages/sqlalchemy/sql/schema.py", line 675, in _init
    resolve_fks=resolve_fks,
  File "/home/airflow/.local/lib/python3.7/site-packages/sqlalchemy/sql/schema.py", line 710, in _autoload
    _extend_on=_extend_on,
  File "/home/airflow/.local/lib/python3.7/site-packages/sqlalchemy/engine/reflection.py", line 758, in reflect_table
    table_name, schema, **table.dialect_kwargs
  File "/home/airflow/.local/lib/python3.7/site-packages/sqlalchemy/engine/reflection.py", line 399, in get_table_options
    conn, table_name, schema, info_cache=self.info_cache, **kw
  File "<string>", line 2, in get_table_options
  File "/home/airflow/.local/lib/python3.7/site-packages/sqlalchemy/engine/reflection.py", line 55, in cache
    ret = fn(self, con, *args, **kw)
  File "/home/airflow/.local/lib/python3.7/site-packages/sqlalchemy/dialects/mysql/base.py", line 2997, in get_table_options
    connection, table_name, schema, **kw
  File "/home/airflow/.local/lib/python3.7/site-packages/sqlalchemy/dialects/mysql/base.py", line 3249, in _parsed_state_or_create
    info_cache=kw.get("info_cache", None),
  File "<string>", line 2, in _setup_parser
  File "/home/airflow/.local/lib/python3.7/site-packages/sqlalchemy/engine/reflection.py", line 55, in cache
    ret = fn(self, con, *args, **kw)
  File "/home/airflow/.local/lib/python3.7/site-packages/sqlalchemy/dialects/mysql/base.py", line 3273, in _setup_parser
    connection, None, charset, full_name=full_name
  File "/home/airflow/.local/lib/python3.7/site-packages/sqlalchemy/dialects/mysql/base.py", line 3376, in _show_create_table
    util.raise_(exc.NoSuchTableError(full_name), replace_context=e)
  File "/home/airflow/.local/lib/python3.7/site-packages/sqlalchemy/util/compat.py", line 211, in raise_
    raise exception
sqlalchemy.exc.NoSuchTableError: `covid_jabar`
[2023-11-27 09:22:21,858] {taskinstance.py:1400} INFO - Marking task as UP_FOR_RETRY. dag_id=final_project_data_covid_etl, task_id=insert_data_staging, execution_date=20231126T000000, start_date=20231127T092220, end_date=20231127T092221
[2023-11-27 09:22:21,874] {standard_task_runner.py:97} ERROR - Failed to execute job 377 for task insert_data_staging (`covid_jabar`; 501)
[2023-11-27 09:22:21,921] {local_task_job.py:156} INFO - Task exited with return code 1
[2023-11-27 09:22:21,964] {local_task_job.py:273} INFO - 0 downstream tasks scheduled from follow-on schedule check
[2023-11-27 14:12:29,413] {taskinstance.py:1159} INFO - Dependencies all met for <TaskInstance: final_project_data_covid_etl.insert_data_staging scheduled__2023-11-26T00:00:00+00:00 [queued]>
[2023-11-27 14:12:29,429] {taskinstance.py:1159} INFO - Dependencies all met for <TaskInstance: final_project_data_covid_etl.insert_data_staging scheduled__2023-11-26T00:00:00+00:00 [queued]>
[2023-11-27 14:12:29,429] {taskinstance.py:1356} INFO - 
--------------------------------------------------------------------------------
[2023-11-27 14:12:29,430] {taskinstance.py:1357} INFO - Starting attempt 1 of 3
[2023-11-27 14:12:29,430] {taskinstance.py:1358} INFO - 
--------------------------------------------------------------------------------
[2023-11-27 14:12:29,446] {taskinstance.py:1377} INFO - Executing <Task(PythonOperator): insert_data_staging> on 2023-11-26 00:00:00+00:00
[2023-11-27 14:12:29,450] {standard_task_runner.py:52} INFO - Started process 535 to run task
[2023-11-27 14:12:29,453] {standard_task_runner.py:79} INFO - Running: ['***', 'tasks', 'run', 'final_project_data_covid_etl', 'insert_data_staging', 'scheduled__2023-11-26T00:00:00+00:00', '--job-id', '436', '--raw', '--subdir', 'DAGS_FOLDER/get_data.py', '--cfg-path', '/tmp/tmp217a9c4h', '--error-file', '/tmp/tmppj9u3j6j']
[2023-11-27 14:12:29,454] {standard_task_runner.py:80} INFO - Job 436: Subtask insert_data_staging
[2023-11-27 14:12:29,512] {task_command.py:369} INFO - Running <TaskInstance: final_project_data_covid_etl.insert_data_staging scheduled__2023-11-26T00:00:00+00:00 [running]> on host 9bd194bc0dbc
[2023-11-27 14:12:29,581] {taskinstance.py:1571} INFO - Exporting the following env vars:
AIRFLOW_CTX_DAG_OWNER=ricky
AIRFLOW_CTX_DAG_ID=final_project_data_covid_etl
AIRFLOW_CTX_TASK_ID=insert_data_staging
AIRFLOW_CTX_EXECUTION_DATE=2023-11-26T00:00:00+00:00
AIRFLOW_CTX_TRY_NUMBER=1
AIRFLOW_CTX_DAG_RUN_ID=scheduled__2023-11-26T00:00:00+00:00
[2023-11-27 14:12:30,918] {python.py:173} INFO - Done. Returned value was: None
[2023-11-27 14:12:30,931] {taskinstance.py:1400} INFO - Marking task as SUCCESS. dag_id=final_project_data_covid_etl, task_id=insert_data_staging, execution_date=20231126T000000, start_date=20231127T141229, end_date=20231127T141230
[2023-11-27 14:12:30,954] {local_task_job.py:156} INFO - Task exited with return code 0
[2023-11-27 14:12:31,010] {local_task_job.py:273} INFO - 1 downstream tasks scheduled from follow-on schedule check
[2023-11-27 14:23:22,956] {taskinstance.py:1159} INFO - Dependencies all met for <TaskInstance: final_project_data_covid_etl.insert_data_staging scheduled__2023-11-26T00:00:00+00:00 [queued]>
[2023-11-27 14:23:22,965] {taskinstance.py:1159} INFO - Dependencies all met for <TaskInstance: final_project_data_covid_etl.insert_data_staging scheduled__2023-11-26T00:00:00+00:00 [queued]>
[2023-11-27 14:23:22,965] {taskinstance.py:1356} INFO - 
--------------------------------------------------------------------------------
[2023-11-27 14:23:22,965] {taskinstance.py:1357} INFO - Starting attempt 1 of 3
[2023-11-27 14:23:22,965] {taskinstance.py:1358} INFO - 
--------------------------------------------------------------------------------
[2023-11-27 14:23:22,979] {taskinstance.py:1377} INFO - Executing <Task(PythonOperator): insert_data_staging> on 2023-11-26 00:00:00+00:00
[2023-11-27 14:23:22,984] {standard_task_runner.py:52} INFO - Started process 878 to run task
[2023-11-27 14:23:22,987] {standard_task_runner.py:79} INFO - Running: ['***', 'tasks', 'run', 'final_project_data_covid_etl', 'insert_data_staging', 'scheduled__2023-11-26T00:00:00+00:00', '--job-id', '455', '--raw', '--subdir', 'DAGS_FOLDER/get_data.py', '--cfg-path', '/tmp/tmp7hqpasw4', '--error-file', '/tmp/tmph9x3clf8']
[2023-11-27 14:23:22,987] {standard_task_runner.py:80} INFO - Job 455: Subtask insert_data_staging
[2023-11-27 14:23:23,039] {task_command.py:369} INFO - Running <TaskInstance: final_project_data_covid_etl.insert_data_staging scheduled__2023-11-26T00:00:00+00:00 [running]> on host 9bd194bc0dbc
[2023-11-27 14:23:23,103] {taskinstance.py:1571} INFO - Exporting the following env vars:
AIRFLOW_CTX_DAG_OWNER=ricky
AIRFLOW_CTX_DAG_ID=final_project_data_covid_etl
AIRFLOW_CTX_TASK_ID=insert_data_staging
AIRFLOW_CTX_EXECUTION_DATE=2023-11-26T00:00:00+00:00
AIRFLOW_CTX_TRY_NUMBER=1
AIRFLOW_CTX_DAG_RUN_ID=scheduled__2023-11-26T00:00:00+00:00
[2023-11-27 14:23:24,210] {python.py:173} INFO - Done. Returned value was: None
[2023-11-27 14:23:24,224] {taskinstance.py:1400} INFO - Marking task as SUCCESS. dag_id=final_project_data_covid_etl, task_id=insert_data_staging, execution_date=20231126T000000, start_date=20231127T142322, end_date=20231127T142324
[2023-11-27 14:23:24,245] {local_task_job.py:156} INFO - Task exited with return code 0
[2023-11-27 14:23:24,303] {local_task_job.py:273} INFO - 1 downstream tasks scheduled from follow-on schedule check
