[2023-11-26 14:26:17,509] {taskinstance.py:1159} INFO - Dependencies all met for <TaskInstance: data_covid_etl.ingest_staging_db scheduled__2023-11-22T00:00:00+00:00 [queued]>
[2023-11-26 14:26:17,528] {taskinstance.py:1159} INFO - Dependencies all met for <TaskInstance: data_covid_etl.ingest_staging_db scheduled__2023-11-22T00:00:00+00:00 [queued]>
[2023-11-26 14:26:17,528] {taskinstance.py:1356} INFO - 
--------------------------------------------------------------------------------
[2023-11-26 14:26:17,528] {taskinstance.py:1357} INFO - Starting attempt 1 of 6
[2023-11-26 14:26:17,528] {taskinstance.py:1358} INFO - 
--------------------------------------------------------------------------------
[2023-11-26 14:26:17,565] {taskinstance.py:1377} INFO - Executing <Task(PythonOperator): ingest_staging_db> on 2023-11-22 00:00:00+00:00
[2023-11-26 14:26:17,569] {standard_task_runner.py:52} INFO - Started process 677 to run task
[2023-11-26 14:26:17,574] {standard_task_runner.py:79} INFO - Running: ['***', 'tasks', 'run', 'data_covid_etl', 'ingest_staging_db', 'scheduled__2023-11-22T00:00:00+00:00', '--job-id', '17', '--raw', '--subdir', 'DAGS_FOLDER/get_data.py', '--cfg-path', '/tmp/tmp_ylonghx', '--error-file', '/tmp/tmpxabv10_0']
[2023-11-26 14:26:17,574] {standard_task_runner.py:80} INFO - Job 17: Subtask ingest_staging_db
[2023-11-26 14:26:17,706] {task_command.py:369} INFO - Running <TaskInstance: data_covid_etl.ingest_staging_db scheduled__2023-11-22T00:00:00+00:00 [running]> on host f384f2afcc4f
[2023-11-26 14:26:17,840] {taskinstance.py:1571} INFO - Exporting the following env vars:
AIRFLOW_CTX_DAG_OWNER=oce
AIRFLOW_CTX_DAG_ID=data_covid_etl
AIRFLOW_CTX_TASK_ID=ingest_staging_db
AIRFLOW_CTX_EXECUTION_DATE=2023-11-22T00:00:00+00:00
AIRFLOW_CTX_TRY_NUMBER=1
AIRFLOW_CTX_DAG_RUN_ID=scheduled__2023-11-22T00:00:00+00:00
[2023-11-26 14:26:18,765] {taskinstance.py:1889} ERROR - Task failed with exception
Traceback (most recent call last):
  File "/home/airflow/.local/lib/python3.7/site-packages/sqlalchemy/engine/base.py", line 1706, in _execute_context
    cursor, statement, parameters, context
  File "/home/airflow/.local/lib/python3.7/site-packages/sqlalchemy/engine/default.py", line 716, in do_execute
    cursor.execute(statement, parameters)
  File "/home/airflow/.local/lib/python3.7/site-packages/MySQLdb/cursors.py", line 206, in execute
    res = self._query(query)
  File "/home/airflow/.local/lib/python3.7/site-packages/MySQLdb/cursors.py", line 319, in _query
    db.query(q)
  File "/home/airflow/.local/lib/python3.7/site-packages/MySQLdb/connections.py", line 254, in query
    _mysql.connection.query(self, query)
MySQLdb._exceptions.OperationalError: (1051, "Unknown table 'finalproject.covid_jabar'")

The above exception was the direct cause of the following exception:

Traceback (most recent call last):
  File "/home/airflow/.local/lib/python3.7/site-packages/airflow/operators/python.py", line 171, in execute
    return_value = self.execute_callable()
  File "/home/airflow/.local/lib/python3.7/site-packages/airflow/operators/python.py", line 189, in execute_callable
    return self.python_callable(*self.op_args, **self.op_kwargs)
  File "/opt/airflow/dags/get_data.py", line 36, in ingest_data_staging
    df.to_sql("covid_jabar", staging_db_constring, if_exists="replace", index=False)
  File "/home/airflow/.local/lib/python3.7/site-packages/pandas/core/generic.py", line 2882, in to_sql
    method=method,
  File "/home/airflow/.local/lib/python3.7/site-packages/pandas/io/sql.py", line 728, in to_sql
    **engine_kwargs,
  File "/home/airflow/.local/lib/python3.7/site-packages/pandas/io/sql.py", line 1758, in to_sql
    dtype=dtype,
  File "/home/airflow/.local/lib/python3.7/site-packages/pandas/io/sql.py", line 1650, in prep_table
    table.create()
  File "/home/airflow/.local/lib/python3.7/site-packages/pandas/io/sql.py", line 860, in create
    self.pd_sql.drop_table(self.name, self.schema)
  File "/home/airflow/.local/lib/python3.7/site-packages/pandas/io/sql.py", line 1810, in drop_table
    self.get_table(table_name, schema).drop()
  File "/home/airflow/.local/lib/python3.7/site-packages/sqlalchemy/sql/schema.py", line 960, in drop
    bind._run_ddl_visitor(ddl.SchemaDropper, self, checkfirst=checkfirst)
  File "/home/airflow/.local/lib/python3.7/site-packages/sqlalchemy/engine/base.py", line 3008, in _run_ddl_visitor
    conn._run_ddl_visitor(visitorcallable, element, **kwargs)
  File "/home/airflow/.local/lib/python3.7/site-packages/sqlalchemy/engine/base.py", line 2016, in _run_ddl_visitor
    visitorcallable(self.dialect, self, **kwargs).traverse_single(element)
  File "/home/airflow/.local/lib/python3.7/site-packages/sqlalchemy/sql/visitors.py", line 483, in traverse_single
    return meth(obj, **kw)
  File "/home/airflow/.local/lib/python3.7/site-packages/sqlalchemy/sql/ddl.py", line 1097, in visit_table
    self.connection.execute(DropTable(table))
  File "/home/airflow/.local/lib/python3.7/site-packages/sqlalchemy/engine/base.py", line 1200, in execute
    return meth(self, multiparams, params, _EMPTY_EXECUTION_OPTS)
  File "/home/airflow/.local/lib/python3.7/site-packages/sqlalchemy/sql/ddl.py", line 78, in _execute_on_connection
    self, multiparams, params, execution_options
  File "/home/airflow/.local/lib/python3.7/site-packages/sqlalchemy/engine/base.py", line 1296, in _execute_ddl
    compiled,
  File "/home/airflow/.local/lib/python3.7/site-packages/sqlalchemy/engine/base.py", line 1749, in _execute_context
    e, statement, parameters, cursor, context
  File "/home/airflow/.local/lib/python3.7/site-packages/sqlalchemy/engine/base.py", line 1930, in _handle_dbapi_exception
    sqlalchemy_exception, with_traceback=exc_info[2], from_=e
  File "/home/airflow/.local/lib/python3.7/site-packages/sqlalchemy/util/compat.py", line 211, in raise_
    raise exception
  File "/home/airflow/.local/lib/python3.7/site-packages/sqlalchemy/engine/base.py", line 1706, in _execute_context
    cursor, statement, parameters, context
  File "/home/airflow/.local/lib/python3.7/site-packages/sqlalchemy/engine/default.py", line 716, in do_execute
    cursor.execute(statement, parameters)
  File "/home/airflow/.local/lib/python3.7/site-packages/MySQLdb/cursors.py", line 206, in execute
    res = self._query(query)
  File "/home/airflow/.local/lib/python3.7/site-packages/MySQLdb/cursors.py", line 319, in _query
    db.query(q)
  File "/home/airflow/.local/lib/python3.7/site-packages/MySQLdb/connections.py", line 254, in query
    _mysql.connection.query(self, query)
sqlalchemy.exc.OperationalError: (MySQLdb._exceptions.OperationalError) (1051, "Unknown table 'finalproject.covid_jabar'")
[SQL: 
DROP TABLE covid_jabar]
(Background on this error at: http://sqlalche.me/e/14/e3q8)
[2023-11-26 14:26:18,789] {taskinstance.py:1400} INFO - Marking task as UP_FOR_RETRY. dag_id=data_covid_etl, task_id=ingest_staging_db, execution_date=20231122T000000, start_date=20231126T142617, end_date=20231126T142618
[2023-11-26 14:26:18,825] {standard_task_runner.py:97} ERROR - Failed to execute job 17 for task ingest_staging_db ((MySQLdb._exceptions.OperationalError) (1051, "Unknown table 'finalproject.covid_jabar'")
[SQL: 
DROP TABLE covid_jabar]
(Background on this error at: http://sqlalche.me/e/14/e3q8); 677)
[2023-11-26 14:26:18,837] {local_task_job.py:156} INFO - Task exited with return code 1
[2023-11-26 14:26:18,876] {local_task_job.py:273} INFO - 0 downstream tasks scheduled from follow-on schedule check
[2023-11-26 15:39:40,159] {taskinstance.py:1159} INFO - Dependencies all met for <TaskInstance: data_covid_etl.ingest_staging_db scheduled__2023-11-22T00:00:00+00:00 [queued]>
[2023-11-26 15:39:40,183] {taskinstance.py:1159} INFO - Dependencies all met for <TaskInstance: data_covid_etl.ingest_staging_db scheduled__2023-11-22T00:00:00+00:00 [queued]>
[2023-11-26 15:39:40,183] {taskinstance.py:1356} INFO - 
--------------------------------------------------------------------------------
[2023-11-26 15:39:40,183] {taskinstance.py:1357} INFO - Starting attempt 1 of 6
[2023-11-26 15:39:40,183] {taskinstance.py:1358} INFO - 
--------------------------------------------------------------------------------
[2023-11-26 15:39:40,218] {taskinstance.py:1377} INFO - Executing <Task(PythonOperator): ingest_staging_db> on 2023-11-22 00:00:00+00:00
[2023-11-26 15:39:40,236] {standard_task_runner.py:52} INFO - Started process 2579 to run task
[2023-11-26 15:39:40,281] {standard_task_runner.py:79} INFO - Running: ['***', 'tasks', 'run', 'data_covid_etl', 'ingest_staging_db', 'scheduled__2023-11-22T00:00:00+00:00', '--job-id', '64', '--raw', '--subdir', 'DAGS_FOLDER/get_data.py', '--cfg-path', '/tmp/tmpldh81vv0', '--error-file', '/tmp/tmpj8x9c5ze']
[2023-11-26 15:39:40,282] {standard_task_runner.py:80} INFO - Job 64: Subtask ingest_staging_db
[2023-11-26 15:39:40,467] {task_command.py:369} INFO - Running <TaskInstance: data_covid_etl.ingest_staging_db scheduled__2023-11-22T00:00:00+00:00 [running]> on host f384f2afcc4f
[2023-11-26 15:39:40,686] {taskinstance.py:1571} INFO - Exporting the following env vars:
AIRFLOW_CTX_DAG_OWNER=oce
AIRFLOW_CTX_DAG_ID=data_covid_etl
AIRFLOW_CTX_TASK_ID=ingest_staging_db
AIRFLOW_CTX_EXECUTION_DATE=2023-11-22T00:00:00+00:00
AIRFLOW_CTX_TRY_NUMBER=1
AIRFLOW_CTX_DAG_RUN_ID=scheduled__2023-11-22T00:00:00+00:00
[2023-11-26 15:39:56,053] {python.py:173} INFO - Done. Returned value was: None
[2023-11-26 15:39:56,069] {taskinstance.py:1400} INFO - Marking task as SUCCESS. dag_id=data_covid_etl, task_id=ingest_staging_db, execution_date=20231122T000000, start_date=20231126T153940, end_date=20231126T153956
[2023-11-26 15:39:56,133] {local_task_job.py:156} INFO - Task exited with return code 0
[2023-11-26 15:39:56,171] {local_task_job.py:273} INFO - 0 downstream tasks scheduled from follow-on schedule check
[2023-11-26 17:57:12,228] {taskinstance.py:1159} INFO - Dependencies all met for <TaskInstance: data_covid_etl.ingest_staging_db scheduled__2023-11-22T00:00:00+00:00 [queued]>
[2023-11-26 17:57:12,252] {taskinstance.py:1159} INFO - Dependencies all met for <TaskInstance: data_covid_etl.ingest_staging_db scheduled__2023-11-22T00:00:00+00:00 [queued]>
[2023-11-26 17:57:12,252] {taskinstance.py:1356} INFO - 
--------------------------------------------------------------------------------
[2023-11-26 17:57:12,252] {taskinstance.py:1357} INFO - Starting attempt 1 of 6
[2023-11-26 17:57:12,252] {taskinstance.py:1358} INFO - 
--------------------------------------------------------------------------------
[2023-11-26 17:57:12,282] {taskinstance.py:1377} INFO - Executing <Task(PythonOperator): ingest_staging_db> on 2023-11-22 00:00:00+00:00
[2023-11-26 17:57:12,304] {standard_task_runner.py:52} INFO - Started process 700 to run task
[2023-11-26 17:57:12,323] {standard_task_runner.py:79} INFO - Running: ['***', 'tasks', 'run', 'data_covid_etl', 'ingest_staging_db', 'scheduled__2023-11-22T00:00:00+00:00', '--job-id', '109', '--raw', '--subdir', 'DAGS_FOLDER/get_data.py', '--cfg-path', '/tmp/tmp8ztafyye', '--error-file', '/tmp/tmpb1x1lgoo']
[2023-11-26 17:57:12,333] {standard_task_runner.py:80} INFO - Job 109: Subtask ingest_staging_db
[2023-11-26 17:57:12,485] {task_command.py:369} INFO - Running <TaskInstance: data_covid_etl.ingest_staging_db scheduled__2023-11-22T00:00:00+00:00 [running]> on host 79a606f4be36
[2023-11-26 17:57:12,699] {taskinstance.py:1571} INFO - Exporting the following env vars:
AIRFLOW_CTX_DAG_OWNER=oce
AIRFLOW_CTX_DAG_ID=data_covid_etl
AIRFLOW_CTX_TASK_ID=ingest_staging_db
AIRFLOW_CTX_EXECUTION_DATE=2023-11-22T00:00:00+00:00
AIRFLOW_CTX_TRY_NUMBER=1
AIRFLOW_CTX_DAG_RUN_ID=scheduled__2023-11-22T00:00:00+00:00
[2023-11-26 17:57:13,087] {taskinstance.py:1889} ERROR - Task failed with exception
Traceback (most recent call last):
  File "/home/airflow/.local/lib/python3.7/site-packages/sqlalchemy/engine/base.py", line 1706, in _execute_context
    cursor, statement, parameters, context
  File "/home/airflow/.local/lib/python3.7/site-packages/sqlalchemy/engine/default.py", line 716, in do_execute
    cursor.execute(statement, parameters)
  File "/home/airflow/.local/lib/python3.7/site-packages/MySQLdb/cursors.py", line 206, in execute
    res = self._query(query)
  File "/home/airflow/.local/lib/python3.7/site-packages/MySQLdb/cursors.py", line 319, in _query
    db.query(q)
  File "/home/airflow/.local/lib/python3.7/site-packages/MySQLdb/connections.py", line 254, in query
    _mysql.connection.query(self, query)
MySQLdb._exceptions.ProgrammingError: (1146, "Table 'finalproject.covid_jabar' doesn't exist")

The above exception was the direct cause of the following exception:

Traceback (most recent call last):
  File "/home/airflow/.local/lib/python3.7/site-packages/sqlalchemy/dialects/mysql/base.py", line 3373, in _show_create_table
    ).exec_driver_sql(st)
  File "/home/airflow/.local/lib/python3.7/site-packages/sqlalchemy/engine/base.py", line 1580, in exec_driver_sql
    future=True,
  File "/home/airflow/.local/lib/python3.7/site-packages/sqlalchemy/engine/base.py", line 1491, in _exec_driver_sql
    distilled_parameters,
  File "/home/airflow/.local/lib/python3.7/site-packages/sqlalchemy/engine/base.py", line 1749, in _execute_context
    e, statement, parameters, cursor, context
  File "/home/airflow/.local/lib/python3.7/site-packages/sqlalchemy/engine/base.py", line 1930, in _handle_dbapi_exception
    sqlalchemy_exception, with_traceback=exc_info[2], from_=e
  File "/home/airflow/.local/lib/python3.7/site-packages/sqlalchemy/util/compat.py", line 211, in raise_
    raise exception
  File "/home/airflow/.local/lib/python3.7/site-packages/sqlalchemy/engine/base.py", line 1706, in _execute_context
    cursor, statement, parameters, context
  File "/home/airflow/.local/lib/python3.7/site-packages/sqlalchemy/engine/default.py", line 716, in do_execute
    cursor.execute(statement, parameters)
  File "/home/airflow/.local/lib/python3.7/site-packages/MySQLdb/cursors.py", line 206, in execute
    res = self._query(query)
  File "/home/airflow/.local/lib/python3.7/site-packages/MySQLdb/cursors.py", line 319, in _query
    db.query(q)
  File "/home/airflow/.local/lib/python3.7/site-packages/MySQLdb/connections.py", line 254, in query
    _mysql.connection.query(self, query)
sqlalchemy.exc.ProgrammingError: (MySQLdb._exceptions.ProgrammingError) (1146, "Table 'finalproject.covid_jabar' doesn't exist")
[SQL: SHOW CREATE TABLE `covid_jabar`]
(Background on this error at: http://sqlalche.me/e/14/f405)

The above exception was the direct cause of the following exception:

Traceback (most recent call last):
  File "/home/airflow/.local/lib/python3.7/site-packages/airflow/operators/python.py", line 171, in execute
    return_value = self.execute_callable()
  File "/home/airflow/.local/lib/python3.7/site-packages/airflow/operators/python.py", line 189, in execute_callable
    return self.python_callable(*self.op_args, **self.op_kwargs)
  File "/opt/airflow/dags/get_data.py", line 34, in ingest_data_staging
    df.to_sql("covid_jabar", staging_db_constring, if_exists="replace", index=False)
  File "/home/airflow/.local/lib/python3.7/site-packages/pandas/core/generic.py", line 2882, in to_sql
    method=method,
  File "/home/airflow/.local/lib/python3.7/site-packages/pandas/io/sql.py", line 728, in to_sql
    **engine_kwargs,
  File "/home/airflow/.local/lib/python3.7/site-packages/pandas/io/sql.py", line 1758, in to_sql
    dtype=dtype,
  File "/home/airflow/.local/lib/python3.7/site-packages/pandas/io/sql.py", line 1650, in prep_table
    table.create()
  File "/home/airflow/.local/lib/python3.7/site-packages/pandas/io/sql.py", line 860, in create
    self.pd_sql.drop_table(self.name, self.schema)
  File "/home/airflow/.local/lib/python3.7/site-packages/pandas/io/sql.py", line 1809, in drop_table
    self.meta.reflect(only=[table_name], schema=schema)
  File "/home/airflow/.local/lib/python3.7/site-packages/sqlalchemy/sql/schema.py", line 4715, in reflect
    Table(name, self, **reflect_opts)
  File "<string>", line 2, in __new__
  File "/home/airflow/.local/lib/python3.7/site-packages/sqlalchemy/util/deprecations.py", line 298, in warned
    return fn(*args, **kwargs)
  File "/home/airflow/.local/lib/python3.7/site-packages/sqlalchemy/sql/schema.py", line 600, in __new__
    metadata._remove_table(name, schema)
  File "/home/airflow/.local/lib/python3.7/site-packages/sqlalchemy/util/langhelpers.py", line 72, in __exit__
    with_traceback=exc_tb,
  File "/home/airflow/.local/lib/python3.7/site-packages/sqlalchemy/util/compat.py", line 211, in raise_
    raise exception
  File "/home/airflow/.local/lib/python3.7/site-packages/sqlalchemy/sql/schema.py", line 595, in __new__
    table._init(name, metadata, *args, **kw)
  File "/home/airflow/.local/lib/python3.7/site-packages/sqlalchemy/sql/schema.py", line 675, in _init
    resolve_fks=resolve_fks,
  File "/home/airflow/.local/lib/python3.7/site-packages/sqlalchemy/sql/schema.py", line 710, in _autoload
    _extend_on=_extend_on,
  File "/home/airflow/.local/lib/python3.7/site-packages/sqlalchemy/engine/reflection.py", line 758, in reflect_table
    table_name, schema, **table.dialect_kwargs
  File "/home/airflow/.local/lib/python3.7/site-packages/sqlalchemy/engine/reflection.py", line 399, in get_table_options
    conn, table_name, schema, info_cache=self.info_cache, **kw
  File "<string>", line 2, in get_table_options
  File "/home/airflow/.local/lib/python3.7/site-packages/sqlalchemy/engine/reflection.py", line 55, in cache
    ret = fn(self, con, *args, **kw)
  File "/home/airflow/.local/lib/python3.7/site-packages/sqlalchemy/dialects/mysql/base.py", line 2997, in get_table_options
    connection, table_name, schema, **kw
  File "/home/airflow/.local/lib/python3.7/site-packages/sqlalchemy/dialects/mysql/base.py", line 3249, in _parsed_state_or_create
    info_cache=kw.get("info_cache", None),
  File "<string>", line 2, in _setup_parser
  File "/home/airflow/.local/lib/python3.7/site-packages/sqlalchemy/engine/reflection.py", line 55, in cache
    ret = fn(self, con, *args, **kw)
  File "/home/airflow/.local/lib/python3.7/site-packages/sqlalchemy/dialects/mysql/base.py", line 3273, in _setup_parser
    connection, None, charset, full_name=full_name
  File "/home/airflow/.local/lib/python3.7/site-packages/sqlalchemy/dialects/mysql/base.py", line 3376, in _show_create_table
    util.raise_(exc.NoSuchTableError(full_name), replace_context=e)
  File "/home/airflow/.local/lib/python3.7/site-packages/sqlalchemy/util/compat.py", line 211, in raise_
    raise exception
sqlalchemy.exc.NoSuchTableError: `covid_jabar`
[2023-11-26 17:57:13,113] {taskinstance.py:1400} INFO - Marking task as UP_FOR_RETRY. dag_id=data_covid_etl, task_id=ingest_staging_db, execution_date=20231122T000000, start_date=20231126T175712, end_date=20231126T175713
[2023-11-26 17:57:13,153] {standard_task_runner.py:97} ERROR - Failed to execute job 109 for task ingest_staging_db (`covid_jabar`; 700)
[2023-11-26 17:57:13,217] {local_task_job.py:156} INFO - Task exited with return code 1
[2023-11-26 17:57:13,283] {local_task_job.py:273} INFO - 0 downstream tasks scheduled from follow-on schedule check
[2023-11-26 18:00:54,597] {taskinstance.py:1159} INFO - Dependencies all met for <TaskInstance: data_covid_etl.ingest_staging_db scheduled__2023-11-22T00:00:00+00:00 [queued]>
[2023-11-26 18:00:54,611] {taskinstance.py:1159} INFO - Dependencies all met for <TaskInstance: data_covid_etl.ingest_staging_db scheduled__2023-11-22T00:00:00+00:00 [queued]>
[2023-11-26 18:00:54,611] {taskinstance.py:1356} INFO - 
--------------------------------------------------------------------------------
[2023-11-26 18:00:54,611] {taskinstance.py:1357} INFO - Starting attempt 1 of 6
[2023-11-26 18:00:54,611] {taskinstance.py:1358} INFO - 
--------------------------------------------------------------------------------
[2023-11-26 18:00:54,644] {taskinstance.py:1377} INFO - Executing <Task(PythonOperator): ingest_staging_db> on 2023-11-22 00:00:00+00:00
[2023-11-26 18:00:54,652] {standard_task_runner.py:52} INFO - Started process 920 to run task
[2023-11-26 18:00:54,659] {standard_task_runner.py:79} INFO - Running: ['***', 'tasks', 'run', 'data_covid_etl', 'ingest_staging_db', 'scheduled__2023-11-22T00:00:00+00:00', '--job-id', '157', '--raw', '--subdir', 'DAGS_FOLDER/get_data.py', '--cfg-path', '/tmp/tmphiycgufe', '--error-file', '/tmp/tmpvbk5vqyq']
[2023-11-26 18:00:54,660] {standard_task_runner.py:80} INFO - Job 157: Subtask ingest_staging_db
[2023-11-26 18:00:54,745] {task_command.py:369} INFO - Running <TaskInstance: data_covid_etl.ingest_staging_db scheduled__2023-11-22T00:00:00+00:00 [running]> on host 79a606f4be36
[2023-11-26 18:00:54,818] {taskinstance.py:1571} INFO - Exporting the following env vars:
AIRFLOW_CTX_DAG_OWNER=oce
AIRFLOW_CTX_DAG_ID=data_covid_etl
AIRFLOW_CTX_TASK_ID=ingest_staging_db
AIRFLOW_CTX_EXECUTION_DATE=2023-11-22T00:00:00+00:00
AIRFLOW_CTX_TRY_NUMBER=1
AIRFLOW_CTX_DAG_RUN_ID=scheduled__2023-11-22T00:00:00+00:00
[2023-11-26 18:00:55,330] {taskinstance.py:1889} ERROR - Task failed with exception
Traceback (most recent call last):
  File "/home/airflow/.local/lib/python3.7/site-packages/sqlalchemy/engine/base.py", line 1706, in _execute_context
    cursor, statement, parameters, context
  File "/home/airflow/.local/lib/python3.7/site-packages/sqlalchemy/engine/default.py", line 716, in do_execute
    cursor.execute(statement, parameters)
  File "/home/airflow/.local/lib/python3.7/site-packages/MySQLdb/cursors.py", line 206, in execute
    res = self._query(query)
  File "/home/airflow/.local/lib/python3.7/site-packages/MySQLdb/cursors.py", line 319, in _query
    db.query(q)
  File "/home/airflow/.local/lib/python3.7/site-packages/MySQLdb/connections.py", line 254, in query
    _mysql.connection.query(self, query)
MySQLdb._exceptions.OperationalError: (1050, "Table 'covid_jabar' already exists")

The above exception was the direct cause of the following exception:

Traceback (most recent call last):
  File "/home/airflow/.local/lib/python3.7/site-packages/airflow/operators/python.py", line 171, in execute
    return_value = self.execute_callable()
  File "/home/airflow/.local/lib/python3.7/site-packages/airflow/operators/python.py", line 189, in execute_callable
    return self.python_callable(*self.op_args, **self.op_kwargs)
  File "/opt/airflow/dags/get_data.py", line 35, in ingest_data_staging
    df.to_sql("covid_jabar", staging_db_constring, if_exists="replace", index=False)
  File "/home/airflow/.local/lib/python3.7/site-packages/pandas/core/generic.py", line 2882, in to_sql
    method=method,
  File "/home/airflow/.local/lib/python3.7/site-packages/pandas/io/sql.py", line 728, in to_sql
    **engine_kwargs,
  File "/home/airflow/.local/lib/python3.7/site-packages/pandas/io/sql.py", line 1758, in to_sql
    dtype=dtype,
  File "/home/airflow/.local/lib/python3.7/site-packages/pandas/io/sql.py", line 1650, in prep_table
    table.create()
  File "/home/airflow/.local/lib/python3.7/site-packages/pandas/io/sql.py", line 867, in create
    self._execute_create()
  File "/home/airflow/.local/lib/python3.7/site-packages/pandas/io/sql.py", line 853, in _execute_create
    self.table.create()
  File "/home/airflow/.local/lib/python3.7/site-packages/sqlalchemy/sql/schema.py", line 943, in create
    bind._run_ddl_visitor(ddl.SchemaGenerator, self, checkfirst=checkfirst)
  File "/home/airflow/.local/lib/python3.7/site-packages/sqlalchemy/engine/base.py", line 3008, in _run_ddl_visitor
    conn._run_ddl_visitor(visitorcallable, element, **kwargs)
  File "/home/airflow/.local/lib/python3.7/site-packages/sqlalchemy/engine/base.py", line 2016, in _run_ddl_visitor
    visitorcallable(self.dialect, self, **kwargs).traverse_single(element)
  File "/home/airflow/.local/lib/python3.7/site-packages/sqlalchemy/sql/visitors.py", line 483, in traverse_single
    return meth(obj, **kw)
  File "/home/airflow/.local/lib/python3.7/site-packages/sqlalchemy/sql/ddl.py", line 895, in visit_table
    include_foreign_key_constraints,  # noqa
  File "/home/airflow/.local/lib/python3.7/site-packages/sqlalchemy/engine/base.py", line 1200, in execute
    return meth(self, multiparams, params, _EMPTY_EXECUTION_OPTS)
  File "/home/airflow/.local/lib/python3.7/site-packages/sqlalchemy/sql/ddl.py", line 78, in _execute_on_connection
    self, multiparams, params, execution_options
  File "/home/airflow/.local/lib/python3.7/site-packages/sqlalchemy/engine/base.py", line 1296, in _execute_ddl
    compiled,
  File "/home/airflow/.local/lib/python3.7/site-packages/sqlalchemy/engine/base.py", line 1749, in _execute_context
    e, statement, parameters, cursor, context
  File "/home/airflow/.local/lib/python3.7/site-packages/sqlalchemy/engine/base.py", line 1930, in _handle_dbapi_exception
    sqlalchemy_exception, with_traceback=exc_info[2], from_=e
  File "/home/airflow/.local/lib/python3.7/site-packages/sqlalchemy/util/compat.py", line 211, in raise_
    raise exception
  File "/home/airflow/.local/lib/python3.7/site-packages/sqlalchemy/engine/base.py", line 1706, in _execute_context
    cursor, statement, parameters, context
  File "/home/airflow/.local/lib/python3.7/site-packages/sqlalchemy/engine/default.py", line 716, in do_execute
    cursor.execute(statement, parameters)
  File "/home/airflow/.local/lib/python3.7/site-packages/MySQLdb/cursors.py", line 206, in execute
    res = self._query(query)
  File "/home/airflow/.local/lib/python3.7/site-packages/MySQLdb/cursors.py", line 319, in _query
    db.query(q)
  File "/home/airflow/.local/lib/python3.7/site-packages/MySQLdb/connections.py", line 254, in query
    _mysql.connection.query(self, query)
sqlalchemy.exc.OperationalError: (MySQLdb._exceptions.OperationalError) (1050, "Table 'covid_jabar' already exists")
[SQL: 
CREATE TABLE covid_jabar (
	`CLOSECONTACT` BIGINT, 
	`CONFIRMATION` BIGINT, 
	`PROBABLE` BIGINT, 
	`SUSPECT` BIGINT, 
	closecontact_dikarantina BIGINT, 
	closecontact_discarded BIGINT, 
	closecontact_meninggal BIGINT, 
	confirmation_meninggal BIGINT, 
	confirmation_sembuh BIGINT, 
	kode_kab TEXT, 
	kode_prov TEXT, 
	nama_kab TEXT, 
	nama_prov TEXT, 
	probable_diisolasi BIGINT, 
	probable_discarded BIGINT, 
	probable_meninggal BIGINT, 
	suspect_diisolasi BIGINT, 
	suspect_discarded BIGINT, 
	suspect_meninggal BIGINT, 
	tanggal TEXT
)

]
(Background on this error at: http://sqlalche.me/e/14/e3q8)
[2023-11-26 18:00:55,346] {taskinstance.py:1400} INFO - Marking task as UP_FOR_RETRY. dag_id=data_covid_etl, task_id=ingest_staging_db, execution_date=20231122T000000, start_date=20231126T180054, end_date=20231126T180055
[2023-11-26 18:00:55,374] {standard_task_runner.py:97} ERROR - Failed to execute job 157 for task ingest_staging_db ((MySQLdb._exceptions.OperationalError) (1050, "Table 'covid_jabar' already exists")
[SQL: 
CREATE TABLE covid_jabar (
	`CLOSECONTACT` BIGINT, 
	`CONFIRMATION` BIGINT, 
	`PROBABLE` BIGINT, 
	`SUSPECT` BIGINT, 
	closecontact_dikarantina BIGINT, 
	closecontact_discarded BIGINT, 
	closecontact_meninggal BIGINT, 
	confirmation_meninggal BIGINT, 
	confirmation_sembuh BIGINT, 
	kode_kab TEXT, 
	kode_prov TEXT, 
	nama_kab TEXT, 
	nama_prov TEXT, 
	probable_diisolasi BIGINT, 
	probable_discarded BIGINT, 
	probable_meninggal BIGINT, 
	suspect_diisolasi BIGINT, 
	suspect_discarded BIGINT, 
	suspect_meninggal BIGINT, 
	tanggal TEXT
)

]
(Background on this error at: http://sqlalche.me/e/14/e3q8); 920)
[2023-11-26 18:00:55,393] {local_task_job.py:156} INFO - Task exited with return code 1
[2023-11-26 18:00:55,479] {local_task_job.py:273} INFO - 0 downstream tasks scheduled from follow-on schedule check
[2023-11-26 18:02:41,941] {taskinstance.py:1159} INFO - Dependencies all met for <TaskInstance: data_covid_etl.ingest_staging_db scheduled__2023-11-22T00:00:00+00:00 [queued]>
[2023-11-26 18:02:41,961] {taskinstance.py:1159} INFO - Dependencies all met for <TaskInstance: data_covid_etl.ingest_staging_db scheduled__2023-11-22T00:00:00+00:00 [queued]>
[2023-11-26 18:02:41,961] {taskinstance.py:1356} INFO - 
--------------------------------------------------------------------------------
[2023-11-26 18:02:41,961] {taskinstance.py:1357} INFO - Starting attempt 1 of 4
[2023-11-26 18:02:41,961] {taskinstance.py:1358} INFO - 
--------------------------------------------------------------------------------
[2023-11-26 18:02:41,981] {taskinstance.py:1377} INFO - Executing <Task(PythonOperator): ingest_staging_db> on 2023-11-22 00:00:00+00:00
[2023-11-26 18:02:41,986] {standard_task_runner.py:52} INFO - Started process 1027 to run task
[2023-11-26 18:02:41,993] {standard_task_runner.py:79} INFO - Running: ['***', 'tasks', 'run', 'data_covid_etl', 'ingest_staging_db', 'scheduled__2023-11-22T00:00:00+00:00', '--job-id', '173', '--raw', '--subdir', 'DAGS_FOLDER/get_data.py', '--cfg-path', '/tmp/tmpmmwotzc5', '--error-file', '/tmp/tmpwsxjjk89']
[2023-11-26 18:02:41,994] {standard_task_runner.py:80} INFO - Job 173: Subtask ingest_staging_db
[2023-11-26 18:02:42,068] {task_command.py:369} INFO - Running <TaskInstance: data_covid_etl.ingest_staging_db scheduled__2023-11-22T00:00:00+00:00 [running]> on host 79a606f4be36
[2023-11-26 18:02:42,170] {taskinstance.py:1571} INFO - Exporting the following env vars:
AIRFLOW_CTX_DAG_OWNER=oce
AIRFLOW_CTX_DAG_ID=data_covid_etl
AIRFLOW_CTX_TASK_ID=ingest_staging_db
AIRFLOW_CTX_EXECUTION_DATE=2023-11-22T00:00:00+00:00
AIRFLOW_CTX_TRY_NUMBER=1
AIRFLOW_CTX_DAG_RUN_ID=scheduled__2023-11-22T00:00:00+00:00
[2023-11-26 18:02:42,788] {taskinstance.py:1889} ERROR - Task failed with exception
Traceback (most recent call last):
  File "/home/airflow/.local/lib/python3.7/site-packages/sqlalchemy/engine/base.py", line 1706, in _execute_context
    cursor, statement, parameters, context
  File "/home/airflow/.local/lib/python3.7/site-packages/sqlalchemy/engine/default.py", line 716, in do_execute
    cursor.execute(statement, parameters)
  File "/home/airflow/.local/lib/python3.7/site-packages/MySQLdb/cursors.py", line 206, in execute
    res = self._query(query)
  File "/home/airflow/.local/lib/python3.7/site-packages/MySQLdb/cursors.py", line 319, in _query
    db.query(q)
  File "/home/airflow/.local/lib/python3.7/site-packages/MySQLdb/connections.py", line 254, in query
    _mysql.connection.query(self, query)
MySQLdb._exceptions.ProgrammingError: (1146, "Table 'finalproject.covid_jabar' doesn't exist")

The above exception was the direct cause of the following exception:

Traceback (most recent call last):
  File "/home/airflow/.local/lib/python3.7/site-packages/sqlalchemy/dialects/mysql/base.py", line 3373, in _show_create_table
    ).exec_driver_sql(st)
  File "/home/airflow/.local/lib/python3.7/site-packages/sqlalchemy/engine/base.py", line 1580, in exec_driver_sql
    future=True,
  File "/home/airflow/.local/lib/python3.7/site-packages/sqlalchemy/engine/base.py", line 1491, in _exec_driver_sql
    distilled_parameters,
  File "/home/airflow/.local/lib/python3.7/site-packages/sqlalchemy/engine/base.py", line 1749, in _execute_context
    e, statement, parameters, cursor, context
  File "/home/airflow/.local/lib/python3.7/site-packages/sqlalchemy/engine/base.py", line 1930, in _handle_dbapi_exception
    sqlalchemy_exception, with_traceback=exc_info[2], from_=e
  File "/home/airflow/.local/lib/python3.7/site-packages/sqlalchemy/util/compat.py", line 211, in raise_
    raise exception
  File "/home/airflow/.local/lib/python3.7/site-packages/sqlalchemy/engine/base.py", line 1706, in _execute_context
    cursor, statement, parameters, context
  File "/home/airflow/.local/lib/python3.7/site-packages/sqlalchemy/engine/default.py", line 716, in do_execute
    cursor.execute(statement, parameters)
  File "/home/airflow/.local/lib/python3.7/site-packages/MySQLdb/cursors.py", line 206, in execute
    res = self._query(query)
  File "/home/airflow/.local/lib/python3.7/site-packages/MySQLdb/cursors.py", line 319, in _query
    db.query(q)
  File "/home/airflow/.local/lib/python3.7/site-packages/MySQLdb/connections.py", line 254, in query
    _mysql.connection.query(self, query)
sqlalchemy.exc.ProgrammingError: (MySQLdb._exceptions.ProgrammingError) (1146, "Table 'finalproject.covid_jabar' doesn't exist")
[SQL: SHOW CREATE TABLE `covid_jabar`]
(Background on this error at: http://sqlalche.me/e/14/f405)

The above exception was the direct cause of the following exception:

Traceback (most recent call last):
  File "/home/airflow/.local/lib/python3.7/site-packages/airflow/operators/python.py", line 171, in execute
    return_value = self.execute_callable()
  File "/home/airflow/.local/lib/python3.7/site-packages/airflow/operators/python.py", line 189, in execute_callable
    return self.python_callable(*self.op_args, **self.op_kwargs)
  File "/opt/airflow/dags/get_data.py", line 35, in ingest_data_staging
    df.to_sql("covid_jabar", staging_db_constring, if_exists="replace", index=False)
  File "/home/airflow/.local/lib/python3.7/site-packages/pandas/core/generic.py", line 2882, in to_sql
    method=method,
  File "/home/airflow/.local/lib/python3.7/site-packages/pandas/io/sql.py", line 728, in to_sql
    **engine_kwargs,
  File "/home/airflow/.local/lib/python3.7/site-packages/pandas/io/sql.py", line 1758, in to_sql
    dtype=dtype,
  File "/home/airflow/.local/lib/python3.7/site-packages/pandas/io/sql.py", line 1650, in prep_table
    table.create()
  File "/home/airflow/.local/lib/python3.7/site-packages/pandas/io/sql.py", line 860, in create
    self.pd_sql.drop_table(self.name, self.schema)
  File "/home/airflow/.local/lib/python3.7/site-packages/pandas/io/sql.py", line 1809, in drop_table
    self.meta.reflect(only=[table_name], schema=schema)
  File "/home/airflow/.local/lib/python3.7/site-packages/sqlalchemy/sql/schema.py", line 4715, in reflect
    Table(name, self, **reflect_opts)
  File "<string>", line 2, in __new__
  File "/home/airflow/.local/lib/python3.7/site-packages/sqlalchemy/util/deprecations.py", line 298, in warned
    return fn(*args, **kwargs)
  File "/home/airflow/.local/lib/python3.7/site-packages/sqlalchemy/sql/schema.py", line 600, in __new__
    metadata._remove_table(name, schema)
  File "/home/airflow/.local/lib/python3.7/site-packages/sqlalchemy/util/langhelpers.py", line 72, in __exit__
    with_traceback=exc_tb,
  File "/home/airflow/.local/lib/python3.7/site-packages/sqlalchemy/util/compat.py", line 211, in raise_
    raise exception
  File "/home/airflow/.local/lib/python3.7/site-packages/sqlalchemy/sql/schema.py", line 595, in __new__
    table._init(name, metadata, *args, **kw)
  File "/home/airflow/.local/lib/python3.7/site-packages/sqlalchemy/sql/schema.py", line 675, in _init
    resolve_fks=resolve_fks,
  File "/home/airflow/.local/lib/python3.7/site-packages/sqlalchemy/sql/schema.py", line 710, in _autoload
    _extend_on=_extend_on,
  File "/home/airflow/.local/lib/python3.7/site-packages/sqlalchemy/engine/reflection.py", line 758, in reflect_table
    table_name, schema, **table.dialect_kwargs
  File "/home/airflow/.local/lib/python3.7/site-packages/sqlalchemy/engine/reflection.py", line 399, in get_table_options
    conn, table_name, schema, info_cache=self.info_cache, **kw
  File "<string>", line 2, in get_table_options
  File "/home/airflow/.local/lib/python3.7/site-packages/sqlalchemy/engine/reflection.py", line 55, in cache
    ret = fn(self, con, *args, **kw)
  File "/home/airflow/.local/lib/python3.7/site-packages/sqlalchemy/dialects/mysql/base.py", line 2997, in get_table_options
    connection, table_name, schema, **kw
  File "/home/airflow/.local/lib/python3.7/site-packages/sqlalchemy/dialects/mysql/base.py", line 3249, in _parsed_state_or_create
    info_cache=kw.get("info_cache", None),
  File "<string>", line 2, in _setup_parser
  File "/home/airflow/.local/lib/python3.7/site-packages/sqlalchemy/engine/reflection.py", line 55, in cache
    ret = fn(self, con, *args, **kw)
  File "/home/airflow/.local/lib/python3.7/site-packages/sqlalchemy/dialects/mysql/base.py", line 3273, in _setup_parser
    connection, None, charset, full_name=full_name
  File "/home/airflow/.local/lib/python3.7/site-packages/sqlalchemy/dialects/mysql/base.py", line 3376, in _show_create_table
    util.raise_(exc.NoSuchTableError(full_name), replace_context=e)
  File "/home/airflow/.local/lib/python3.7/site-packages/sqlalchemy/util/compat.py", line 211, in raise_
    raise exception
sqlalchemy.exc.NoSuchTableError: `covid_jabar`
[2023-11-26 18:02:42,803] {taskinstance.py:1400} INFO - Marking task as UP_FOR_RETRY. dag_id=data_covid_etl, task_id=ingest_staging_db, execution_date=20231122T000000, start_date=20231126T180241, end_date=20231126T180242
[2023-11-26 18:02:42,821] {standard_task_runner.py:97} ERROR - Failed to execute job 173 for task ingest_staging_db (`covid_jabar`; 1027)
[2023-11-26 18:02:42,846] {local_task_job.py:156} INFO - Task exited with return code 1
[2023-11-26 18:02:42,961] {local_task_job.py:273} INFO - 0 downstream tasks scheduled from follow-on schedule check
[2023-11-26 18:05:34,894] {taskinstance.py:1159} INFO - Dependencies all met for <TaskInstance: data_covid_etl.ingest_staging_db scheduled__2023-11-22T00:00:00+00:00 [queued]>
[2023-11-26 18:05:34,911] {taskinstance.py:1159} INFO - Dependencies all met for <TaskInstance: data_covid_etl.ingest_staging_db scheduled__2023-11-22T00:00:00+00:00 [queued]>
[2023-11-26 18:05:34,911] {taskinstance.py:1356} INFO - 
--------------------------------------------------------------------------------
[2023-11-26 18:05:34,911] {taskinstance.py:1357} INFO - Starting attempt 1 of 3
[2023-11-26 18:05:34,911] {taskinstance.py:1358} INFO - 
--------------------------------------------------------------------------------
[2023-11-26 18:05:34,929] {taskinstance.py:1377} INFO - Executing <Task(PythonOperator): ingest_staging_db> on 2023-11-22 00:00:00+00:00
[2023-11-26 18:05:34,934] {standard_task_runner.py:52} INFO - Started process 1149 to run task
[2023-11-26 18:05:34,939] {standard_task_runner.py:79} INFO - Running: ['***', 'tasks', 'run', 'data_covid_etl', 'ingest_staging_db', 'scheduled__2023-11-22T00:00:00+00:00', '--job-id', '190', '--raw', '--subdir', 'DAGS_FOLDER/get_data.py', '--cfg-path', '/tmp/tmp_kllz9jc', '--error-file', '/tmp/tmp56_wrlif']
[2023-11-26 18:05:34,941] {standard_task_runner.py:80} INFO - Job 190: Subtask ingest_staging_db
[2023-11-26 18:05:35,003] {task_command.py:369} INFO - Running <TaskInstance: data_covid_etl.ingest_staging_db scheduled__2023-11-22T00:00:00+00:00 [running]> on host 79a606f4be36
[2023-11-26 18:05:35,096] {taskinstance.py:1571} INFO - Exporting the following env vars:
AIRFLOW_CTX_DAG_OWNER=oce
AIRFLOW_CTX_DAG_ID=data_covid_etl
AIRFLOW_CTX_TASK_ID=ingest_staging_db
AIRFLOW_CTX_EXECUTION_DATE=2023-11-22T00:00:00+00:00
AIRFLOW_CTX_TRY_NUMBER=1
AIRFLOW_CTX_DAG_RUN_ID=scheduled__2023-11-22T00:00:00+00:00
[2023-11-26 18:05:35,514] {taskinstance.py:1889} ERROR - Task failed with exception
Traceback (most recent call last):
  File "/home/airflow/.local/lib/python3.7/site-packages/sqlalchemy/engine/base.py", line 1706, in _execute_context
    cursor, statement, parameters, context
  File "/home/airflow/.local/lib/python3.7/site-packages/sqlalchemy/engine/default.py", line 716, in do_execute
    cursor.execute(statement, parameters)
  File "/home/airflow/.local/lib/python3.7/site-packages/MySQLdb/cursors.py", line 206, in execute
    res = self._query(query)
  File "/home/airflow/.local/lib/python3.7/site-packages/MySQLdb/cursors.py", line 319, in _query
    db.query(q)
  File "/home/airflow/.local/lib/python3.7/site-packages/MySQLdb/connections.py", line 254, in query
    _mysql.connection.query(self, query)
MySQLdb._exceptions.OperationalError: (1051, "Unknown table 'finalproject.covid_jabar'")

The above exception was the direct cause of the following exception:

Traceback (most recent call last):
  File "/home/airflow/.local/lib/python3.7/site-packages/airflow/operators/python.py", line 171, in execute
    return_value = self.execute_callable()
  File "/home/airflow/.local/lib/python3.7/site-packages/airflow/operators/python.py", line 189, in execute_callable
    return self.python_callable(*self.op_args, **self.op_kwargs)
  File "/opt/airflow/dags/get_data.py", line 35, in ingest_data_staging
    df.to_sql("covid_jabar", staging_db_constring, if_exists="replace", index=False)
  File "/home/airflow/.local/lib/python3.7/site-packages/pandas/core/generic.py", line 2882, in to_sql
    method=method,
  File "/home/airflow/.local/lib/python3.7/site-packages/pandas/io/sql.py", line 728, in to_sql
    **engine_kwargs,
  File "/home/airflow/.local/lib/python3.7/site-packages/pandas/io/sql.py", line 1758, in to_sql
    dtype=dtype,
  File "/home/airflow/.local/lib/python3.7/site-packages/pandas/io/sql.py", line 1650, in prep_table
    table.create()
  File "/home/airflow/.local/lib/python3.7/site-packages/pandas/io/sql.py", line 860, in create
    self.pd_sql.drop_table(self.name, self.schema)
  File "/home/airflow/.local/lib/python3.7/site-packages/pandas/io/sql.py", line 1810, in drop_table
    self.get_table(table_name, schema).drop()
  File "/home/airflow/.local/lib/python3.7/site-packages/sqlalchemy/sql/schema.py", line 960, in drop
    bind._run_ddl_visitor(ddl.SchemaDropper, self, checkfirst=checkfirst)
  File "/home/airflow/.local/lib/python3.7/site-packages/sqlalchemy/engine/base.py", line 3008, in _run_ddl_visitor
    conn._run_ddl_visitor(visitorcallable, element, **kwargs)
  File "/home/airflow/.local/lib/python3.7/site-packages/sqlalchemy/engine/base.py", line 2016, in _run_ddl_visitor
    visitorcallable(self.dialect, self, **kwargs).traverse_single(element)
  File "/home/airflow/.local/lib/python3.7/site-packages/sqlalchemy/sql/visitors.py", line 483, in traverse_single
    return meth(obj, **kw)
  File "/home/airflow/.local/lib/python3.7/site-packages/sqlalchemy/sql/ddl.py", line 1097, in visit_table
    self.connection.execute(DropTable(table))
  File "/home/airflow/.local/lib/python3.7/site-packages/sqlalchemy/engine/base.py", line 1200, in execute
    return meth(self, multiparams, params, _EMPTY_EXECUTION_OPTS)
  File "/home/airflow/.local/lib/python3.7/site-packages/sqlalchemy/sql/ddl.py", line 78, in _execute_on_connection
    self, multiparams, params, execution_options
  File "/home/airflow/.local/lib/python3.7/site-packages/sqlalchemy/engine/base.py", line 1296, in _execute_ddl
    compiled,
  File "/home/airflow/.local/lib/python3.7/site-packages/sqlalchemy/engine/base.py", line 1749, in _execute_context
    e, statement, parameters, cursor, context
  File "/home/airflow/.local/lib/python3.7/site-packages/sqlalchemy/engine/base.py", line 1930, in _handle_dbapi_exception
    sqlalchemy_exception, with_traceback=exc_info[2], from_=e
  File "/home/airflow/.local/lib/python3.7/site-packages/sqlalchemy/util/compat.py", line 211, in raise_
    raise exception
  File "/home/airflow/.local/lib/python3.7/site-packages/sqlalchemy/engine/base.py", line 1706, in _execute_context
    cursor, statement, parameters, context
  File "/home/airflow/.local/lib/python3.7/site-packages/sqlalchemy/engine/default.py", line 716, in do_execute
    cursor.execute(statement, parameters)
  File "/home/airflow/.local/lib/python3.7/site-packages/MySQLdb/cursors.py", line 206, in execute
    res = self._query(query)
  File "/home/airflow/.local/lib/python3.7/site-packages/MySQLdb/cursors.py", line 319, in _query
    db.query(q)
  File "/home/airflow/.local/lib/python3.7/site-packages/MySQLdb/connections.py", line 254, in query
    _mysql.connection.query(self, query)
sqlalchemy.exc.OperationalError: (MySQLdb._exceptions.OperationalError) (1051, "Unknown table 'finalproject.covid_jabar'")
[SQL: 
DROP TABLE covid_jabar]
(Background on this error at: http://sqlalche.me/e/14/e3q8)
[2023-11-26 18:05:35,541] {taskinstance.py:1400} INFO - Marking task as UP_FOR_RETRY. dag_id=data_covid_etl, task_id=ingest_staging_db, execution_date=20231122T000000, start_date=20231126T180534, end_date=20231126T180535
[2023-11-26 18:05:35,558] {standard_task_runner.py:97} ERROR - Failed to execute job 190 for task ingest_staging_db ((MySQLdb._exceptions.OperationalError) (1051, "Unknown table 'finalproject.covid_jabar'")
[SQL: 
DROP TABLE covid_jabar]
(Background on this error at: http://sqlalche.me/e/14/e3q8); 1149)
[2023-11-26 18:05:35,599] {local_task_job.py:156} INFO - Task exited with return code 1
[2023-11-26 18:05:35,675] {local_task_job.py:273} INFO - 0 downstream tasks scheduled from follow-on schedule check
[2023-11-26 18:08:47,176] {taskinstance.py:1159} INFO - Dependencies all met for <TaskInstance: data_covid_etl.ingest_staging_db scheduled__2023-11-22T00:00:00+00:00 [queued]>
[2023-11-26 18:08:47,198] {taskinstance.py:1159} INFO - Dependencies all met for <TaskInstance: data_covid_etl.ingest_staging_db scheduled__2023-11-22T00:00:00+00:00 [queued]>
[2023-11-26 18:08:47,199] {taskinstance.py:1356} INFO - 
--------------------------------------------------------------------------------
[2023-11-26 18:08:47,200] {taskinstance.py:1357} INFO - Starting attempt 1 of 3
[2023-11-26 18:08:47,200] {taskinstance.py:1358} INFO - 
--------------------------------------------------------------------------------
[2023-11-26 18:08:47,215] {taskinstance.py:1377} INFO - Executing <Task(PythonOperator): ingest_staging_db> on 2023-11-22 00:00:00+00:00
[2023-11-26 18:08:47,220] {standard_task_runner.py:52} INFO - Started process 1331 to run task
[2023-11-26 18:08:47,225] {standard_task_runner.py:79} INFO - Running: ['***', 'tasks', 'run', 'data_covid_etl', 'ingest_staging_db', 'scheduled__2023-11-22T00:00:00+00:00', '--job-id', '220', '--raw', '--subdir', 'DAGS_FOLDER/get_data.py', '--cfg-path', '/tmp/tmp_w7fvj92', '--error-file', '/tmp/tmpwoguh06y']
[2023-11-26 18:08:47,226] {standard_task_runner.py:80} INFO - Job 220: Subtask ingest_staging_db
[2023-11-26 18:08:47,291] {task_command.py:369} INFO - Running <TaskInstance: data_covid_etl.ingest_staging_db scheduled__2023-11-22T00:00:00+00:00 [running]> on host 79a606f4be36
[2023-11-26 18:08:47,388] {taskinstance.py:1571} INFO - Exporting the following env vars:
AIRFLOW_CTX_DAG_OWNER=oce
AIRFLOW_CTX_DAG_ID=data_covid_etl
AIRFLOW_CTX_TASK_ID=ingest_staging_db
AIRFLOW_CTX_EXECUTION_DATE=2023-11-22T00:00:00+00:00
AIRFLOW_CTX_TRY_NUMBER=1
AIRFLOW_CTX_DAG_RUN_ID=scheduled__2023-11-22T00:00:00+00:00
[2023-11-26 18:08:47,876] {taskinstance.py:1889} ERROR - Task failed with exception
Traceback (most recent call last):
  File "/home/airflow/.local/lib/python3.7/site-packages/sqlalchemy/engine/base.py", line 1706, in _execute_context
    cursor, statement, parameters, context
  File "/home/airflow/.local/lib/python3.7/site-packages/sqlalchemy/engine/default.py", line 716, in do_execute
    cursor.execute(statement, parameters)
  File "/home/airflow/.local/lib/python3.7/site-packages/MySQLdb/cursors.py", line 206, in execute
    res = self._query(query)
  File "/home/airflow/.local/lib/python3.7/site-packages/MySQLdb/cursors.py", line 319, in _query
    db.query(q)
  File "/home/airflow/.local/lib/python3.7/site-packages/MySQLdb/connections.py", line 254, in query
    _mysql.connection.query(self, query)
MySQLdb._exceptions.OperationalError: (1050, "Table 'covid_jabar' already exists")

The above exception was the direct cause of the following exception:

Traceback (most recent call last):
  File "/home/airflow/.local/lib/python3.7/site-packages/airflow/operators/python.py", line 171, in execute
    return_value = self.execute_callable()
  File "/home/airflow/.local/lib/python3.7/site-packages/airflow/operators/python.py", line 189, in execute_callable
    return self.python_callable(*self.op_args, **self.op_kwargs)
  File "/opt/airflow/dags/get_data.py", line 35, in ingest_data_staging
    df.to_sql("covid_jabar", staging_db_constring, if_exists="replace", index=False)
  File "/home/airflow/.local/lib/python3.7/site-packages/pandas/core/generic.py", line 2882, in to_sql
    method=method,
  File "/home/airflow/.local/lib/python3.7/site-packages/pandas/io/sql.py", line 728, in to_sql
    **engine_kwargs,
  File "/home/airflow/.local/lib/python3.7/site-packages/pandas/io/sql.py", line 1758, in to_sql
    dtype=dtype,
  File "/home/airflow/.local/lib/python3.7/site-packages/pandas/io/sql.py", line 1650, in prep_table
    table.create()
  File "/home/airflow/.local/lib/python3.7/site-packages/pandas/io/sql.py", line 861, in create
    self._execute_create()
  File "/home/airflow/.local/lib/python3.7/site-packages/pandas/io/sql.py", line 853, in _execute_create
    self.table.create()
  File "/home/airflow/.local/lib/python3.7/site-packages/sqlalchemy/sql/schema.py", line 943, in create
    bind._run_ddl_visitor(ddl.SchemaGenerator, self, checkfirst=checkfirst)
  File "/home/airflow/.local/lib/python3.7/site-packages/sqlalchemy/engine/base.py", line 3008, in _run_ddl_visitor
    conn._run_ddl_visitor(visitorcallable, element, **kwargs)
  File "/home/airflow/.local/lib/python3.7/site-packages/sqlalchemy/engine/base.py", line 2016, in _run_ddl_visitor
    visitorcallable(self.dialect, self, **kwargs).traverse_single(element)
  File "/home/airflow/.local/lib/python3.7/site-packages/sqlalchemy/sql/visitors.py", line 483, in traverse_single
    return meth(obj, **kw)
  File "/home/airflow/.local/lib/python3.7/site-packages/sqlalchemy/sql/ddl.py", line 895, in visit_table
    include_foreign_key_constraints,  # noqa
  File "/home/airflow/.local/lib/python3.7/site-packages/sqlalchemy/engine/base.py", line 1200, in execute
    return meth(self, multiparams, params, _EMPTY_EXECUTION_OPTS)
  File "/home/airflow/.local/lib/python3.7/site-packages/sqlalchemy/sql/ddl.py", line 78, in _execute_on_connection
    self, multiparams, params, execution_options
  File "/home/airflow/.local/lib/python3.7/site-packages/sqlalchemy/engine/base.py", line 1296, in _execute_ddl
    compiled,
  File "/home/airflow/.local/lib/python3.7/site-packages/sqlalchemy/engine/base.py", line 1749, in _execute_context
    e, statement, parameters, cursor, context
  File "/home/airflow/.local/lib/python3.7/site-packages/sqlalchemy/engine/base.py", line 1930, in _handle_dbapi_exception
    sqlalchemy_exception, with_traceback=exc_info[2], from_=e
  File "/home/airflow/.local/lib/python3.7/site-packages/sqlalchemy/util/compat.py", line 211, in raise_
    raise exception
  File "/home/airflow/.local/lib/python3.7/site-packages/sqlalchemy/engine/base.py", line 1706, in _execute_context
    cursor, statement, parameters, context
  File "/home/airflow/.local/lib/python3.7/site-packages/sqlalchemy/engine/default.py", line 716, in do_execute
    cursor.execute(statement, parameters)
  File "/home/airflow/.local/lib/python3.7/site-packages/MySQLdb/cursors.py", line 206, in execute
    res = self._query(query)
  File "/home/airflow/.local/lib/python3.7/site-packages/MySQLdb/cursors.py", line 319, in _query
    db.query(q)
  File "/home/airflow/.local/lib/python3.7/site-packages/MySQLdb/connections.py", line 254, in query
    _mysql.connection.query(self, query)
sqlalchemy.exc.OperationalError: (MySQLdb._exceptions.OperationalError) (1050, "Table 'covid_jabar' already exists")
[SQL: 
CREATE TABLE covid_jabar (
	`CLOSECONTACT` BIGINT, 
	`CONFIRMATION` BIGINT, 
	`PROBABLE` BIGINT, 
	`SUSPECT` BIGINT, 
	closecontact_dikarantina BIGINT, 
	closecontact_discarded BIGINT, 
	closecontact_meninggal BIGINT, 
	confirmation_meninggal BIGINT, 
	confirmation_sembuh BIGINT, 
	kode_kab TEXT, 
	kode_prov TEXT, 
	nama_kab TEXT, 
	nama_prov TEXT, 
	probable_diisolasi BIGINT, 
	probable_discarded BIGINT, 
	probable_meninggal BIGINT, 
	suspect_diisolasi BIGINT, 
	suspect_discarded BIGINT, 
	suspect_meninggal BIGINT, 
	tanggal TEXT
)

]
(Background on this error at: http://sqlalche.me/e/14/e3q8)
[2023-11-26 18:08:47,889] {taskinstance.py:1400} INFO - Marking task as UP_FOR_RETRY. dag_id=data_covid_etl, task_id=ingest_staging_db, execution_date=20231122T000000, start_date=20231126T180847, end_date=20231126T180847
[2023-11-26 18:08:47,910] {standard_task_runner.py:97} ERROR - Failed to execute job 220 for task ingest_staging_db ((MySQLdb._exceptions.OperationalError) (1050, "Table 'covid_jabar' already exists")
[SQL: 
CREATE TABLE covid_jabar (
	`CLOSECONTACT` BIGINT, 
	`CONFIRMATION` BIGINT, 
	`PROBABLE` BIGINT, 
	`SUSPECT` BIGINT, 
	closecontact_dikarantina BIGINT, 
	closecontact_discarded BIGINT, 
	closecontact_meninggal BIGINT, 
	confirmation_meninggal BIGINT, 
	confirmation_sembuh BIGINT, 
	kode_kab TEXT, 
	kode_prov TEXT, 
	nama_kab TEXT, 
	nama_prov TEXT, 
	probable_diisolasi BIGINT, 
	probable_discarded BIGINT, 
	probable_meninggal BIGINT, 
	suspect_diisolasi BIGINT, 
	suspect_discarded BIGINT, 
	suspect_meninggal BIGINT, 
	tanggal TEXT
)

]
(Background on this error at: http://sqlalche.me/e/14/e3q8); 1331)
[2023-11-26 18:08:47,960] {local_task_job.py:156} INFO - Task exited with return code 1
[2023-11-26 18:08:48,000] {local_task_job.py:273} INFO - 0 downstream tasks scheduled from follow-on schedule check
[2023-11-26 18:15:24,286] {taskinstance.py:1159} INFO - Dependencies all met for <TaskInstance: data_covid_etl.ingest_staging_db scheduled__2023-11-22T00:00:00+00:00 [queued]>
[2023-11-26 18:15:24,304] {taskinstance.py:1159} INFO - Dependencies all met for <TaskInstance: data_covid_etl.ingest_staging_db scheduled__2023-11-22T00:00:00+00:00 [queued]>
[2023-11-26 18:15:24,304] {taskinstance.py:1356} INFO - 
--------------------------------------------------------------------------------
[2023-11-26 18:15:24,304] {taskinstance.py:1357} INFO - Starting attempt 1 of 3
[2023-11-26 18:15:24,304] {taskinstance.py:1358} INFO - 
--------------------------------------------------------------------------------
[2023-11-26 18:15:24,321] {taskinstance.py:1377} INFO - Executing <Task(PythonOperator): ingest_staging_db> on 2023-11-22 00:00:00+00:00
[2023-11-26 18:15:24,327] {standard_task_runner.py:52} INFO - Started process 1632 to run task
[2023-11-26 18:15:24,332] {standard_task_runner.py:79} INFO - Running: ['***', 'tasks', 'run', 'data_covid_etl', 'ingest_staging_db', 'scheduled__2023-11-22T00:00:00+00:00', '--job-id', '263', '--raw', '--subdir', 'DAGS_FOLDER/get_data.py', '--cfg-path', '/tmp/tmpf08taamb', '--error-file', '/tmp/tmpexvrsy0n']
[2023-11-26 18:15:24,335] {standard_task_runner.py:80} INFO - Job 263: Subtask ingest_staging_db
[2023-11-26 18:15:24,421] {task_command.py:369} INFO - Running <TaskInstance: data_covid_etl.ingest_staging_db scheduled__2023-11-22T00:00:00+00:00 [running]> on host 79a606f4be36
[2023-11-26 18:15:24,533] {taskinstance.py:1571} INFO - Exporting the following env vars:
AIRFLOW_CTX_DAG_OWNER=oce
AIRFLOW_CTX_DAG_ID=data_covid_etl
AIRFLOW_CTX_TASK_ID=ingest_staging_db
AIRFLOW_CTX_EXECUTION_DATE=2023-11-22T00:00:00+00:00
AIRFLOW_CTX_TRY_NUMBER=1
AIRFLOW_CTX_DAG_RUN_ID=scheduled__2023-11-22T00:00:00+00:00
[2023-11-26 18:15:25,200] {python.py:173} INFO - Done. Returned value was: None
[2023-11-26 18:15:25,213] {taskinstance.py:1400} INFO - Marking task as SUCCESS. dag_id=data_covid_etl, task_id=ingest_staging_db, execution_date=20231122T000000, start_date=20231126T181524, end_date=20231126T181525
[2023-11-26 18:15:25,267] {local_task_job.py:156} INFO - Task exited with return code 0
[2023-11-26 18:15:25,324] {local_task_job.py:273} INFO - 1 downstream tasks scheduled from follow-on schedule check
